<?xml version='1.0' encoding='ASCII'?>
<robot xmlns:xacro="http://ros.org/wiki/xacro" name="inmoov">

<xacro:include filename="$(find inmoov_description)/urdf/materials.urdf.xacro"/>

<xacro:macro name="arm" params="side flip covers">

  <link name="${side}_shoulder_base">
    <visual>
      <geometry>
        <mesh filename="package://inmoov_meshes/meshes/${side}_shoulder_base.stl" scale="0.001 0.001 0.001"/>
      </geometry>
      <origin rpy="0 0 0" xyz="0 0 0"/>
      <xacro:frame_color/>
    </visual>
    <inertial>
      <origin rpy="0 0 0" xyz="${flip * -0.018} -0.006 -0.060"/>
      <mass value="2.5e-1"/>
      <inertia ixx="1e-2" ixy="0" ixz="0" iyy="1e-2" iyz="0" izz="1e-2"/>
    </inertial>
  </link>


  <link name="${side}_shoulder">
    <visual>
      <geometry>
        <mesh filename="package://inmoov_meshes/meshes/${side}_shoulder.stl" scale="0.001 0.001 0.001"/>
      </geometry>
      <origin rpy="0 0 0" xyz="0 0 0"/>
      <xacro:frame_color/>
    </visual>
    <inertial>
      <origin rpy="0 0 0" xyz="${flip * 0.058} -0.009 -0.034"/>
      <mass value="1.5e-1"/>
      <inertia ixx="1e-2" ixy="0" ixz="0" iyy="1e-2" iyz="0" izz="1e-2"/>
    </inertial>
  </link>


  <link name="${side}_bicep">
    <visual>
      <geometry>
        <mesh filename="package://inmoov_meshes/meshes/bicep.stl" scale="0.001 0.001 0.001"/>
      </geometry>
      <origin rpy="0 0 0" xyz="0 0 0"/>
      <xacro:frame_color/>
    </visual>
    <inertial>
      <origin rpy="0 0 0" xyz="0 -0.010 -0.082"/>
      <mass value="1.48e-1"/>
      <inertia ixx="1e-2" ixy="0" ixz="0" iyy="1e-2" iyz="0" izz="1e-2"/>
    </inertial>
  </link>


  <link name="${side}_bicepcover">
    <visual>
      <geometry>
        <mesh filename="package://inmoov_meshes/meshes/bicepcover.stl" scale="0.001 0.001 0.001"/>
      </geometry>
      <origin rpy="0 0 0" xyz="0 0 0"/>
      <xacro:cover_color/>
    </visual>
    <inertial>
      <origin rpy="0 0 0" xyz="0 0.023 -0.116"/>
      <mass value="1.5e-1"/>
      <inertia ixx="4.061e-3" ixy="0" ixz="0" iyy="3.552e-3" iyz="0" izz="2.504e-3"/>
    </inertial>
  </link>


  <link name="${side}_forearm">
    <visual>
      <geometry>
        <mesh filename="package://inmoov_meshes/meshes/${side}_forearm.stl" scale="0.001 0.001 0.001"/>
      </geometry>
      <origin rpy="0 0 0" xyz="${flip * 0.001} 0 0"/>
      <xacro:cover_color/>
    </visual>
    <inertial>
      <origin rpy="0 0 0" xyz="0 0 -0.163"/>
      <mass value="6e-2"/>
      <inertia ixx="1e-2" ixy="0" ixz="0" iyy="1e-2" iyz="0" izz="1e-2"/>
    </inertial>
  </link>


  <joint name="${side}_shoulder_up" type="revolute">
    <axis xyz="1 0 0"/>
    <limit effort="2.422" lower="0" upper="3.14" velocity="7.48"/>
    <origin rpy="0 0 0" xyz="${flip * 0.012} 0 -0.04"/>
    <parent link="${side}_shoulder_base"/>
    <child link="${side}_shoulder"/>
    <dynamics damping="0.7"/>
  </joint>


  <joint name="${side}_bicep_rotate" type="revolute">
    <axis xyz="0 0 1"/>
    <limit effort="2.422" lower="-0.872" upper="1.57" velocity="7.48"/>
    <origin rpy="0 0 0" xyz="${flip * 0.066} 0 -0.060"/>
    <parent link="${side}_shoulder"/>
    <child link="${side}_bicep"/>
    <dynamics damping="0.7"/>
  </joint>


  <joint name="${side}_elbow" type="revolute">
    <axis xyz="1 0 0"/>
    <limit effort="2.422" lower="0" upper="1.57" velocity="7.48"/>
    <origin rpy="0 0 0" xyz="0 -0.0278 -0.2235"/>
    <parent link="${side}_bicep"/>
    <child link="${side}_forearm"/>
    <dynamics damping="0.7"/>
  </joint>


  <joint name="${side}_bicepcover" type="fixed">
    <origin rpy="0 0 0" xyz="0 0 0"/>
    <parent link="${side}_bicep"/>
    <child link="${side}_bicepcover"/>
  </joint>



</xacro:macro>



</robot>