<?xml version='1.0' encoding='ASCII'?>
<robot xmlns:xacro="http://ros.org/wiki/xacro" name="inmoov">

<xacro:include filename="$(find inmoov_description)/urdf/materials.urdf.xacro"/>

<xacro:macro name="face" params="covers">


  <link name="face">
    <visual>
      <geometry>
        <mesh filename="package://inmoov_meshes/meshes/face.stl" scale="0.001 0.001 0.001"/>
      </geometry>
      <origin rpy="0 0 0" xyz="0 0 0"/>
      <xacro:cover_color/>
    </visual>
    <inertial>
      <origin rpy="0 0 0" xyz="0 0.028 -0.015"/>
      <mass value="1.437e-2"/>
      <inertia ixx="3.79e-4" ixy="0" ixz="0" iyy="1.542e-3" iyz="0" izz="1.336e-3"/>
    </inertial>
  </link>


  <joint name="eyes_updown" type="revolute">
   <axis xyz="1 0 0"/>
   <limit effort="0.2354" lower="-0.45" upper="0.45" velocity="11.6356"/>
   <origin rpy="0 0 0" xyz="0 0 0"/>
   <parent link="face"/>
   <child link="eyesupport"/>
   <dynamics damping="0.7"/>
  </joint>


  <link name="eyesupport">
    <visual>
      <geometry>
        <mesh filename="package://inmoov_meshes/meshes/eyesupport.stl" scale="0.001 0.001 0.001"/>
      </geometry>
      <origin rpy="0 0 0" xyz="0 0 0"/>
      <xacro:frame_color/>
    </visual>
    <inertial>
      <origin rpy="0 0 0" xyz="0 -0.004 0.001"/>
      <mass value="1.47e-2"/>
      <inertia ixx="9e-6" ixy="0" ixz="0" iyy="2.3e-5" iyz="0" izz="4e-6"/>
    </inertial>
  </link>


<xacro:asmEye side="right" flip="1"/>


  <joint name="eye_leftright" type="revolute">
   <axis xyz="0 0 1"/>
   <limit effort="0.2354" lower="-0.45" upper="0.45" velocity="11.6356"/>
   <origin rpy="0 0 0" xyz="0.033 0 -0.0036"/>
   <parent link="eyesupport"/>
   <child link="right_eyesupport"/>
   <dynamics damping="0.7"/>
  </joint>


<xacro:asmEye side="left" flip="-1"/>


  <joint name="left_eye_leftright" type="revolute">
   <axis xyz="0 0 1"/>
   <limit effort="0.2354" lower="-0.45" upper="0.45" velocity="11.6356"/>
   <mimic joint="eye_leftright" multiplier="1" offset="0"/>
   <origin rpy="0 0 0" xyz="-0.033 0 -0.0036"/>
   <parent link="eyesupport"/>
   <child link="left_eyesupport"/>
   <dynamics damping="0.7"/>
  </joint>


</xacro:macro>


<xacro:macro name="asmEye" params="side flip">

  <link name="${side}_eyesupport">
    <visual>
      <geometry>
        <mesh filename="package://inmoov_meshes/meshes/${side}_eyesupport.stl" scale="0.001 0.001 0.001"/>
      </geometry>
      <origin rpy="0 0 0" xyz="0 0 0"/>
      <xacro:frame_color/>
    </visual>
    <inertial>
      <origin rpy="0 0 0" xyz="0 -0.004 0.003"/>
      <mass value="5.2e-3"/>
      <inertia ixx="1e-6" ixy="0" ixz="0" iyy="2.3e-5" iyz="0" izz="1e-6"/>
    </inertial>
  </link>


  <link name="${side}_camera">
    <visual>
      <geometry>
        <mesh filename="package://inmoov_meshes/meshes/camera.stl" scale="0.001 0.001 0.001"/>
      </geometry>
      <origin rpy="0 0 0" xyz="0 0 0"/>
      <xacro:camera_color/>
    </visual>
    <inertial>
      <origin rpy="0 0 0" xyz="0 0.002 -0.002"/>
      <mass value="2.6e-2"/>
      <inertia ixx="1e-2" ixy="0" ixz="0" iyy="1e-2" iyz="0" izz="1e-2"/>
    </inertial>
  </link>


  <link name="${side}_eye">
    <visual>
      <geometry>
        <mesh filename="package://inmoov_meshes/meshes/eye.stl" scale="0.001 0.001 0.001"/>
      </geometry>
      <origin rpy="0 0 0" xyz="0 0 0"/>
      <xacro:eyeball_color/>
    </visual>
    <inertial>
      <origin rpy="0 0 0" xyz="0 0.003 0"/>
      <mass value="2.6e-3"/>
      <inertia ixx="1e-6" ixy="0" ixz="0" iyy="1e-6" iyz="0" izz="1e-6"/>
    </inertial>
  </link>


  <link name="${side}_iris">
    <visual>
      <geometry>
        <mesh filename="package://inmoov_meshes/meshes/iris.stl" scale="0.001 0.001 0.001"/>
      </geometry>
      <origin rpy="0 0 0" xyz="0 0 0"/>
      <xacro:iris_color/>
    </visual>
    <inertial>
      <origin rpy="0 0 0" xyz="0 0.002 0"/>
      <mass value="5e-4"/>
      <inertia ixx="1e-6" ixy="0" ixz="0" iyy="1e-6" iyz="0" izz="1e-6"/>
    </inertial>
  </link>


  <joint name="${side}_camera" type="fixed">
    <origin rpy="0 0 0" xyz="0 -0.001 0"/>
    <parent link="${side}_eyesupport"/>
    <child link="${side}_camera"/>
  </joint>


  <joint name="${side}_eye" type="fixed">
    <origin rpy="0 0 0" xyz="0 0.003 0"/>
    <parent link="${side}_eyesupport"/>
    <child link="${side}_eye"/>
  </joint>


  <joint name="${side}_iris" type="fixed">
    <origin rpy="0 0 0" xyz="0 0.0061 0"/>
    <parent link="${side}_eyesupport"/>
    <child link="${side}_iris"/>
  </joint>


</xacro:macro>

</robot>