<?xml version="1.0"?>

<robot name="inmoov" xmlns:xacro="http://ros.org/wiki/xacro">

<xacro:include filename="$(find inmoov_description)/urdf/materials.urdf.xacro" />


<xacro:macro name="hand" params="side neg flip covers">


  <link name="${side}_hand">
    <visual>
      <geometry>
        <mesh filename="package://inmoov_description/meshes/${side}_hand.stl" scale="0.001 0.001 0.001"/>
      </geometry>
      <origin rpy="0 0 0" xyz="0 0 0"/>
      <xacro:frame_color/>
    </visual>
    <collision>
      <geometry>
        <mesh filename="package://inmoov_description/meshes/${side}_hand.stl" scale="0.001 0.001 0.001"/>
      </geometry> 
      <origin rpy="0 0 0" xyz="0 0 0"/>
    </collision>
    <inertial>
      <origin rpy="0 0 0" xyz="${flip * 0.005} 0 -0.054"/>
      <mass value="4.4e-2"/>
      <inertia ixx="1e-3"  ixy="0"  ixz="0" iyy="1e-3" iyz="0" izz="1e-3" />
    </inertial>
  </link>


  <link name="${side}_thumb_meta">
    <visual>
      <geometry>
        <mesh filename="package://inmoov_description/meshes/${side}_thumb5_1.stl" scale="0.001 0.001 0.001"/>
      </geometry>
      <origin rpy="3.1415 0 0" xyz="0 0 0"/>
      <xacro:frame_color/>
    </visual>
    <collision>
      <geometry>
        <mesh filename="package://inmoov_description/meshes/${side}_thumb5_1.stl" scale="0.001 0.001 0.001"/>
      </geometry> 
      <origin rpy="3.1415 0 0" xyz="0 0 0"/>
    </collision>
    <inertial>
      <origin rpy="3.1415 0 0" xyz="${flip * 0.014} 0.001 -0.003"/>
      <mass value="5.3e-3"/>
      <inertia ixx="1e-3"  ixy="0"  ixz="0" iyy="1e-3" iyz="0" izz="1e-3" />
    </inertial>
  </link>


  <link name="${side}_thumb_prox">
    <visual>
      <geometry>
        <mesh filename="package://inmoov_description/meshes/thumb5_2.stl" scale="0.001 0.001 0.001"/>
      </geometry>
      <origin rpy="0 0 3.1415" xyz="0 0 0"/>
      <xacro:frame_color/>
    </visual>
    <collision>
      <geometry>
        <mesh filename="package://inmoov_description/meshes/thumb5_2.stl" scale="0.001 0.001 0.001"/>
      </geometry> 
      <origin rpy="0 0 3.1415" xyz="0 0 0"/>
    </collision>
    <inertial>
      <origin rpy="0 0 3.1415" xyz="0 0 -0.016"/>
      <mass value="4.2e-3"/>
      <inertia ixx="1e-3"  ixy="0"  ixz="0" iyy="1e-3" iyz="0" izz="1e-3" />
    </inertial>
  </link>


  <link name="${side}_thumb_dist">
    <visual>
      <geometry>
        <mesh filename="package://inmoov_description/meshes/thumb5_3.stl" scale="0.001 0.001 0.001"/>
      </geometry>
      <origin rpy="0 0 3.1415" xyz="0 0 0"/>
      <xacro:frame_color/>
    </visual>
    <collision>
      <geometry>
        <mesh filename="package://inmoov_description/meshes/thumb5_3.stl" scale="0.001 0.001 0.001"/>
      </geometry> 
      <origin rpy="0 0 3.1415" xyz="0 0 0"/>
    </collision>
    <inertial>
      <origin rpy="0 0 3.1415" xyz="0 0 -0.013"/>
      <mass value="2.6e-3"/>
      <inertia ixx="1e-3"  ixy="0"  ixz="0" iyy="1e-3" iyz="0" izz="1e-3" />
    </inertial>
  </link>


  <link name="${side}_index_prox">
    <visual>
      <geometry>
        <mesh filename="package://inmoov_description/meshes/index3_1.stl" scale="0.001 0.001 0.001"/>
      </geometry>
      <origin rpy="0 0 3.1415" xyz="0 0 0"/>
      <xacro:frame_color/>
    </visual>
    <collision>
      <geometry>
        <mesh filename="package://inmoov_description/meshes/index3_1.stl" scale="0.001 0.001 0.001"/>
      </geometry> 
      <origin rpy="0 0 3.1415" xyz="0 0 0"/>
    </collision>
    <inertial>
      <origin rpy="0 0 3.1415" xyz="0 0 -0.018"/>
      <mass value="2.6e-3"/>
      <inertia ixx="1e-3"  ixy="0"  ixz="0" iyy="1e-3" iyz="0" izz="1e-3" />
    </inertial>
  </link>


  <link name="${side}_index_mid">
    <visual>
      <geometry>
        <mesh filename="package://inmoov_description/meshes/index3_2.stl" scale="0.001 0.001 0.001"/>
      </geometry>
      <origin rpy="0 0 3.1415" xyz="0 0 0"/>
      <xacro:frame_color/>
    </visual>
    <collision>
      <geometry>
        <mesh filename="package://inmoov_description/meshes/index3_2.stl" scale="0.001 0.001 0.001"/>
      </geometry> 
      <origin rpy="0 0 3.1415" xyz="0 0 0"/>
    </collision>
    <inertial>
      <origin rpy="0 0 3.1415" xyz="0 0.001 -0.011"/>
      <mass value="2.6e-3"/>
      <inertia ixx="1e-3"  ixy="0"  ixz="0" iyy="1e-3" iyz="0" izz="1e-3" />
    </inertial>
  </link>


  <link name="${side}_index_dist">
    <visual>
      <geometry>
        <mesh filename="package://inmoov_description/meshes/index3_3.stl" scale="0.001 0.001 0.001"/>
      </geometry>
      <origin rpy="0 0 3.1415" xyz="0 0 0"/>
      <xacro:frame_color/>
    </visual>
    <collision>
      <geometry>
        <mesh filename="package://inmoov_description/meshes/index3_3.stl" scale="0.001 0.001 0.001"/>
      </geometry> 
      <origin rpy="0 0 3.1415" xyz="0 0 0"/>
    </collision>
    <inertial>
      <origin rpy="0 0 3.1415" xyz="0 0 -0.014"/>
      <mass value="2.6e-3"/>
      <inertia ixx="1e-3"  ixy="0"  ixz="0" iyy="1e-3" iyz="0" izz="1e-3" />
    </inertial>
  </link>


  <link name="${side}_middle_prox">
    <visual>
      <geometry>
        <mesh filename="package://inmoov_description/meshes/middle3_1.stl" scale="0.001 0.001 0.001"/>
      </geometry>
      <origin rpy="0 0 3.1415" xyz="0 0 0"/>
      <xacro:frame_color/>
    </visual>
    <collision>
      <geometry>
        <mesh filename="package://inmoov_description/meshes/middle3_1.stl" scale="0.001 0.001 0.001"/>
      </geometry> 
      <origin rpy="0 0 3.1415" xyz="0 0 0"/>
    </collision>
    <inertial>
      <origin rpy="0 0 3.1415" xyz="0 0 -0.018"/>
      <mass value="2.6e-3"/>
      <inertia ixx="1e-3"  ixy="0"  ixz="0" iyy="1e-3" iyz="0" izz="1e-3" />
    </inertial>
  </link>


  <link name="${side}_middle_mid">
    <visual>
      <geometry>
        <mesh filename="package://inmoov_description/meshes/middle3_2.stl" scale="0.001 0.001 0.001"/>
      </geometry>
      <origin rpy="0 0 3.1415" xyz="0 0 0"/>
      <xacro:frame_color/>
    </visual>
    <collision>
      <geometry>
        <mesh filename="package://inmoov_description/meshes/middle3_2.stl" scale="0.001 0.001 0.001"/>
      </geometry> 
      <origin rpy="0 0 3.1415" xyz="0 0 0"/>
    </collision>
    <inertial>
      <origin rpy="0 0 3.1415" xyz="0 0.001 -0.011"/>
      <mass value="2.6e-3"/>
      <inertia ixx="1e-3"  ixy="0"  ixz="0" iyy="1e-3" iyz="0" izz="1e-3" />
    </inertial>
  </link>


  <link name="${side}_middle_dist">
    <visual>
      <geometry>
        <mesh filename="package://inmoov_description/meshes/middle3_3.stl" scale="0.001 0.001 0.001"/>
      </geometry>
      <origin rpy="0 0 3.1415" xyz="0 0 0"/>
      <xacro:frame_color/>
    </visual>
    <collision>
      <geometry>
        <mesh filename="package://inmoov_description/meshes/middle3_3.stl" scale="0.001 0.001 0.001"/>
      </geometry> 
      <origin rpy="0 0 3.1415" xyz="0 0 0"/>
    </collision>
    <inertial>
      <origin rpy="0 0 3.1415" xyz="0 0 -0.010"/>
      <mass value="2.6e-3"/>
      <inertia ixx="1e-3"  ixy="0"  ixz="0" iyy="1e-3" iyz="0" izz="1e-3" />
    </inertial>
  </link>


  <link name="${side}_ring_meta">
    <visual>
      <geometry>
        <mesh filename="package://inmoov_description/meshes/${side}_ring3_1.stl" scale="0.001 0.001 0.001"/>
      </geometry>
      <origin rpy="0 0 3.1415" xyz="0 0 0"/>
      <xacro:frame_color/>
    </visual>
    <collision>
      <geometry>
        <mesh filename="package://inmoov_description/meshes/${side}_ring3_1.stl" scale="0.001 0.001 0.001"/>
      </geometry> 
      <origin rpy="0 0 3.1415" xyz="0 0 0"/>
    </collision>
    <inertial>
      <origin rpy="0 0 3.1415" xyz="${flip * -0.016} 0 -0.002"/>
      <mass value="2.6e-3"/>
      <inertia ixx="1e-3"  ixy="0"  ixz="0" iyy="1e-3" iyz="0" izz="1e-3" />
    </inertial>
  </link>


  <link name="${side}_ring_prox">
    <visual>
      <geometry>
        <mesh filename="package://inmoov_description/meshes/ring3_2.stl" scale="0.001 0.001 0.001"/>
      </geometry>
      <origin rpy="0 0 3.1415" xyz="0 0 0"/>
      <xacro:frame_color/>
    </visual>
    <collision>
      <geometry>
        <mesh filename="package://inmoov_description/meshes/ring3_2.stl" scale="0.001 0.001 0.001"/>
      </geometry> 
      <origin rpy="0 0 3.1415" xyz="0 0 0"/>
    </collision>
    <inertial>
      <origin rpy="0 0 3.1415" xyz="0 0 -0.016"/>
      <mass value="2.6e-3"/>
      <inertia ixx="1e-3"  ixy="0"  ixz="0" iyy="1e-3" iyz="0" izz="1e-3" />
    </inertial>
  </link>


  <link name="${side}_ring_mid">
    <visual>
      <geometry>
        <mesh filename="package://inmoov_description/meshes/ring3_3.stl" scale="0.001 0.001 0.001"/>
      </geometry>
      <origin rpy="0 0 3.1415" xyz="0 0 0"/>
      <xacro:frame_color/>
    </visual>
    <collision>
      <geometry>
        <mesh filename="package://inmoov_description/meshes/ring3_3.stl" scale="0.001 0.001 0.001"/>
      </geometry> 
      <origin rpy="0 0 3.1415" xyz="0 0 0"/>
    </collision>
    <inertial>
      <origin rpy="0 0 3.1415" xyz="0 0.001 -0.010"/>
      <mass value="2.6e-3"/>
      <inertia ixx="1e-3"  ixy="0"  ixz="0" iyy="1e-3" iyz="0" izz="1e-3" />
    </inertial>
  </link>


  <link name="${side}_ring_dist">
    <visual>
      <geometry>
        <mesh filename="package://inmoov_description/meshes/ring3_4.stl" scale="0.001 0.001 0.001"/>
      </geometry>
      <origin rpy="0 0 3.1415" xyz="0 0 0"/>
      <xacro:frame_color/>
    </visual>
    <collision>
      <geometry>
        <mesh filename="package://inmoov_description/meshes/ring3_4.stl" scale="0.001 0.001 0.001"/>
      </geometry> 
      <origin rpy="0 0 3.1415" xyz="0 0 0"/>
    </collision>
    <inertial>
      <origin rpy="0 0 3.1415" xyz="0 0 -0.012"/>
      <mass value="2.6e-3"/>
      <inertia ixx="1e-3"  ixy="0"  ixz="0" iyy="1e-3" iyz="0" izz="1e-3" />
    </inertial>
  </link>


  <link name="${side}_pinky_meta">
    <visual>
      <geometry>
        <mesh filename="package://inmoov_description/meshes/${side}_pinky3_1.stl" scale="0.001 0.001 0.001"/>
      </geometry>
      <origin rpy="0 0 3.1415" xyz="0 0 0"/>
      <xacro:frame_color/>
    </visual>
    <collision>
      <geometry>
        <mesh filename="package://inmoov_description/meshes/${side}_pinky3_1.stl" scale="0.001 0.001 0.001"/>
      </geometry> 
      <origin rpy="0 0 3.1415" xyz="0 0 0"/>
    </collision>
    <inertial>
      <origin rpy="0 0 3.1415" xyz="${flip * -0.018} 0 -0.005"/>
      <mass value="2.6e-3"/>
      <inertia ixx="1e-3"  ixy="0"  ixz="0" iyy="1e-3" iyz="0" izz="1e-3" />
    </inertial>
  </link>


  <link name="${side}_pinky_prox">
    <visual>
      <geometry>
        <mesh filename="package://inmoov_description/meshes/pinky3_2.stl" scale="0.001 0.001 0.001"/>
      </geometry>
      <origin rpy="0 0 3.1415" xyz="0 0 0"/>
      <xacro:frame_color/>
    </visual>
    <collision>
      <geometry>
        <mesh filename="package://inmoov_description/meshes/pinky3_2.stl" scale="0.001 0.001 0.001"/>
      </geometry> 
      <origin rpy="0 0 3.1415" xyz="0 0 0"/>
    </collision>
    <inertial>
      <origin rpy="0 0 3.1415" xyz="0 0 -0.010"/>
      <mass value="2.6e-3"/>
      <inertia ixx="1e-3"  ixy="0"  ixz="0" iyy="1e-3" iyz="0" izz="1e-3" />
    </inertial>
  </link>

  <link name="${side}_pinky_mid">
    <visual>
      <geometry>
        <mesh filename="package://inmoov_description/meshes/pinky3_3.stl" scale="0.001 0.001 0.001"/>
      </geometry>
      <origin rpy="0 0 3.1415" xyz="0 0 0"/>
      <xacro:frame_color/>
    </visual>
    <collision>
      <geometry>
        <mesh filename="package://inmoov_description/meshes/pinky3_3.stl" scale="0.001 0.001 0.001"/>
      </geometry> 
      <origin rpy="0 0 3.1415" xyz="0 0 0"/>
    </collision>
    <inertial>
      <origin rpy="0 0 3.1415" xyz="0 0 -0.009"/>
      <mass value="2.6e-3"/>
      <inertia ixx="1e-3"  ixy="0"  ixz="0" iyy="1e-3" iyz="0" izz="1e-3" />
    </inertial>
  </link>


  <link name="${side}_pinky_dist">
    <visual>
      <geometry>
        <mesh filename="package://inmoov_description/meshes/pinky3_4.stl" scale="0.001 0.001 0.001"/>
      </geometry>
      <origin rpy="0 0 3.1415" xyz="0 0 0"/>
      <xacro:frame_color/>
    </visual>
    <collision>
      <geometry>
        <mesh filename="package://inmoov_description/meshes/pinky3_4.stl" scale="0.001 0.001 0.001"/>
      </geometry> 
      <origin rpy="0 0 3.1415" xyz="0 0 0"/>
    </collision>
    <inertial>
      <origin rpy="0 0 3.1415" xyz="0 0 -0.010"/>
      <mass value="2.6e-3"/>
      <inertia ixx="1e-3"  ixy="0"  ixz="0" iyy="1e-3" iyz="0" izz="1e-3" />
    </inertial>
  </link>


  <joint name="${side}_thumbCMC" type="revolute">
   <axis xyz="0 0 1"/>
   <limit effort="1.9613" lower="0" upper="${neg * -1.57}" velocity="6.545"/>
   <origin rpy="3.1415 ${neg * 0.1} 0" xyz="${neg * -0.029} 0 -0.0577"/>
   <mimic joint="${side}_thumbMCP" multiplier="${neg *-0.75}" offset="0"/>
   <parent link="${side}_hand"/>
   <child link="${side}_thumb_meta"/>
  </joint>


  <joint name="${side}_thumbMCP" type="revolute">
   <axis xyz="1 0 0"/>
   <limit effort="1.9613" lower="0" upper="1.5" velocity="6.545"/>
   <origin rpy="0 ${neg * 2.3} ${neg * -0.3}" xyz="${neg * -0.02725} -0.0006 0.014"/>
   <parent link="${side}_thumb_meta"/>
   <child link="${side}_thumb_prox"/>
   <dynamics damping="0.7"/>
  </joint>


  <joint name="${side}_thumbIP" type="revolute">
   <axis xyz="1 0 0"/>
   <limit effort="1.9613" lower="0" upper="1.57" velocity="6.545"/>
   <origin rpy="0 0 0" xyz="0 0 -0.035"/>
   <mimic joint="${side}_thumbMCP" multiplier="1" offset="0"/>
   <parent link="${side}_thumb_prox"/>
   <child link="${side}_thumb_dist"/>
  </joint>


  <joint name="${side}_indexMCP" type="revolute">
   <axis xyz="1 0 0"/>
   <limit effort="1.9613" lower="0" upper="1.5" velocity="6.545"/>
   <origin rpy="0 ${neg * -0.1} 3.1415" xyz="${neg * -0.0342} -0.0015 -0.119"/>
   <mimic joint="${side}_indexPIP" multiplier="1" offset="0"/>
   <parent link="${side}_hand"/>
   <child link="${side}_index_prox"/>
  </joint>


  <joint name="${side}_indexPIP" type="revolute">
   <axis xyz="1 0 0"/>
   <limit effort="1.9613" lower="0" upper="1.5" velocity="6.545"/>
   <origin rpy="0 0 0" xyz="0 0.001 -0.03595"/>
   <parent link="${side}_index_prox"/>
   <child link="${side}_index_mid"/>
   <dynamics damping="0.7"/>
  </joint>


  <joint name="${side}_indexDIP" type="revolute">
   <axis xyz="1 0 0"/>
   <limit effort="1.9613" lower="0" upper="1.5" velocity="6.545"/>
   <origin rpy="0 0 0" xyz="0 0 -0.024"/>
   <mimic joint="${side}_indexPIP" multiplier="1" offset="0"/>
   <parent link="${side}_index_mid"/>
   <child link="${side}_index_dist"/>
  </joint>


  <joint name="${side}_middleMCP" type="revolute">
   <axis xyz="1 0 0"/>
   <limit effort="1.9613" lower="0" upper="1.5" velocity="6.545"/>
   <origin rpy="0 0 3.1415" xyz="${neg * -0.007} -0.00175 -0.12325"/>
   <mimic joint="${side}_middlePIP" multiplier="1" offset="0"/>
   <parent link="${side}_hand"/>
   <child link="${side}_middle_prox"/>
  </joint>


  <joint name="${side}_middlePIP" type="revolute">
   <axis xyz="1 0 0"/>
   <limit effort="1.9613" lower="0" upper="1.5" velocity="6.545"/>
   <origin rpy="0 0 0" xyz="0 0.000 -0.0389"/>
   <parent link="${side}_middle_prox"/>
   <child link="${side}_middle_mid"/>
   <dynamics damping="0.7"/>
  </joint>


  <joint name="${side}_middleDIP" type="revolute">
   <axis xyz="1 0 0"/>
   <limit effort="1.9613" lower="0" upper="1.57" velocity="6.545"/>
   <origin rpy="0 0 0" xyz="0 0.0005 -0.0259"/>
   <mimic joint="${side}_middlePIP" multiplier="1" offset="0"/>
   <parent link="${side}_middle_mid"/>
   <child link="${side}_middle_dist"/>
  </joint>


  <joint name="${side}_ringCMC" type="revolute">
   <axis xyz="0 0 1"/>
   <limit effort="1.9613" lower="0" upper="${neg * -1.57}" velocity="6.545"/>
   <origin rpy="0 ${neg * -0.7} 3.1415" xyz="${neg * 0.00705} 0 -0.0794"/>
   <mimic joint="${side}_ringMCP" multiplier="${neg * -0.1}" offset="0"/>
   <parent link="${side}_hand"/>
   <child link="${side}_ring_meta"/>
  </joint>


  <joint name="${side}_ringMCP" type="revolute">
   <axis xyz="1 0 0"/>
   <limit effort="1.9613" lower="0" upper="1.5" velocity="6.545"/>
   <origin rpy="0 ${neg * 0.7775} 0" xyz="${neg * -0.0351} 0.00126 -0.0166"/>
   <parent link="${side}_ring_meta"/>
   <child link="${side}_ring_prox"/>
   <dynamics damping="0.7"/>
  </joint>


  <joint name="${side}_ringPIP" type="revolute">
   <axis xyz="1 0 0"/>
   <limit effort="1.9613" lower="0" upper="1.57" velocity="6.545"/>
   <origin rpy="0 0 0" xyz="0 0.0005 -0.0345"/>
   <mimic joint="${side}_ringMCP" multiplier="1" offset="0"/>
   <parent link="${side}_ring_prox"/>
   <child link="${side}_ring_mid"/>
  </joint>

  <joint name="${side}_ringDIP" type="revolute">
   <axis xyz="1 0 0"/>
   <limit effort="1.9613" lower="0" upper="1.57" velocity="6.545"/>
   <origin rpy="0 0 0" xyz="0 0.0004 -0.0229"/>
   <mimic joint="${side}_ringMCP" multiplier="1" offset="0"/>
   <parent link="${side}_ring_mid"/>
   <child link="${side}_ring_dist"/>
  </joint>

  <joint name="${side}_pinkyCMC" type="revolute">
   <axis xyz="0 0 1"/>
   <limit effort="1.9613" lower="0" upper="${neg * -1.57}" velocity="6.545"/>
   <origin rpy="0 ${neg * -0.7} 3.1415" xyz="${neg * 0.0270} 0 -0.0555"/>
   <mimic joint="${side}_pinkyMCP" multiplier="${neg * -0.1}" offset="0"/>
   <parent link="${side}_hand"/>
   <child link="${side}_pinky_meta"/>
  </joint>

  <joint name="${side}_pinkyMCP" type="revolute">
   <axis xyz="1 0 0"/>
   <limit effort="1.9613" lower="0" upper="1.5" velocity="6.545"/>
   <origin rpy="0 ${neg * 0.93} 0" xyz="${neg * -0.046} -0 -0.0228"/>
   <parent link="${side}_pinky_meta"/>
   <child link="${side}_pinky_prox"/>
   <dynamics damping="0.7"/>
  </joint>

  <joint name="${side}_pinkyPIP" type="revolute">
   <axis xyz="1 0 0"/>
   <limit effort="1.9613" lower="0" upper="1.57" velocity="6.545"/>
   <origin rpy="0 0 0" xyz="0 0.0005 -0.031"/>
   <mimic joint="${side}_pinkyMCP" multiplier="1" offset="0"/>
   <parent link="${side}_pinky_prox"/>
   <child link="${side}_pinky_mid"/>
  </joint>

  <joint name="${side}_pinkyDIP" type="revolute">
   <axis xyz="1 0 0"/>
   <limit effort="1.9613" lower="0" upper="1.57" velocity="6.545"/>
   <origin rpy="0 0 0" xyz="0 0.0004 -0.0208"/>
   <mimic joint="${side}_pinkyMCP" multiplier="1" offset="0"/>
   <parent link="${side}_pinky_mid"/>
   <child link="${side}_pinky_dist"/>
  </joint>


  <link name="${side}_handcover">
    <visual>
      <geometry>
        <mesh filename="package://inmoov_description/meshes/${side}_cover_hand.stl" scale="0.001 0.001 0.001"/>
      </geometry>
      <origin rpy="0 0 0" xyz="0 0 0"/>
      <xacro:cover_color/>
    </visual>
    <collision>
      <geometry>
        <mesh filename="package://inmoov_description/meshes/${side}_cover_hand.stl" scale="0.001 0.001 0.001"/>
      </geometry> 
      <origin rpy="0 0 0" xyz="0 0 0"/>
    </collision>
    <inertial>
      <origin rpy="0 0 0" xyz="${flip * -0.016} 0.004 0.036"/>
      <mass value="2.2e-2"/>
      <inertia ixx="1e-5"  ixy="0"  ixz="0" iyy="1e-4" iyz="0" izz="1e-5" />
    </inertial>
  </link>


  <link name="${side}_cover_handring">
    <visual>
      <geometry>
        <mesh filename="package://inmoov_description/meshes/${side}_cover_handring.stl" scale="0.001 0.001 0.001"/>
      </geometry>
      <origin rpy="0 0 3.1415" xyz="0 0 0"/>
      <xacro:cover_color/>
    </visual>
    <collision>
      <geometry>
        <mesh filename="package://inmoov_description/meshes/${side}_cover_handring.stl" scale="0.001 0.001 0.001"/>
      </geometry> 
      <origin rpy="0 0 3.1415" xyz="0 0 0"/>
    </collision>
    <inertial>
      <origin rpy="0 0 3.1415" xyz="0 0.003 -0.002"/>
      <mass value="2.6e-3"/>
      <inertia ixx="1e-6"  ixy="0"  ixz="0" iyy="1e-6" iyz="0" izz="1e-6" />
    </inertial>
  </link>


  <link name="${side}_cover_handpinky">
    <visual>
      <geometry>
        <mesh filename="package://inmoov_description/meshes/${side}_cover_handpinky.stl" scale="0.001 0.001 0.001"/>
      </geometry>
      <origin rpy="0 0 3.1415" xyz="0 0 0"/>
      <xacro:cover_color/>
    </visual>
    <collision>
      <geometry>
        <mesh filename="package://inmoov_description/meshes/${side}_cover_handpinky.stl" scale="0.001 0.001 0.001"/>
      </geometry> 
      <origin rpy="0 0 3.1415" xyz="0 0 0"/>
    </collision>
    <inertial>
      <origin rpy="0 0 3.1415" xyz="0 0.002 0.002"/>
      <mass value="2.6e-3"/>
      <inertia ixx="1e-6"  ixy="0"  ixz="0" iyy="1e-6" iyz="0" izz="1e-6" />
    </inertial>
  </link>


  <link name="${side}_cover_thumb">
    <visual>
      <geometry>
        <mesh filename="package://inmoov_description/meshes/${side}_cover_thumb.stl" scale="0.001 0.001 0.001"/>
      </geometry>
      <origin rpy="3.1415 0 0" xyz="0 0 0"/>
      <xacro:cover_color/>
    </visual>
    <collision>
      <geometry>
        <mesh filename="package://inmoov_description/meshes/${side}_cover_thumb.stl" scale="0.001 0.001 0.001"/>
      </geometry> 
      <origin rpy="3.1415 0 0" xyz="0 0 0"/>
    </collision>
    <inertial>
      <origin rpy="0 0 3.1415" xyz="0 0 -0.002"/>
      <mass value="2.6e-3"/>
      <inertia ixx="1e-6"  ixy="0"  ixz="0" iyy="1e-6" iyz="0" izz="1e-6" />
    </inertial>
  </link>


  <link name="${side}_cover_index">
    <visual>
      <geometry>
        <mesh filename="package://inmoov_description/meshes/${side}_cover_index.stl" scale="0.001 0.001 0.001"/>
      </geometry>
      <origin rpy="0 0 3.1415" xyz="0 0 0"/>
      <xacro:cover_color/>
    </visual>
    <collision>
      <geometry>
        <mesh filename="package://inmoov_description/meshes/${side}_cover_index.stl" scale="0.001 0.001 0.001"/>
      </geometry> 
      <origin rpy="0 0 3.1415" xyz="0 0 0"/>
    </collision>
    <inertial>
      <origin rpy="0 0 3.1415" xyz="0 0 -0.002"/>
      <mass value="2.6e-3"/>
      <inertia ixx="1e-6"  ixy="0"  ixz="0" iyy="1e-6" iyz="0" izz="1e-6" />
    </inertial>
  </link>


  <link name="${side}_cover_middle">
    <visual>
      <geometry>
        <mesh filename="package://inmoov_description/meshes/${side}_cover_middle.stl" scale="0.001 0.001 0.001"/>
      </geometry>
      <origin rpy="0 0 3.1415" xyz="0 0 0"/>
      <xacro:cover_color/>
    </visual>
    <collision>
      <geometry>
        <mesh filename="package://inmoov_description/meshes/${side}_cover_middle.stl" scale="0.001 0.001 0.001"/>
      </geometry> 
      <origin rpy="0 0 3.1415" xyz="0 0 0"/>
    </collision>
    <inertial>
      <origin rpy="0 0 3.1415" xyz="0 0 -0.002"/>
      <mass value="2.6e-3"/>
      <inertia ixx="1e-6"  ixy="0"  ixz="0" iyy="1e-6" iyz="0" izz="1e-6" />
    </inertial>
  </link>


  <link name="${side}_cover_ring">
    <visual>
      <geometry>
        <mesh filename="package://inmoov_description/meshes/${side}_cover_ring.stl" scale="0.001 0.001 0.001"/>
      </geometry>
      <origin rpy="0 0 3.1415" xyz="0 0 0"/>
      <xacro:cover_color/>
    </visual>
    <collision>
      <geometry>
        <mesh filename="package://inmoov_description/meshes/${side}_cover_ring.stl" scale="0.001 0.001 0.001"/>
      </geometry> 
      <origin rpy="0 0 3.1415" xyz="0 0 0"/>
    </collision>
    <inertial>
      <origin rpy="0 0 3.1415" xyz="0 0 -0.002"/>
      <mass value="2.6e-3"/>
      <inertia ixx="1e-6"  ixy="0"  ixz="0" iyy="1e-6" iyz="0" izz="1e-6" />
    </inertial>
  </link>


  <link name="${side}_cover_pinky">
    <visual>
      <geometry>
        <mesh filename="package://inmoov_description/meshes/${side}_cover_pinky.stl" scale="0.001 0.001 0.001"/>
      </geometry>
      <origin rpy="0 0 3.1415" xyz="0 0 0"/>
      <xacro:cover_color/>
    </visual>
    <collision>
      <geometry>
        <mesh filename="package://inmoov_description/meshes/${side}_cover_pinky.stl" scale="0.001 0.001 0.001"/>
      </geometry> 
      <origin rpy="0 0 3.1415" xyz="0 0 0"/>
    </collision>
    <inertial>
      <origin rpy="0 0 3.1415" xyz="0 0 -0.002"/>
      <mass value="2.6e-3"/>
      <inertia ixx="1e-6"  ixy="0"  ixz="0" iyy="1e-6" iyz="0" izz="1e-6" />
    </inertial>
  </link>


  <joint name="${side}_handcover" type="fixed">
<origin rpy="0 0 0" xyz="${neg * -0.0192} 0.009 -0.0977"/>
    <parent link="${side}_hand"/>
    <child link="${side}_handcover"/>
  </joint>


  <joint name="${side}_cover_handring" type="fixed">
<origin rpy="0 ${neg * 0.7} 0" xyz="${neg * -0.015} -0.009 -0.0008"/>
    <parent link="${side}_ring_meta"/>
    <child link="${side}_cover_handring"/>
  </joint>


  <joint name="${side}_cover_handpinky" type="fixed">
<origin rpy="0 ${neg * 0.7} 0" xyz="${neg * -0.0205} -0.01 -0.0069"/>
    <parent link="${side}_pinky_meta"/>
    <child link="${side}_cover_handpinky"/>
  </joint>


  <joint name="${side}_cover_thumb" type="fixed">
    <origin rpy="0 ${neg * 3.1} 0" xyz="${neg * -0.02125} -0.01 -0.0047"/>
    <parent link="${side}_thumb_meta"/>
    <child link="${side}_cover_thumb"/>
  </joint>


  <joint name="${side}_cover_index" type="fixed">
    <origin rpy="${neg * 0.05} 0 0" xyz="0 -0.0071 -0.012"/>
    <parent link="${side}_index_prox"/>
    <child link="${side}_cover_index"/>
  </joint>


  <joint name="${side}_cover_middle" type="fixed">
    <origin rpy="${neg * -0.05} 0 0" xyz="0 -0.0071 -0.012"/>
    <parent link="${side}_middle_prox"/>
    <child link="${side}_cover_middle"/>
  </joint>


  <joint name="${side}_cover_ring" type="fixed">
    <origin rpy="${neg * -0.05} ${neg * -0.1} 0" xyz="0 -0.005 -0.011"/>
    <parent link="${side}_ring_prox"/>
    <child link="${side}_cover_ring"/>
  </joint>


  <joint name="${side}_cover_pinky" type="fixed">
    <origin rpy="${neg * -0.05} ${neg * -0.1} 0" xyz="0 -0.005 -0.0105"/>
    <parent link="${side}_pinky_prox"/>
    <child link="${side}_cover_pinky"/>
  </joint>


</xacro:macro>



</robot>
