<?xml version="1.0"?>

<robot name="inmoov" xmlns:xacro="http://ros.org/wiki/xacro">

<xacro:include filename="$(find inmoov_description)/urdf/materials.urdf.xacro" />


<xacro:macro name="lhand" params="side neg covers">


  <link name="left_hand">
    <visual>
      <geometry>
        <mesh filename="package://inmoov_description/meshes/left_hand.stl" scale="0.001 0.001 0.001"/>
      </geometry>
      <origin rpy="0 0 0" xyz="0 0 0"/>
      <material name="cframe">
        <color rgba="0.25 0.25 0.25 1"/>
      </material>
    </visual>
    <collision>
      <geometry>
        <mesh filename="package://inmoov_description/meshes/left_hand.stl" scale="0.001 0.001 0.001"/>
      </geometry>
      <origin rpy="0 0 0" xyz="0 0 0"/>
    </collision>
    <inertial>
      <origin rpy="0 0 0" xyz="0.0157079632695 0 -0.054"/>
      <mass value="4.4e-2"/>
      <inertia ixx="1e-3" ixy="0" ixz="0" iyy="1e-3" iyz="0" izz="1e-3"/>
    </inertial>
  </link>


  <link name="left_thumb_meta">
    <visual>
      <geometry>
        <mesh filename="package://inmoov_description/meshes/left_thumb5_1.stl" scale="0.001 0.001 0.001"/>
      </geometry>
      <origin rpy="3.1415 0 0" xyz="0 0 0"/>
      <material name="cframe">
        <color rgba="0.25 0.25 0.25 1"/>
      </material>
    </visual>
    <collision>
      <geometry>
        <mesh filename="package://inmoov_description/meshes/left_thumb5_1.stl" scale="0.001 0.001 0.001"/>
      </geometry>
      <origin rpy="3.1415 0 0" xyz="0 0 0"/>
    </collision>
    <inertial>
      <origin rpy="3.1415 0 0" xyz="0.0439822971546 0.001 -0.003"/>
      <mass value="5.3e-3"/>
      <inertia ixx="1e-3" ixy="0" ixz="0" iyy="1e-3" iyz="0" izz="1e-3"/>
    </inertial>
  </link>


  <link name="left_thumb_prox">
    <visual>
      <geometry>
        <mesh filename="package://inmoov_description/meshes/thumb5_2.stl" scale="0.001 0.001 0.001"/>
      </geometry>
      <origin rpy="0 0 3.1415" xyz="0 0 0"/>
      <material name="cframe">
        <color rgba="0.25 0.25 0.25 1"/>
      </material>
    </visual>
    <collision>
      <geometry>
        <mesh filename="package://inmoov_description/meshes/thumb5_2.stl" scale="0.001 0.001 0.001"/>
      </geometry>
      <origin rpy="0 0 3.1415" xyz="0 0 0"/>
    </collision>
    <inertial>
      <origin rpy="0 0 3.1415" xyz="0 0 -0.016"/>
      <mass value="4.2e-3"/>
      <inertia ixx="1e-3" ixy="0" ixz="0" iyy="1e-3" iyz="0" izz="1e-3"/>
    </inertial>
  </link>


  <link name="left_thumb_dist">
    <visual>
      <geometry>
        <mesh filename="package://inmoov_description/meshes/thumb5_3.stl" scale="0.001 0.001 0.001"/>
      </geometry>
      <origin rpy="0 0 3.1415" xyz="0 0 0"/>
      <material name="cframe">
        <color rgba="0.25 0.25 0.25 1"/>
      </material>
    </visual>
    <collision>
      <geometry>
        <mesh filename="package://inmoov_description/meshes/thumb5_3.stl" scale="0.001 0.001 0.001"/>
      </geometry>
      <origin rpy="0 0 3.1415" xyz="0 0 0"/>
    </collision>
    <inertial>
      <origin rpy="0 0 3.1415" xyz="0 0 -0.013"/>
      <mass value="2.6e-3"/>
      <inertia ixx="1e-3" ixy="0" ixz="0" iyy="1e-3" iyz="0" izz="1e-3"/>
    </inertial>
  </link>


  <link name="left_index_prox">
    <visual>
      <geometry>
        <mesh filename="package://inmoov_description/meshes/index3_1.stl" scale="0.001 0.001 0.001"/>
      </geometry>
      <origin rpy="0 0 3.1415" xyz="0 0 0"/>
      <material name="cframe">
        <color rgba="0.25 0.25 0.25 1"/>
      </material>
    </visual>
    <collision>
      <geometry>
        <mesh filename="package://inmoov_description/meshes/index3_1.stl" scale="0.001 0.001 0.001"/>
      </geometry>
      <origin rpy="0 0 3.1415" xyz="0 0 0"/>
    </collision>
    <inertial>
      <origin rpy="0 0 3.1415" xyz="0 0 -0.018"/>
      <mass value="2.6e-3"/>
      <inertia ixx="1e-3" ixy="0" ixz="0" iyy="1e-3" iyz="0" izz="1e-3"/>
    </inertial>
  </link>


  <link name="left_index_mid">
    <visual>
      <geometry>
        <mesh filename="package://inmoov_description/meshes/index3_2.stl" scale="0.001 0.001 0.001"/>
      </geometry>
      <origin rpy="0 0 3.1415" xyz="0 0 0"/>
      <material name="cframe">
        <color rgba="0.25 0.25 0.25 1"/>
      </material>
    </visual>
    <collision>
      <geometry>
        <mesh filename="package://inmoov_description/meshes/index3_2.stl" scale="0.001 0.001 0.001"/>
      </geometry>
      <origin rpy="0 0 3.1415" xyz="0 0 0"/>
    </collision>
    <inertial>
      <origin rpy="0 0 3.1415" xyz="0 0.001 -0.011"/>
      <mass value="2.6e-3"/>
      <inertia ixx="1e-3" ixy="0" ixz="0" iyy="1e-3" iyz="0" izz="1e-3"/>
    </inertial>
  </link>


  <link name="left_index_dist">
    <visual>
      <geometry>
        <mesh filename="package://inmoov_description/meshes/index3_3.stl" scale="0.001 0.001 0.001"/>
      </geometry>
      <origin rpy="0 0 3.1415" xyz="0 0 0"/>
      <material name="cframe">
        <color rgba="0.25 0.25 0.25 1"/>
      </material>
    </visual>
    <collision>
      <geometry>
        <mesh filename="package://inmoov_description/meshes/index3_3.stl" scale="0.001 0.001 0.001"/>
      </geometry>
      <origin rpy="0 0 3.1415" xyz="0 0 0"/>
    </collision>
    <inertial>
      <origin rpy="0 0 3.1415" xyz="0 0 -0.014"/>
      <mass value="2.6e-3"/>
      <inertia ixx="1e-3" ixy="0" ixz="0" iyy="1e-3" iyz="0" izz="1e-3"/>
    </inertial>
  </link>


  <link name="left_middle_prox">
    <visual>
      <geometry>
        <mesh filename="package://inmoov_description/meshes/middle3_1.stl" scale="0.001 0.001 0.001"/>
      </geometry>
      <origin rpy="0 0 3.1415" xyz="0 0 0"/>
      <material name="cframe">
        <color rgba="0.25 0.25 0.25 1"/>
      </material>
    </visual>
    <collision>
      <geometry>
        <mesh filename="package://inmoov_description/meshes/middle3_1.stl" scale="0.001 0.001 0.001"/>
      </geometry>
      <origin rpy="0 0 3.1415" xyz="0 0 0"/>
    </collision>
    <inertial>
      <origin rpy="0 0 3.1415" xyz="0 0 -0.018"/>
      <mass value="2.6e-3"/>
      <inertia ixx="1e-3" ixy="0" ixz="0" iyy="1e-3" iyz="0" izz="1e-3"/>
    </inertial>
  </link>


  <link name="left_middle_mid">
    <visual>
      <geometry>
        <mesh filename="package://inmoov_description/meshes/middle3_2.stl" scale="0.001 0.001 0.001"/>
      </geometry>
      <origin rpy="0 0 3.1415" xyz="0 0 0"/>
      <material name="cframe">
        <color rgba="0.25 0.25 0.25 1"/>
      </material>
    </visual>
    <collision>
      <geometry>
        <mesh filename="package://inmoov_description/meshes/middle3_2.stl" scale="0.001 0.001 0.001"/>
      </geometry>
      <origin rpy="0 0 3.1415" xyz="0 0 0"/>
    </collision>
    <inertial>
      <origin rpy="0 0 3.1415" xyz="0 0.001 -0.011"/>
      <mass value="2.6e-3"/>
      <inertia ixx="1e-3" ixy="0" ixz="0" iyy="1e-3" iyz="0" izz="1e-3"/>
    </inertial>
  </link>


  <link name="left_middle_dist">
    <visual>
      <geometry>
        <mesh filename="package://inmoov_description/meshes/middle3_3.stl" scale="0.001 0.001 0.001"/>
      </geometry>
      <origin rpy="0 0 3.1415" xyz="0 0 0"/>
      <material name="cframe">
        <color rgba="0.25 0.25 0.25 1"/>
      </material>
    </visual>
    <collision>
      <geometry>
        <mesh filename="package://inmoov_description/meshes/middle3_3.stl" scale="0.001 0.001 0.001"/>
      </geometry>
      <origin rpy="0 0 3.1415" xyz="0 0 0"/>
    </collision>
    <inertial>
      <origin rpy="0 0 3.1415" xyz="0 0 -0.010"/>
      <mass value="2.6e-3"/>
      <inertia ixx="1e-3" ixy="0" ixz="0" iyy="1e-3" iyz="0" izz="1e-3"/>
    </inertial>
  </link>


  <link name="left_ring_meta">
    <visual>
      <geometry>
        <mesh filename="package://inmoov_description/meshes/left_ring3_1.stl" scale="0.001 0.001 0.001"/>
      </geometry>
      <origin rpy="0 0 3.1415" xyz="0 0 0"/>
      <material name="cframe">
        <color rgba="0.25 0.25 0.25 1"/>
      </material>
    </visual>
    <collision>
      <geometry>
        <mesh filename="package://inmoov_description/meshes/left_ring3_1.stl" scale="0.001 0.001 0.001"/>
      </geometry>
      <origin rpy="0 0 3.1415" xyz="0 0 0"/>
    </collision>
    <inertial>
      <origin rpy="0 0 3.1415" xyz="-0.0502654824624 0 -0.002"/>
      <mass value="2.6e-3"/>
      <inertia ixx="1e-3" ixy="0" ixz="0" iyy="1e-3" iyz="0" izz="1e-3"/>
    </inertial>
  </link>


  <link name="left_ring_prox">
    <visual>
      <geometry>
        <mesh filename="package://inmoov_description/meshes/ring3_2.stl" scale="0.001 0.001 0.001"/>
      </geometry>
      <origin rpy="0 0 3.1415" xyz="0 0 0"/>
      <material name="cframe">
        <color rgba="0.25 0.25 0.25 1"/>
      </material>
    </visual>
    <collision>
      <geometry>
        <mesh filename="package://inmoov_description/meshes/ring3_2.stl" scale="0.001 0.001 0.001"/>
      </geometry>
      <origin rpy="0 0 3.1415" xyz="0 0 0"/>
    </collision>
    <inertial>
      <origin rpy="0 0 3.1415" xyz="0 0 -0.016"/>
      <mass value="2.6e-3"/>
      <inertia ixx="1e-3" ixy="0" ixz="0" iyy="1e-3" iyz="0" izz="1e-3"/>
    </inertial>
  </link>


  <link name="left_ring_mid">
    <visual>
      <geometry>
        <mesh filename="package://inmoov_description/meshes/ring3_3.stl" scale="0.001 0.001 0.001"/>
      </geometry>
      <origin rpy="0 0 3.1415" xyz="0 0 0"/>
      <material name="cframe">
        <color rgba="0.25 0.25 0.25 1"/>
      </material>
    </visual>
    <collision>
      <geometry>
        <mesh filename="package://inmoov_description/meshes/ring3_3.stl" scale="0.001 0.001 0.001"/>
      </geometry>
      <origin rpy="0 0 3.1415" xyz="0 0 0"/>
    </collision>
    <inertial>
      <origin rpy="0 0 3.1415" xyz="0 0.001 -0.010"/>
      <mass value="2.6e-3"/>
      <inertia ixx="1e-3" ixy="0" ixz="0" iyy="1e-3" iyz="0" izz="1e-3"/>
    </inertial>
  </link>


  <link name="left_ring_dist">
    <visual>
      <geometry>
        <mesh filename="package://inmoov_description/meshes/ring3_4.stl" scale="0.001 0.001 0.001"/>
      </geometry>
      <origin rpy="0 0 3.1415" xyz="0 0 0"/>
      <material name="cframe">
        <color rgba="0.25 0.25 0.25 1"/>
      </material>
    </visual>
    <collision>
      <geometry>
        <mesh filename="package://inmoov_description/meshes/ring3_4.stl" scale="0.001 0.001 0.001"/>
      </geometry>
      <origin rpy="0 0 3.1415" xyz="0 0 0"/>
    </collision>
    <inertial>
      <origin rpy="0 0 3.1415" xyz="0 0 -0.012"/>
      <mass value="2.6e-3"/>
      <inertia ixx="1e-3" ixy="0" ixz="0" iyy="1e-3" iyz="0" izz="1e-3"/>
    </inertial>
  </link>


  <link name="left_pinky_meta">
    <visual>
      <geometry>
        <mesh filename="package://inmoov_description/meshes/left_pinky3_1.stl" scale="0.001 0.001 0.001"/>
      </geometry>
      <origin rpy="0 0 3.1415" xyz="0 0 0"/>
      <material name="cframe">
        <color rgba="0.25 0.25 0.25 1"/>
      </material>
    </visual>
    <collision>
      <geometry>
        <mesh filename="package://inmoov_description/meshes/left_pinky3_1.stl" scale="0.001 0.001 0.001"/>
      </geometry>
      <origin rpy="0 0 3.1415" xyz="0 0 0"/>
    </collision>
    <inertial>
      <origin rpy="0 0 3.1415" xyz="-0.0565486677702 0 -0.005"/>
      <mass value="2.6e-3"/>
      <inertia ixx="1e-3" ixy="0" ixz="0" iyy="1e-3" iyz="0" izz="1e-3"/>
    </inertial>
  </link>


  <link name="left_pinky_prox">
    <visual>
      <geometry>
        <mesh filename="package://inmoov_description/meshes/pinky3_2.stl" scale="0.001 0.001 0.001"/>
      </geometry>
      <origin rpy="0 0 3.1415" xyz="0 0 0"/>
      <material name="cframe">
        <color rgba="0.25 0.25 0.25 1"/>
      </material>
    </visual>
    <collision>
      <geometry>
        <mesh filename="package://inmoov_description/meshes/pinky3_2.stl" scale="0.001 0.001 0.001"/>
      </geometry>
      <origin rpy="0 0 3.1415" xyz="0 0 0"/>
    </collision>
    <inertial>
      <origin rpy="0 0 3.1415" xyz="0 0 -0.010"/>
      <mass value="2.6e-3"/>
      <inertia ixx="1e-3" ixy="0" ixz="0" iyy="1e-3" iyz="0" izz="1e-3"/>
    </inertial>
  </link>


  <link name="left_pinky_mid">
    <visual>
      <geometry>
        <mesh filename="package://inmoov_description/meshes/pinky3_3.stl" scale="0.001 0.001 0.001"/>
      </geometry>
      <origin rpy="0 0 3.1415" xyz="0 0 0"/>
      <material name="cframe">
        <color rgba="0.25 0.25 0.25 1"/>
      </material>
    </visual>
    <collision>
      <geometry>
        <mesh filename="package://inmoov_description/meshes/pinky3_3.stl" scale="0.001 0.001 0.001"/>
      </geometry>
      <origin rpy="0 0 3.1415" xyz="0 0 0"/>
    </collision>
    <inertial>
      <origin rpy="0 0 3.1415" xyz="0 0 -0.009"/>
      <mass value="2.6e-3"/>
      <inertia ixx="1e-3" ixy="0" ixz="0" iyy="1e-3" iyz="0" izz="1e-3"/>
    </inertial>
  </link>


  <link name="left_pinky_dist">
    <visual>
      <geometry>
        <mesh filename="package://inmoov_description/meshes/pinky3_4.stl" scale="0.001 0.001 0.001"/>
      </geometry>
      <origin rpy="0 0 3.1415" xyz="0 0 0"/>
      <material name="cframe">
        <color rgba="0.25 0.25 0.25 1"/>
      </material>
    </visual>
    <collision>
      <geometry>
        <mesh filename="package://inmoov_description/meshes/pinky3_4.stl" scale="0.001 0.001 0.001"/>
      </geometry>
      <origin rpy="0 0 3.1415" xyz="0 0 0"/>
    </collision>
    <inertial>
      <origin rpy="0 0 3.1415" xyz="0 0 -0.010"/>
      <mass value="2.6e-3"/>
      <inertia ixx="1e-3" ixy="0" ixz="0" iyy="1e-3" iyz="0" izz="1e-3"/>
    </inertial>
  </link>


  <joint name="left_thumbCMC" type="revolute">
    <axis xyz="0 0 1"/>
    <limit effort="1.9613" lower="0" upper="1.57" velocity="6.545"/>
    <origin rpy="3.1415 -0.1 0" xyz="0.029 0 -0.0577"/>
    <mimic joint="left_thumbMCP" multiplier="0.75" offset="0"/>
    <parent link="left_hand"/>
    <child link="left_thumb_meta"/>
  </joint>


  <joint name="left_thumbMCP" type="revolute">
    <axis xyz="1 0 0"/>
    <limit effort="1.9613" lower="0" upper="1.5" velocity="6.545"/>
    <origin rpy="0 -2.3 0.3" xyz="0.02725 -0.0006 0.014"/>
    <parent link="left_thumb_meta"/>
    <child link="left_thumb_prox"/>
    <dynamics damping="0.7"/>
  </joint>


  <joint name="left_thumbIP" type="revolute">
    <axis xyz="1 0 0"/>
    <limit effort="1.9613" lower="0" upper="1.57" velocity="6.545"/>
    <origin rpy="0 0 0" xyz="0 0 -0.035"/>
    <mimic joint="left_thumbMCP" multiplier="1" offset="0"/>
    <parent link="left_thumb_prox"/>
    <child link="left_thumb_dist"/>
  </joint>


  <joint name="left_indexMCP" type="revolute">
    <axis xyz="1 0 0"/>
    <limit effort="1.9613" lower="0" upper="1.5" velocity="6.545"/>
    <origin rpy="0 0.1 3.1415" xyz="0.0342 -0.0015 -0.119"/>
    <mimic joint="left_indexPIP" multiplier="1" offset="0"/>
    <parent link="left_hand"/>
    <child link="left_index_prox"/>
  </joint>


  <joint name="left_indexPIP" type="revolute">
    <axis xyz="1 0 0"/>
    <limit effort="1.9613" lower="0" upper="1.5" velocity="6.545"/>
    <origin rpy="0 0 0" xyz="0 0.001 -0.03595"/>
    <parent link="left_index_prox"/>
    <child link="left_index_mid"/>
    <dynamics damping="0.7"/>
  </joint>


  <joint name="left_indexDIP" type="revolute">
    <axis xyz="1 0 0"/>
    <limit effort="1.9613" lower="0" upper="1.5" velocity="6.545"/>
    <origin rpy="0 0 0" xyz="0 0 -0.024"/>
    <mimic joint="left_indexPIP" multiplier="1" offset="0"/>
    <parent link="left_index_mid"/>
    <child link="left_index_dist"/>
  </joint>


  <joint name="left_middleMCP" type="revolute">
    <axis xyz="1 0 0"/>
    <limit effort="1.9613" lower="0" upper="1.5" velocity="6.545"/>
    <origin rpy="0 0 3.1415" xyz="0.007 -0.00175 -0.12325"/>
    <mimic joint="left_middlePIP" multiplier="1" offset="0"/>
    <parent link="left_hand"/>
    <child link="left_middle_prox"/>
  </joint>


  <joint name="left_middlePIP" type="revolute">
    <axis xyz="1 0 0"/>
    <limit effort="1.9613" lower="0" upper="1.5" velocity="6.545"/>
    <origin rpy="0 0 0" xyz="0 0.000 -0.0389"/>
    <parent link="left_middle_prox"/>
    <child link="left_middle_mid"/>
    <dynamics damping="0.7"/>
  </joint>


  <joint name="left_middleDIP" type="revolute">
    <axis xyz="1 0 0"/>
    <limit effort="1.9613" lower="0" upper="1.57" velocity="6.545"/>
    <origin rpy="0 0 0" xyz="0 0.0005 -0.0259"/>
    <mimic joint="left_middlePIP" multiplier="1" offset="0"/>
    <parent link="left_middle_mid"/>
    <child link="left_middle_dist"/>
  </joint>


  <joint name="left_ringCMC" type="revolute">
    <axis xyz="0 0 1"/>
    <limit effort="1.9613" lower="0" upper="1.57" velocity="6.545"/>
    <origin rpy="0 0.7 3.1415" xyz="-0.00705 0 -0.0794"/>
    <mimic joint="left_ringMCP" multiplier="0.1" offset="0"/>
    <parent link="left_hand"/>
    <child link="left_ring_meta"/>
  </joint>


  <joint name="left_ringMCP" type="revolute">
    <axis xyz="1 0 0"/>
    <limit effort="1.9613" lower="0" upper="1.5" velocity="6.545"/>
    <origin rpy="0 -0.7775 0" xyz="0.0351 0.00126 -0.0166"/>
    <parent link="left_ring_meta"/>
    <child link="left_ring_prox"/>
    <dynamics damping="0.7"/>
  </joint>


  <joint name="left_ringPIP" type="revolute">
    <axis xyz="1 0 0"/>
    <limit effort="1.9613" lower="0" upper="1.57" velocity="6.545"/>
    <origin rpy="0 0 0" xyz="0 0.0005 -0.0345"/>
    <mimic joint="left_ringMCP" multiplier="1" offset="0"/>
    <parent link="left_ring_prox"/>
    <child link="left_ring_mid"/>
  </joint>


  <joint name="left_ringDIP" type="revolute">
    <axis xyz="1 0 0"/>
    <limit effort="1.9613" lower="0" upper="1.57" velocity="6.545"/>
    <origin rpy="0 0 0" xyz="0 0.0004 -0.0229"/>
    <mimic joint="left_ringMCP" multiplier="1" offset="0"/>
    <parent link="left_ring_mid"/>
    <child link="left_ring_dist"/>
  </joint>


  <joint name="left_pinkyCMC" type="revolute">
    <axis xyz="0 0 1"/>
    <limit effort="1.9613" lower="0" upper="1.57" velocity="6.545"/>
    <origin rpy="0 0.7 3.1415" xyz="-0.027 0 -0.0555"/>
    <mimic joint="left_pinkyMCP" multiplier="0.1" offset="0"/>
    <parent link="left_hand"/>
    <child link="left_pinky_meta"/>
  </joint>


  <joint name="left_pinkyMCP" type="revolute">
    <axis xyz="1 0 0"/>
    <limit effort="1.9613" lower="0" upper="1.5" velocity="6.545"/>
    <origin rpy="0 -0.93 0" xyz="0.046 -0 -0.0228"/>
    <parent link="left_pinky_meta"/>
    <child link="left_pinky_prox"/>
    <dynamics damping="0.7"/>
  </joint>


  <joint name="left_pinkyPIP" type="revolute">
    <axis xyz="1 0 0"/>
    <limit effort="1.9613" lower="0" upper="1.57" velocity="6.545"/>
    <origin rpy="0 0 0" xyz="0 0.0005 -0.031"/>
    <mimic joint="left_pinkyMCP" multiplier="1" offset="0"/>
    <parent link="left_pinky_prox"/>
    <child link="left_pinky_mid"/>
  </joint>


  <joint name="left_pinkyDIP" type="revolute">
    <axis xyz="1 0 0"/>
    <limit effort="1.9613" lower="0" upper="1.57" velocity="6.545"/>
    <origin rpy="0 0 0" xyz="0 0.0004 -0.0208"/>
    <mimic joint="left_pinkyMCP" multiplier="1" offset="0"/>
    <parent link="left_pinky_mid"/>
    <child link="left_pinky_dist"/>
  </joint>


  <link name="left_handcover">
    <visual>
      <geometry>
        <mesh filename="package://inmoov_description/meshes/left_cover_hand.stl" scale="0.001 0.001 0.001"/>
      </geometry>
      <origin rpy="0 0 0" xyz="0 0 0"/>
      <material name="ccover">
        <color rgba="0.6 0.6 0.6 1"/>
      </material>
    </visual>
    <collision>
      <geometry>
        <mesh filename="package://inmoov_description/meshes/left_cover_hand.stl" scale="0.001 0.001 0.001"/>
      </geometry>
      <origin rpy="0 0 0" xyz="0 0 0"/>
    </collision>
    <inertial>
      <origin rpy="0 0 0" xyz="-0.0502654824624 0.004 0.036"/>
      <mass value="2.2e-2"/>
      <inertia ixx="1e-5" ixy="0" ixz="0" iyy="1e-4" iyz="0" izz="1e-5"/>
    </inertial>
  </link>


  <link name="left_cover_handring">
    <visual>
      <geometry>
        <mesh filename="package://inmoov_description/meshes/left_cover_handring.stl" scale="0.001 0.001 0.001"/>
      </geometry>
      <origin rpy="0 0 3.1415" xyz="0 0 0"/>
      <material name="ccover">
        <color rgba="0.6 0.6 0.6 1"/>
      </material>
    </visual>
    <collision>
      <geometry>
        <mesh filename="package://inmoov_description/meshes/left_cover_handring.stl" scale="0.001 0.001 0.001"/>
      </geometry>
      <origin rpy="0 0 3.1415" xyz="0 0 0"/>
    </collision>
    <inertial>
      <origin rpy="0 0 3.1415" xyz="0 0.003 -0.002"/>
      <mass value="2.6e-3"/>
      <inertia ixx="1e-6" ixy="0" ixz="0" iyy="1e-6" iyz="0" izz="1e-6"/>
    </inertial>
  </link>


  <link name="left_cover_handpinky">
    <visual>
      <geometry>
        <mesh filename="package://inmoov_description/meshes/left_cover_handpinky.stl" scale="0.001 0.001 0.001"/>
      </geometry>
      <origin rpy="0 0 3.1415" xyz="0 0 0"/>
      <material name="ccover">
        <color rgba="0.6 0.6 0.6 1"/>
      </material>
    </visual>
    <collision>
      <geometry>
        <mesh filename="package://inmoov_description/meshes/left_cover_handpinky.stl" scale="0.001 0.001 0.001"/>
      </geometry>
      <origin rpy="0 0 3.1415" xyz="0 0 0"/>
    </collision>
    <inertial>
      <origin rpy="0 0 3.1415" xyz="0 0.002 0.002"/>
      <mass value="2.6e-3"/>
      <inertia ixx="1e-6" ixy="0" ixz="0" iyy="1e-6" iyz="0" izz="1e-6"/>
    </inertial>
  </link>


  <link name="left_cover_thumb">
    <visual>
      <geometry>
        <mesh filename="package://inmoov_description/meshes/left_cover_thumb.stl" scale="0.001 0.001 0.001"/>
      </geometry>
      <origin rpy="3.1415 0 0" xyz="0 0 0"/>
      <material name="ccover">
        <color rgba="0.6 0.6 0.6 1"/>
      </material>
    </visual>
    <collision>
      <geometry>
        <mesh filename="package://inmoov_description/meshes/left_cover_thumb.stl" scale="0.001 0.001 0.001"/>
      </geometry>
      <origin rpy="3.1415 0 0" xyz="0 0 0"/>
    </collision>
    <inertial>
      <origin rpy="0 0 3.1415" xyz="0 0 -0.002"/>
      <mass value="2.6e-3"/>
      <inertia ixx="1e-6" ixy="0" ixz="0" iyy="1e-6" iyz="0" izz="1e-6"/>
    </inertial>
  </link>


  <link name="left_cover_index">
    <visual>
      <geometry>
        <mesh filename="package://inmoov_description/meshes/left_cover_index.stl" scale="0.001 0.001 0.001"/>
      </geometry>
      <origin rpy="0 0 3.1415" xyz="0 0 0"/>
      <material name="ccover">
        <color rgba="0.6 0.6 0.6 1"/>
      </material>
    </visual>
    <collision>
      <geometry>
        <mesh filename="package://inmoov_description/meshes/left_cover_index.stl" scale="0.001 0.001 0.001"/>
      </geometry>
      <origin rpy="0 0 3.1415" xyz="0 0 0"/>
    </collision>
    <inertial>
      <origin rpy="0 0 3.1415" xyz="0 0 -0.002"/>
      <mass value="2.6e-3"/>
      <inertia ixx="1e-6" ixy="0" ixz="0" iyy="1e-6" iyz="0" izz="1e-6"/>
    </inertial>
  </link>


  <link name="left_cover_middle">
    <visual>
      <geometry>
        <mesh filename="package://inmoov_description/meshes/left_cover_middle.stl" scale="0.001 0.001 0.001"/>
      </geometry>
      <origin rpy="0 0 3.1415" xyz="0 0 0"/>
      <material name="ccover">
        <color rgba="0.6 0.6 0.6 1"/>
      </material>
    </visual>
    <collision>
      <geometry>
        <mesh filename="package://inmoov_description/meshes/left_cover_middle.stl" scale="0.001 0.001 0.001"/>
      </geometry>
      <origin rpy="0 0 3.1415" xyz="0 0 0"/>
    </collision>
    <inertial>
      <origin rpy="0 0 3.1415" xyz="0 0 -0.002"/>
      <mass value="2.6e-3"/>
      <inertia ixx="1e-6" ixy="0" ixz="0" iyy="1e-6" iyz="0" izz="1e-6"/>
    </inertial>
  </link>


  <link name="left_cover_ring">
    <visual>
      <geometry>
        <mesh filename="package://inmoov_description/meshes/left_cover_ring.stl" scale="0.001 0.001 0.001"/>
      </geometry>
      <origin rpy="0 0 3.1415" xyz="0 0 0"/>
      <material name="ccover">
        <color rgba="0.6 0.6 0.6 1"/>
      </material>
    </visual>
    <collision>
      <geometry>
        <mesh filename="package://inmoov_description/meshes/left_cover_ring.stl" scale="0.001 0.001 0.001"/>
      </geometry>
      <origin rpy="0 0 3.1415" xyz="0 0 0"/>
    </collision>
    <inertial>
      <origin rpy="0 0 3.1415" xyz="0 0 -0.002"/>
      <mass value="2.6e-3"/>
      <inertia ixx="1e-6" ixy="0" ixz="0" iyy="1e-6" iyz="0" izz="1e-6"/>
    </inertial>
  </link>


  <link name="left_cover_pinky">
    <visual>
      <geometry>
        <mesh filename="package://inmoov_description/meshes/left_cover_pinky.stl" scale="0.001 0.001 0.001"/>
      </geometry>
      <origin rpy="0 0 3.1415" xyz="0 0 0"/>
      <material name="ccover">
        <color rgba="0.6 0.6 0.6 1"/>
      </material>
    </visual>
    <collision>
      <geometry>
        <mesh filename="package://inmoov_description/meshes/left_cover_pinky.stl" scale="0.001 0.001 0.001"/>
      </geometry>
      <origin rpy="0 0 3.1415" xyz="0 0 0"/>
    </collision>
    <inertial>
      <origin rpy="0 0 3.1415" xyz="0 0 -0.002"/>
      <mass value="2.6e-3"/>
      <inertia ixx="1e-6" ixy="0" ixz="0" iyy="1e-6" iyz="0" izz="1e-6"/>
    </inertial>
  </link>


  <joint name="left_handcover" type="fixed">
    <origin rpy="0 0 0" xyz="0.0192 0.009 -0.0977"/>
    <parent link="left_hand"/>
    <child link="left_handcover"/>
  </joint>


  <joint name="left_cover_handring" type="fixed">
    <origin rpy="0 -0.7 0" xyz="0.015 -0.009 -0.0008"/>
    <parent link="left_ring_meta"/>
    <child link="left_cover_handring"/>
  </joint>


  <joint name="left_cover_handpinky" type="fixed">
    <origin rpy="0 -0.7 0" xyz="0.0205 -0.01 -0.0069"/>
    <parent link="left_pinky_meta"/>
    <child link="left_cover_handpinky"/>
  </joint>


  <joint name="left_cover_thumb" type="fixed">
    <origin rpy="0 -3.1 0" xyz="0.02125 -0.01 -0.0047"/>
    <parent link="left_thumb_meta"/>
    <child link="left_cover_thumb"/>
  </joint>


  <joint name="left_cover_index" type="fixed">
    <origin rpy="-0.05 0 0" xyz="0 -0.0071 -0.012"/>
    <parent link="left_index_prox"/>
    <child link="left_cover_index"/>
  </joint>


  <joint name="left_cover_middle" type="fixed">
    <origin rpy="0.05 0 0" xyz="0 -0.0071 -0.012"/>
    <parent link="left_middle_prox"/>
    <child link="left_cover_middle"/>
  </joint>


  <joint name="left_cover_ring" type="fixed">
    <origin rpy="0.05 0.1 0" xyz="0 -0.005 -0.011"/>
    <parent link="left_ring_prox"/>
    <child link="left_cover_ring"/>
  </joint>


  <joint name="left_cover_pinky" type="fixed">
    <origin rpy="0.05 0.1 0" xyz="0 -0.005 -0.0105"/>
    <parent link="left_pinky_prox"/>
    <child link="left_cover_pinky"/>
  </joint>


</xacro:macro>


</robot>
