<?xml version="1.0" ?>
<!-- =================================================================================== -->
<!-- |    This document was autogenerated by xacro from inmoov.urdf.xacro              | -->
<!-- |    EDITING THIS FILE BY HAND IS NOT RECOMMENDED                                 | -->
<!-- =================================================================================== -->
<robot name="inmoov" xmlns:xacro="http://ros.org/wiki/xacro">
  <link name="world"/>
  <joint name="fixed" type="fixed">
    <parent link="world"/>
    <child link="base_link"/>
  </joint>
  <link name="base_link">
    <visual>
      <geometry>
        <cylinder length="0.11" radius="0.26"/>
      </geometry>
      <origin rpy="0 0 0" xyz="0 0 0.055"/>
      <material name="cbase">
        <color rgba="0.1 0.1 0.1 1"/>
      </material>
    </visual>
    <collision>
      <geometry>
        <cylinder length="0.11" radius="0.26"/>
      </geometry>
      <origin rpy="0 0 0" xyz="0 0 0.055"/>
    </collision>
  </link>
  <joint name="base_to_pedestal" type="fixed">
    <parent link="base_link"/>
    <child link="pedestal"/>
    <origin rpy="0 0 0" xyz="0 0 0"/>
  </joint>
  <link name="pedestal">
    <visual>
      <geometry>
        <cylinder length="0.94" radius="0.0254"/>
      </geometry>
      <origin rpy="0 0 0" xyz="0 0 0.58"/>
      <material name="cbase">
        <color rgba="0.1 0.1 0.1 1"/>
      </material>
    </visual>
    <collision>
      <geometry>
        <cylinder length="0.94" radius="0.0254"/>
      </geometry>
      <origin rpy="0 0 0" xyz="0 0 0.58"/>
    </collision>
    <inertial>
      <origin rpy="0 0 0" xyz="0 0 0.58"/>
      <mass value="5"/>
      <inertia ixx="0.1" ixy="0" ixz="0" iyy="0.1" iyz="0" izz="0.1"/>
    </inertial>
  </link>
  <link name="head_tilt">
    <visual>
      <geometry>
        <mesh filename="package://inmoov_meshes/meshes/virtual.stl" scale="0.001 0.001 0.001"/>
      </geometry>
      <origin rpy="0 0 0" xyz="0 0 0"/>
      <material name="cframe">
        <color rgba="0.25 0.25 0.25 1"/>
      </material>
    </visual>
    <inertial>
      <origin rpy="0 0 0" xyz="0 0.001 0.001"/>
      <mass value="5.25e-4"/>
      <inertia ixx="1e-3" ixy="0" ixz="0" iyy="1e-3" iyz="0" izz="1e-3"/>
    </inertial>
  </link>
  <joint name="pedestal_to_mid_stomach" type="fixed">
    <parent link="pedestal"/>
    <child link="mid_stomach"/>
    <origin rpy="0 0 0" xyz="0 0 0"/>
  </joint>
  <link name="mid_stomach">
    <visual>
      <geometry>
        <mesh filename="package://inmoov_meshes/meshes/mid_stomach.stl" scale="0.001 0.001 0.001"/>
      </geometry>
      <origin rpy="0 0 0" xyz="0 0 1.152"/>
      <material name="cframe">
        <color rgba="0.25 0.25 0.25 1"/>
      </material>
    </visual>
    <collision>
      <geometry>
        <mesh filename="package://inmoov_meshes/meshes/mid_stomach.stl" scale="0.001 0.001 0.001"/>
      </geometry>
      <origin rpy="0 0 0" xyz="0 0 1.152"/>
    </collision>
    <inertial>
      <origin rpy="0 0 0" xyz="0 0.002 1.207"/>
      <mass value="7.5e-1"/>
      <inertia ixx="1.2953e-2" ixy="0" ixz="0" iyy="2.7058e-2" iyz="0" izz="2.9405e-2"/>
    </inertial>
  </link>
  <link name="disk">
    <visual>
      <geometry>
        <mesh filename="package://inmoov_meshes/meshes/disk.stl" scale="0.001 0.001 0.001"/>
      </geometry>
      <origin rpy="0 0 0" xyz="0 0.046 0"/>
      <material name="ccover">
        <color rgba="0.6 0.6 0.6 1"/>
      </material>
    </visual>
    <collision>
      <geometry>
        <mesh filename="package://inmoov_meshes/meshes/disk.stl" scale="0.001 0.001 0.001"/>
      </geometry>
      <origin rpy="0 0 0" xyz="0 0.046 0"/>
    </collision>
    <inertial>
      <origin rpy="0 0 0" xyz="0 0.067 0"/>
      <mass value="9.7555e-2"/>
      <inertia ixx="1.39e-4" ixy="0" ixz="0" iyy="2.72e-4" iyz="0" izz="1.41e-4"/>
    </inertial>
  </link>
  <link name="top_stomach">
    <visual>
      <geometry>
        <mesh filename="package://inmoov_meshes/meshes/top_stomach.stl" scale="0.001 0.001 0.001"/>
      </geometry>
      <origin rpy="0 0 0" xyz="0 0 0"/>
      <material name="cframe">
        <color rgba="0.25 0.25 0.25 1"/>
      </material>
    </visual>
    <collision>
      <geometry>
        <mesh filename="package://inmoov_meshes/meshes/top_stomach.stl" scale="0.001 0.001 0.001"/>
      </geometry>
      <origin rpy="0 0 0" xyz="0 0 0"/>
    </collision>
    <inertial>
      <origin rpy="0 0 0" xyz="0 -0.008 0.055"/>
      <mass value="7.5e-1"/>
      <inertia ixx="9.943e-3" ixy="0" ixz="0" iyy="1.1935e-2" iyz="0" izz="1.2213e-2"/>
    </inertial>
  </link>
  <link name="torso">
    <visual>
      <geometry>
        <mesh filename="package://inmoov_meshes/meshes/torso.stl" scale="0.001 0.001 0.001"/>
      </geometry>
      <origin rpy="0 0 0" xyz="0 0 0"/>
      <material name="cframe">
        <color rgba="0.25 0.25 0.25 1"/>
      </material>
    </visual>
    <collision>
      <geometry>
        <mesh filename="package://inmoov_meshes/meshes/torso.stl" scale="0.001 0.001 0.001"/>
      </geometry>
      <origin rpy="0 0 0" xyz="0 0 0"/>
    </collision>
    <inertial>
      <origin rpy="0 0 0" xyz="0 0.013 0.232"/>
      <mass value="4.25"/>
      <inertia ixx="6.8154e-2" ixy="0" ixz="0" iyy="8.0772e-2" iyz="0" izz="2.1806e-2"/>
    </inertial>
  </link>
  <link name="kinect">
    <visual>
      <geometry>
        <mesh filename="package://inmoov_meshes/meshes/kinectone.stl" scale="0.001 0.001 0.001"/>
      </geometry>
      <origin rpy="0 0 0" xyz="0 0 0"/>
      <material name="ckinect">
        <color rgba="0.1 0.1 0.1 1"/>
      </material>
    </visual>
    <collision>
      <geometry>
        <mesh filename="package://inmoov_meshes/meshes/kinectone.stl" scale="0.001 0.001 0.001"/>
      </geometry>
      <origin rpy="0 0 0" xyz="0 0 0"/>
    </collision>
    <inertial>
      <origin rpy="0 0 0" xyz="0 0.061 0.044"/>
      <mass value="1.3"/>
      <inertia ixx="8.329e-3" ixy="0" ixz="0" iyy="6.3423e-2" iyz="0" izz="6.4413e-2"/>
    </inertial>
  </link>
  <link name="kinectIR">
    <visual>
      <geometry>
        <cylinder length="0.005" radius="0.011"/>
      </geometry>
      <origin rpy="0 1.5708 0" xyz="0 0 0"/>
      <material name="cframe">
        <color rgba="0.25 0.25 0.25 1"/>
      </material>
    </visual>
  </link>
  <link name="kinectIR_frame">
    <visual>
      <geometry>
        <cylinder length="0.001" radius="0.001"/>
      </geometry>
      <origin rpy="0 0 0" xyz="0 0 0"/>
      <material name="cframe">
        <color rgba="0.25 0.25 0.25 1"/>
      </material>
    </visual>
  </link>
  <link name="chestplate">
    <visual>
      <geometry>
        <mesh filename="package://inmoov_meshes/meshes/chest.stl" scale="0.001 0.001 0.001"/>
      </geometry>
      <origin rpy="0 0 0" xyz="0 0 0"/>
      <material name="ccover">
        <color rgba="0.6 0.6 0.6 1"/>
      </material>
    </visual>
    <collision>
      <geometry>
        <mesh filename="package://inmoov_meshes/meshes/chest.stl" scale="0.001 0.001 0.001"/>
      </geometry>
      <origin rpy="0 0 0" xyz="0 0 0"/>
    </collision>
    <inertial>
      <origin rpy="0 0 0" xyz="0 0.022 0.182"/>
      <mass value="7e-2"/>
      <inertia ixx="2.446e-3" ixy="0" ixz="0" iyy="4.703e-3" iyz="0" izz="2.387e-3"/>
    </inertial>
  </link>
  <joint name="waist_rotate" type="revolute">
    <axis xyz="0 0 1"/>
    <limit effort="2.422" lower="-1.57" upper="1.57" velocity="7.48"/>
    <origin rpy="0 0 0" xyz="0 0 1.152"/>
    <parent link="mid_stomach"/>
    <child link="top_stomach"/>
    <dynamics damping="0.7"/>
  </joint>
  <joint name="disk" type="fixed">
    <origin rpy="0 0 0" xyz="0 0 0.09"/>
    <parent link="top_stomach"/>
    <child link="disk"/>
  </joint>
  <joint name="waist_lean" type="revolute">
    <axis xyz="0 1 0"/>
    <limit effort="2.422" lower="-0.30" upper="0.30" velocity="7.48"/>
    <origin rpy="0 0 0" xyz="0 0 0.11"/>
    <parent link="top_stomach"/>
    <child link="torso"/>
    <dynamics damping="0.7"/>
  </joint>
  <joint name="chestplate" type="fixed">
    <origin rpy="0 0 0" xyz="0 0.039 0.025"/>
    <parent link="torso"/>
    <child link="chestplate"/>
  </joint>
  <joint name="kinect" type="fixed">
    <origin rpy="0 0 0" xyz="0 0 0.066"/>
    <parent link="torso"/>
    <child link="kinect"/>
  </joint>
  <joint name="kinect_ircamera" type="fixed">
    <origin rpy="0 0 1.5708" xyz="-0.015 0.08 0.042"/>
    <parent link="kinect"/>
    <child link="kinectIR"/>
  </joint>
  <joint name="kinect_ircamera_frame" type="fixed">
    <origin rpy="-1.5708 0 -1.5708" xyz="0 0 0"/>
    <parent link="kinectIR"/>
    <child link="kinectIR_frame"/>
  </joint>
  <joint name="head_tilt" type="revolute">
    <axis xyz="0 1 0"/>
    <limit effort="1000.0" lower="-0.30" upper="0.30" velocity="0.5"/>
    <origin rpy="0 0 0" xyz="-0.001 -0.0315 0.4551"/>
    <parent link="torso"/>
    <child link="head_tilt"/>
    <dynamics damping="0.7"/>
  </joint>
  <joint name="head_updown" type="revolute">
    <axis xyz="1 0 0"/>
    <limit effort="2.422" lower="-1.22" upper="1.22" velocity="7.48"/>
    <origin rpy="0 0 0" xyz="0 0 0"/>
    <parent link="head_tilt"/>
    <child link="head_base"/>
    <dynamics damping="0.7"/>
  </joint>
  <link name="head_base">
    <visual>
      <geometry>
        <mesh filename="package://inmoov_meshes/meshes/head_base.stl" scale="0.001 0.001 0.001"/>
      </geometry>
      <origin rpy="0 0 0" xyz="0 0 0"/>
      <material name="cframe">
        <color rgba="0.25 0.25 0.25 1"/>
      </material>
    </visual>
    <inertial>
      <origin rpy="0 0 0" xyz="0 0.007 0.015"/>
      <mass value="2.3e-2"/>
      <inertia ixx="1e-2" ixy="0" ixz="0" iyy="1e-2" iyz="0" izz="1e-2"/>
    </inertial>
  </link>
  <link name="head">
    <visual>
      <geometry>
        <mesh filename="package://inmoov_meshes/meshes/head.stl" scale="0.001 0.001 0.001"/>
      </geometry>
      <origin rpy="0 0 0" xyz="0 0 0"/>
      <material name="cframe">
        <color rgba="0.25 0.25 0.25 1"/>
      </material>
    </visual>
    <inertial>
      <origin rpy="0 0 0" xyz="0 0.033 0.020"/>
      <mass value="1e-1"/>
      <inertia ixx="1e-2" ixy="0" ixz="0" iyy="1e-2" iyz="0" izz="1e-2"/>
    </inertial>
  </link>
  <link name="jaw">
    <visual>
      <geometry>
        <mesh filename="package://inmoov_meshes/meshes/jaw.stl" scale="0.001 0.001 0.001"/>
      </geometry>
      <origin rpy="0 0 3.1415" xyz="0 0 0"/>
      <material name="ccover">
        <color rgba="0.6 0.6 0.6 1"/>
      </material>
    </visual>
    <collision>
      <geometry>
        <mesh filename="package://inmoov_meshes/meshes/jaw.stl" scale="0.001 0.001 0.001"/>
      </geometry>
      <origin rpy="0 0 3.1415" xyz="0 0 0"/>
    </collision>
    <inertial>
      <origin rpy="0 0 3.1415" xyz="0 -0.063 -0.049"/>
      <mass value="3.1e-2"/>
      <inertia ixx="1e-2" ixy="0" ixz="0" iyy="1e-2" iyz="0" izz="1e-2"/>
    </inertial>
  </link>
  <link name="skull">
    <visual>
      <geometry>
        <mesh filename="package://inmoov_meshes/meshes/skull.stl" scale="0.001 0.001 0.001"/>
      </geometry>
      <origin rpy="0 0 0" xyz="0.001 0 0"/>
      <material name="ccover">
        <color rgba="0.6 0.6 0.6 1"/>
      </material>
    </visual>
    <collision>
      <geometry>
        <mesh filename="package://inmoov_meshes/meshes/skull.stl" scale="0.001 0.001 0.001"/>
      </geometry>
      <origin rpy="0 0 0" xyz="0.001 0 0"/>
    </collision>
    <inertial>
      <origin rpy="0 0 0" xyz="0.001 0.016 0.107"/>
      <mass value="6.6e-2"/>
      <inertia ixx="1e-2" ixy="0" ixz="0" iyy="1e-2" iyz="0" izz="1e-2"/>
    </inertial>
  </link>
  <link name="left_ear">
    <visual>
      <geometry>
        <mesh filename="package://inmoov_meshes/meshes/earleftv1.stl" scale="0.001 0.001 0.001"/>
      </geometry>
      <origin rpy="0 0 0" xyz="0 0 0"/>
      <material name="cframe">
        <color rgba="0.25 0.25 0.25 1"/>
      </material>
    </visual>
    <collision>
      <geometry>
        <mesh filename="package://inmoov_meshes/meshes/earleftv1.stl" scale="0.001 0.001 0.001"/>
      </geometry>
      <origin rpy="0 0 0" xyz="0 0 0"/>
    </collision>
    <inertial>
      <origin rpy="0 0 0" xyz="-0.008 0.004 0.003"/>
      <mass value="4.5e-2"/>
      <inertia ixx="1e-2" ixy="0" ixz="0" iyy="1e-2" iyz="0" izz="1e-2"/>
    </inertial>
  </link>
  <link name="right_ear">
    <visual>
      <geometry>
        <mesh filename="package://inmoov_meshes/meshes/earrightv1.stl" scale="0.001 0.001 0.001"/>
      </geometry>
      <origin rpy="0 0 0" xyz="0 0 0"/>
      <material name="cframe">
        <color rgba="0.25 0.25 0.25 1"/>
      </material>
    </visual>
    <collision>
      <geometry>
        <mesh filename="package://inmoov_meshes/meshes/earrightv1.stl" scale="0.001 0.001 0.001"/>
      </geometry>
      <origin rpy="0 0 0" xyz="0 0 0"/>
    </collision>
    <inertial>
      <origin rpy="0 0 0" xyz="0.008 0.004 0.003"/>
      <mass value="4.5e-2"/>
      <inertia ixx="1e-2" ixy="0" ixz="0" iyy="1e-2" iyz="0" izz="1e-2"/>
    </inertial>
  </link>
  <joint name="head_leftright" type="revolute">
    <axis xyz="0 0 1"/>
    <limit effort="2.422" lower="-1.05" upper="1.05" velocity="7.48"/>
    <origin rpy="0 0 0" xyz="0 0 0.0245"/>
    <parent link="head_base"/>
    <child link="head"/>
    <dynamics damping="0.7"/>
  </joint>
  <joint name="jaw" type="revolute">
    <axis xyz="1 0 0"/>
    <limit effort="1.9613" lower="0" upper="0.261" velocity="6.545"/>
    <origin rpy="0.085 0 3.1415" xyz="-0.001 0.0375 0.0437"/>
    <parent link="head"/>
    <child link="jaw"/>
    <dynamics damping="0.7"/>
  </joint>
  <joint name="skull" type="fixed">
    <origin rpy="0 0 0" xyz="-0.001 0.044 -0.0245"/>
    <parent link="head"/>
    <child link="skull"/>
  </joint>
  <joint name="left_ear" type="fixed">
    <origin rpy="0 0 0" xyz="-0.056 0.035 0.0437"/>
    <parent link="head"/>
    <child link="left_ear"/>
  </joint>
  <joint name="right_ear" type="fixed">
    <origin rpy="0 0 0" xyz="0.056 0.035 0.0437"/>
    <parent link="head"/>
    <child link="right_ear"/>
  </joint>
  <link name="face">
    <visual>
      <geometry>
        <mesh filename="package://inmoov_meshes/meshes/face.stl" scale="0.001 0.001 0.001"/>
      </geometry>
      <origin rpy="0 0 0" xyz="0 0 0"/>
      <material name="ccover">
        <color rgba="0.6 0.6 0.6 1"/>
      </material>
    </visual>
    <collision>
      <geometry>
        <mesh filename="package://inmoov_meshes/meshes/face.stl" scale="0.001 0.001 0.001"/>
      </geometry>
      <origin rpy="0 0 0" xyz="0 0 0"/>
    </collision>
    <inertial>
      <origin rpy="0 0 0" xyz="0 0.028 -0.015"/>
      <mass value="1.437e-2"/>
      <inertia ixx="3.79e-4" ixy="0" ixz="0" iyy="1.542e-3" iyz="0" izz="1.336e-3"/>
    </inertial>
  </link>
  <joint name="eyes_updown" type="revolute">
    <axis xyz="1 0 0"/>
    <limit effort="0.2354" lower="-0.45" upper="0.45" velocity="11.6356"/>
    <origin rpy="0 0 0" xyz="0 0 0"/>
    <parent link="face"/>
    <child link="eyesupport"/>
    <dynamics damping="0.7"/>
  </joint>
  <link name="eyesupport">
    <visual>
      <geometry>
        <mesh filename="package://inmoov_meshes/meshes/eyesupport.stl" scale="0.001 0.001 0.001"/>
      </geometry>
      <origin rpy="0 0 0" xyz="0 0 0"/>
      <material name="cframe">
        <color rgba="0.25 0.25 0.25 1"/>
      </material>
    </visual>
    <inertial>
      <origin rpy="0 0 0" xyz="0 -0.004 0.001"/>
      <mass value="1.47e-2"/>
      <inertia ixx="9e-6" ixy="0" ixz="0" iyy="2.3e-5" iyz="0" izz="4e-6"/>
    </inertial>
  </link>
  <link name="right_eyesupport">
    <visual>
      <geometry>
        <mesh filename="package://inmoov_meshes/meshes/right_eyesupport.stl" scale="0.001 0.001 0.001"/>
      </geometry>
      <origin rpy="0 0 0" xyz="0 0 0"/>
      <material name="cframe">
        <color rgba="0.25 0.25 0.25 1"/>
      </material>
    </visual>
    <inertial>
      <origin rpy="0 0 0" xyz="0 -0.004 0.003"/>
      <mass value="5.2e-3"/>
      <inertia ixx="1e-6" ixy="0" ixz="0" iyy="2.3e-5" iyz="0" izz="1e-6"/>
    </inertial>
  </link>
  <link name="right_camera">
    <visual>
      <geometry>
        <mesh filename="package://inmoov_meshes/meshes/camera.stl" scale="0.001 0.001 0.001"/>
      </geometry>
      <origin rpy="0 0 0" xyz="0 0 0"/>
      <material name="ccamera">
        <color rgba="0.1 0.1 0.1 1"/>
      </material>
    </visual>
    <inertial>
      <origin rpy="0 0 0" xyz="0 0.002 -0.002"/>
      <mass value="2.6e-2"/>
      <inertia ixx="1e-2" ixy="0" ixz="0" iyy="1e-2" iyz="0" izz="1e-2"/>
    </inertial>
  </link>
  <link name="right_eye">
    <visual>
      <geometry>
        <mesh filename="package://inmoov_meshes/meshes/eye.stl" scale="0.001 0.001 0.001"/>
      </geometry>
      <origin rpy="0 0 0" xyz="0 0 0"/>
      <material name="ceyeball">
        <color rgba="0.7 0.7 0.7 1"/>
      </material>
    </visual>
    <inertial>
      <origin rpy="0 0 0" xyz="0 0.003 0"/>
      <mass value="2.6e-3"/>
      <inertia ixx="1e-6" ixy="0" ixz="0" iyy="1e-6" iyz="0" izz="1e-6"/>
    </inertial>
  </link>
  <link name="right_iris">
    <visual>
      <geometry>
        <mesh filename="package://inmoov_meshes/meshes/iris.stl" scale="0.001 0.001 0.001"/>
      </geometry>
      <origin rpy="0 0 0" xyz="0 0 0"/>
      <material name="ciris">
        <color rgba="0.25 0.41 0.88 1"/>
      </material>
    </visual>
    <inertial>
      <origin rpy="0 0 0" xyz="0 0.002 0"/>
      <mass value="5e-4"/>
      <inertia ixx="1e-6" ixy="0" ixz="0" iyy="1e-6" iyz="0" izz="1e-6"/>
    </inertial>
  </link>
  <joint name="right_camera" type="fixed">
    <origin rpy="0 0 0" xyz="0 -0.001 0"/>
    <parent link="right_eyesupport"/>
    <child link="right_camera"/>
  </joint>
  <joint name="right_eye" type="fixed">
    <origin rpy="0 0 0" xyz="0 0.003 0"/>
    <parent link="right_eyesupport"/>
    <child link="right_eye"/>
  </joint>
  <joint name="right_iris" type="fixed">
    <origin rpy="0 0 0" xyz="0 0.0061 0"/>
    <parent link="right_eyesupport"/>
    <child link="right_iris"/>
  </joint>
  <joint name="eye_leftright" type="revolute">
    <axis xyz="0 0 1"/>
    <limit effort="0.2354" lower="-0.45" upper="0.45" velocity="11.6356"/>
    <origin rpy="0 0 0" xyz="0.033 0 -0.0036"/>
    <parent link="eyesupport"/>
    <child link="right_eyesupport"/>
    <dynamics damping="0.7"/>
  </joint>
  <link name="left_eyesupport">
    <visual>
      <geometry>
        <mesh filename="package://inmoov_meshes/meshes/left_eyesupport.stl" scale="0.001 0.001 0.001"/>
      </geometry>
      <origin rpy="0 0 0" xyz="0 0 0"/>
      <material name="cframe">
        <color rgba="0.25 0.25 0.25 1"/>
      </material>
    </visual>
    <inertial>
      <origin rpy="0 0 0" xyz="0 -0.004 0.003"/>
      <mass value="5.2e-3"/>
      <inertia ixx="1e-6" ixy="0" ixz="0" iyy="2.3e-5" iyz="0" izz="1e-6"/>
    </inertial>
  </link>
  <link name="left_camera">
    <visual>
      <geometry>
        <mesh filename="package://inmoov_meshes/meshes/camera.stl" scale="0.001 0.001 0.001"/>
      </geometry>
      <origin rpy="0 0 0" xyz="0 0 0"/>
      <material name="ccamera">
        <color rgba="0.1 0.1 0.1 1"/>
      </material>
    </visual>
    <inertial>
      <origin rpy="0 0 0" xyz="0 0.002 -0.002"/>
      <mass value="2.6e-2"/>
      <inertia ixx="1e-2" ixy="0" ixz="0" iyy="1e-2" iyz="0" izz="1e-2"/>
    </inertial>
  </link>
  <link name="left_eye">
    <visual>
      <geometry>
        <mesh filename="package://inmoov_meshes/meshes/eye.stl" scale="0.001 0.001 0.001"/>
      </geometry>
      <origin rpy="0 0 0" xyz="0 0 0"/>
      <material name="ceyeball">
        <color rgba="0.7 0.7 0.7 1"/>
      </material>
    </visual>
    <inertial>
      <origin rpy="0 0 0" xyz="0 0.003 0"/>
      <mass value="2.6e-3"/>
      <inertia ixx="1e-6" ixy="0" ixz="0" iyy="1e-6" iyz="0" izz="1e-6"/>
    </inertial>
  </link>
  <link name="left_iris">
    <visual>
      <geometry>
        <mesh filename="package://inmoov_meshes/meshes/iris.stl" scale="0.001 0.001 0.001"/>
      </geometry>
      <origin rpy="0 0 0" xyz="0 0 0"/>
      <material name="ciris">
        <color rgba="0.25 0.41 0.88 1"/>
      </material>
    </visual>
    <inertial>
      <origin rpy="0 0 0" xyz="0 0.002 0"/>
      <mass value="5e-4"/>
      <inertia ixx="1e-6" ixy="0" ixz="0" iyy="1e-6" iyz="0" izz="1e-6"/>
    </inertial>
  </link>
  <joint name="left_camera" type="fixed">
    <origin rpy="0 0 0" xyz="0 -0.001 0"/>
    <parent link="left_eyesupport"/>
    <child link="left_camera"/>
  </joint>
  <joint name="left_eye" type="fixed">
    <origin rpy="0 0 0" xyz="0 0.003 0"/>
    <parent link="left_eyesupport"/>
    <child link="left_eye"/>
  </joint>
  <joint name="left_iris" type="fixed">
    <origin rpy="0 0 0" xyz="0 0.0061 0"/>
    <parent link="left_eyesupport"/>
    <child link="left_iris"/>
  </joint>
  <joint name="left_eye_leftright" type="revolute">
    <axis xyz="0 0 1"/>
    <limit effort="0.2354" lower="-0.45" upper="0.45" velocity="11.6356"/>
    <mimic joint="eye_leftright" multiplier="1" offset="0"/>
    <origin rpy="0 0 0" xyz="-0.033 0 -0.0036"/>
    <parent link="eyesupport"/>
    <child link="left_eyesupport"/>
    <dynamics damping="0.7"/>
  </joint>
  <joint name="face" type="fixed">
    <origin rpy="0 0 0" xyz="0 0.0637 0.079"/>
    <parent link="skull"/>
    <child link="face"/>
  </joint>
  <link name="right_shoulder_base">
    <visual>
      <geometry>
        <mesh filename="package://inmoov_meshes/meshes/right_shoulder_base.stl" scale="0.001 0.001 0.001"/>
      </geometry>
      <origin rpy="0 0 0" xyz="0 0 0"/>
      <material name="cframe">
        <color rgba="0.25 0.25 0.25 1"/>
      </material>
    </visual>
    <inertial>
      <origin rpy="0 0 0" xyz="-0.018 -0.006 -0.060"/>
      <mass value="2.5e-1"/>
      <inertia ixx="1e-2" ixy="0" ixz="0" iyy="1e-2" iyz="0" izz="1e-2"/>
    </inertial>
  </link>
  <link name="right_shoulder">
    <visual>
      <geometry>
        <mesh filename="package://inmoov_meshes/meshes/right_shoulder.stl" scale="0.001 0.001 0.001"/>
      </geometry>
      <origin rpy="0 0 0" xyz="0 0 0"/>
      <material name="cframe">
        <color rgba="0.25 0.25 0.25 1"/>
      </material>
    </visual>
    <collision>
      <geometry>
        <mesh filename="package://inmoov_meshes/meshes/right_shoulder.stl" scale="0.001 0.001 0.001"/>
      </geometry>
      <origin rpy="0 0 0" xyz="0 0 0"/>
    </collision>
    <inertial>
      <origin rpy="0 0 0" xyz="0.058 -0.009 -0.034"/>
      <mass value="1.5e-1"/>
      <inertia ixx="1e-2" ixy="0" ixz="0" iyy="1e-2" iyz="0" izz="1e-2"/>
    </inertial>
  </link>
  <link name="right_bicep">
    <visual>
      <geometry>
        <mesh filename="package://inmoov_meshes/meshes/bicep.stl" scale="0.001 0.001 0.001"/>
      </geometry>
      <origin rpy="0 0 0" xyz="0 0 0"/>
      <material name="cframe">
        <color rgba="0.25 0.25 0.25 1"/>
      </material>
    </visual>
    <inertial>
      <origin rpy="0 0 0" xyz="0 -0.010 -0.082"/>
      <mass value="1.48e-1"/>
      <inertia ixx="1e-2" ixy="0" ixz="0" iyy="1e-2" iyz="0" izz="1e-2"/>
    </inertial>
  </link>
  <link name="right_bicepcover">
    <visual>
      <geometry>
        <mesh filename="package://inmoov_meshes/meshes/bicepcover.stl" scale="0.001 0.001 0.001"/>
      </geometry>
      <origin rpy="0 0 0" xyz="0 0 0"/>
      <material name="ccover">
        <color rgba="0.6 0.6 0.6 1"/>
      </material>
    </visual>
    <collision>
      <geometry>
        <mesh filename="package://inmoov_meshes/meshes/bicepcover.stl" scale="0.001 0.001 0.001"/>
      </geometry>
      <origin rpy="0 0 0" xyz="0 0 0"/>
    </collision>
    <inertial>
      <origin rpy="0 0 0" xyz="0 0.023 -0.116"/>
      <mass value="1.5e-1"/>
      <inertia ixx="4.061e-3" ixy="0" ixz="0" iyy="3.552e-3" iyz="0" izz="2.504e-3"/>
    </inertial>
  </link>
  <link name="right_forearm">
    <visual>
      <geometry>
        <mesh filename="package://inmoov_meshes/meshes/right_forearm.stl" scale="0.001 0.001 0.001"/>
      </geometry>
      <origin rpy="0 0 0" xyz="0.001 0 0"/>
      <material name="ccover">
        <color rgba="0.6 0.6 0.6 1"/>
      </material>
    </visual>
    <collision>
      <geometry>
        <mesh filename="package://inmoov_meshes/meshes/right_forearm.stl" scale="0.001 0.001 0.001"/>
      </geometry>
      <origin rpy="0 0 0" xyz="0.001 0 0"/>
    </collision>
    <inertial>
      <origin rpy="0 0 0" xyz="0 0 -0.163"/>
      <mass value="6e-2"/>
      <inertia ixx="1e-2" ixy="0" ixz="0" iyy="1e-2" iyz="0" izz="1e-2"/>
    </inertial>
  </link>
  <joint name="right_shoulder_up" type="revolute">
    <axis xyz="1 0 0"/>
    <limit effort="2.422" lower="0" upper="3.14" velocity="7.48"/>
    <origin rpy="0 0 0" xyz="0.012 0 -0.04"/>
    <parent link="right_shoulder_base"/>
    <child link="right_shoulder"/>
    <dynamics damping="0.7"/>
  </joint>
  <joint name="right_bicep_rotate" type="revolute">
    <axis xyz="0 0 1"/>
    <limit effort="2.422" lower="-0.872" upper="1.57" velocity="7.48"/>
    <origin rpy="0 0 0" xyz="0.066 0 -0.060"/>
    <parent link="right_shoulder"/>
    <child link="right_bicep"/>
    <dynamics damping="0.7"/>
  </joint>
  <joint name="right_elbow" type="revolute">
    <axis xyz="1 0 0"/>
    <limit effort="2.422" lower="0" upper="1.57" velocity="7.48"/>
    <origin rpy="0 0 0" xyz="0 -0.0278 -0.2235"/>
    <parent link="right_bicep"/>
    <child link="right_forearm"/>
    <dynamics damping="0.7"/>
  </joint>
  <joint name="right_bicepcover" type="fixed">
    <origin rpy="0 0 0" xyz="0 0 0"/>
    <parent link="right_bicep"/>
    <child link="right_bicepcover"/>
  </joint>
  <joint name="right_shoulder_side" type="revolute">
    <axis xyz="0 1 0"/>
    <limit effort="2.422" lower="-1.22" upper="0" velocity="7.48"/>
    <origin rpy="0 0 0" xyz="0.143 0 0.298"/>
    <parent link="torso"/>
    <child link="right_shoulder_base"/>
    <dynamics damping="0.7"/>
  </joint>
  <link name="right_hand">
    <visual>
      <geometry>
        <mesh filename="package://inmoov_meshes/meshes/right_hand.stl" scale="0.001 0.001 0.001"/>
      </geometry>
      <origin rpy="0 0 0" xyz="0 0 0"/>
      <material name="cframe">
        <color rgba="0.25 0.25 0.25 1"/>
      </material>
    </visual>
    <collision>
      <geometry>
        <mesh filename="package://inmoov_meshes/meshes/right_hand.stl" scale="0.001 0.001 0.001"/>
      </geometry>
      <origin rpy="0 0 0" xyz="0 0 0"/>
    </collision>
    <inertial>
      <origin rpy="0 0 0" xyz="0.0 0 -0.054"/>
      <mass value="4.4e-2"/>
      <inertia ixx="1e-3" ixy="0" ixz="0" iyy="1e-3" iyz="0" izz="1e-3"/>
    </inertial>
  </link>
  <link name="right_thumb_meta">
    <visual>
      <geometry>
        <mesh filename="package://inmoov_meshes/meshes/right_thumb5_1.stl" scale="0.001 0.001 0.001"/>
      </geometry>
      <origin rpy="3.1415 0 0" xyz="0 0 0"/>
      <material name="cframe">
        <color rgba="0.25 0.25 0.25 1"/>
      </material>
    </visual>
    <collision>
      <geometry>
        <mesh filename="package://inmoov_meshes/meshes/right_thumb5_1.stl" scale="0.001 0.001 0.001"/>
      </geometry>
      <origin rpy="3.1415 0 0" xyz="0 0 0"/>
    </collision>
    <inertial>
      <origin rpy="3.1415 0 0" xyz="0.0 0.001 -0.003"/>
      <mass value="5.3e-3"/>
      <inertia ixx="1e-3" ixy="0" ixz="0" iyy="1e-3" iyz="0" izz="1e-3"/>
    </inertial>
  </link>
  <link name="right_thumb_prox">
    <visual>
      <geometry>
        <mesh filename="package://inmoov_meshes/meshes/thumb5_2.stl" scale="0.001 0.001 0.001"/>
      </geometry>
      <origin rpy="0 0 3.1415" xyz="0 0 0"/>
      <material name="cframe">
        <color rgba="0.25 0.25 0.25 1"/>
      </material>
    </visual>
    <collision>
      <geometry>
        <mesh filename="package://inmoov_meshes/meshes/thumb5_2.stl" scale="0.001 0.001 0.001"/>
      </geometry>
      <origin rpy="0 0 3.1415" xyz="0 0 0"/>
    </collision>
    <inertial>
      <origin rpy="0 0 3.1415" xyz="0 0 -0.016"/>
      <mass value="4.2e-3"/>
      <inertia ixx="1e-3" ixy="0" ixz="0" iyy="1e-3" iyz="0" izz="1e-3"/>
    </inertial>
  </link>
  <link name="right_thumb_dist">
    <visual>
      <geometry>
        <mesh filename="package://inmoov_meshes/meshes/thumb5_3.stl" scale="0.001 0.001 0.001"/>
      </geometry>
      <origin rpy="0 0 3.1415" xyz="0 0 0"/>
      <material name="cframe">
        <color rgba="0.25 0.25 0.25 1"/>
      </material>
    </visual>
    <collision name="rthumb_collision">
      <geometry>
        <mesh filename="package://inmoov_meshes/meshes/thumb5_3.stl" scale="0.001 0.001 0.001"/>
      </geometry>
      <origin rpy="0 0 3.1415" xyz="0 0 0"/>
    </collision>
    <inertial>
      <origin rpy="0 0 3.1415" xyz="0 0 -0.013"/>
      <mass value="2.6e-3"/>
      <inertia ixx="1e-3" ixy="0" ixz="0" iyy="1e-3" iyz="0" izz="1e-3"/>
    </inertial>
  </link>
  <link name="right_index_prox">
    <visual>
      <geometry>
        <mesh filename="package://inmoov_meshes/meshes/index3_1.stl" scale="0.001 0.001 0.001"/>
      </geometry>
      <origin rpy="0 0 3.1415" xyz="0 0 0"/>
      <material name="cframe">
        <color rgba="0.25 0.25 0.25 1"/>
      </material>
    </visual>
    <collision>
      <geometry>
        <mesh filename="package://inmoov_meshes/meshes/index3_1.stl" scale="0.001 0.001 0.001"/>
      </geometry>
      <origin rpy="0 0 3.1415" xyz="0 0 0"/>
    </collision>
    <inertial>
      <origin rpy="0 0 3.1415" xyz="0 0 -0.018"/>
      <mass value="2.6e-3"/>
      <inertia ixx="1e-3" ixy="0" ixz="0" iyy="1e-3" iyz="0" izz="1e-3"/>
    </inertial>
  </link>
  <link name="right_index_mid">
    <visual>
      <geometry>
        <mesh filename="package://inmoov_meshes/meshes/index3_2.stl" scale="0.001 0.001 0.001"/>
      </geometry>
      <origin rpy="0 0 3.1415" xyz="0 0 0"/>
      <material name="cframe">
        <color rgba="0.25 0.25 0.25 1"/>
      </material>
    </visual>
    <collision>
      <geometry>
        <mesh filename="package://inmoov_meshes/meshes/index3_2.stl" scale="0.001 0.001 0.001"/>
      </geometry>
      <origin rpy="0 0 3.1415" xyz="0 0 0"/>
    </collision>
    <inertial>
      <origin rpy="0 0 3.1415" xyz="0 0.001 -0.011"/>
      <mass value="2.6e-3"/>
      <inertia ixx="1e-3" ixy="0" ixz="0" iyy="1e-3" iyz="0" izz="1e-3"/>
    </inertial>
  </link>
  <link name="right_index_dist">
    <visual>
      <geometry>
        <mesh filename="package://inmoov_meshes/meshes/index3_3.stl" scale="0.001 0.001 0.001"/>
      </geometry>
      <origin rpy="0 0 3.1415" xyz="0 0 0"/>
      <material name="cframe">
        <color rgba="0.25 0.25 0.25 1"/>
      </material>
    </visual>
    <collision name="rindex_collision">
      <geometry>
        <mesh filename="package://inmoov_meshes/meshes/index3_3.stl" scale="0.001 0.001 0.001"/>
      </geometry>
      <origin rpy="0 0 3.1415" xyz="0 0 0"/>
    </collision>
    <inertial>
      <origin rpy="0 0 3.1415" xyz="0 0 -0.014"/>
      <mass value="2.6e-3"/>
      <inertia ixx="1e-3" ixy="0" ixz="0" iyy="1e-3" iyz="0" izz="1e-3"/>
    </inertial>
  </link>
  <link name="right_middle_prox">
    <visual>
      <geometry>
        <mesh filename="package://inmoov_meshes/meshes/middle3_1.stl" scale="0.001 0.001 0.001"/>
      </geometry>
      <origin rpy="0 0 3.1415" xyz="0 0 0"/>
      <material name="cframe">
        <color rgba="0.25 0.25 0.25 1"/>
      </material>
    </visual>
    <collision>
      <geometry>
        <mesh filename="package://inmoov_meshes/meshes/middle3_1.stl" scale="0.001 0.001 0.001"/>
      </geometry>
      <origin rpy="0 0 3.1415" xyz="0 0 0"/>
    </collision>
    <inertial>
      <origin rpy="0 0 3.1415" xyz="0 0 -0.018"/>
      <mass value="2.6e-3"/>
      <inertia ixx="1e-3" ixy="0" ixz="0" iyy="1e-3" iyz="0" izz="1e-3"/>
    </inertial>
  </link>
  <link name="right_middle_mid">
    <visual>
      <geometry>
        <mesh filename="package://inmoov_meshes/meshes/middle3_2.stl" scale="0.001 0.001 0.001"/>
      </geometry>
      <origin rpy="0 0 3.1415" xyz="0 0 0"/>
      <material name="cframe">
        <color rgba="0.25 0.25 0.25 1"/>
      </material>
    </visual>
    <collision>
      <geometry>
        <mesh filename="package://inmoov_meshes/meshes/middle3_2.stl" scale="0.001 0.001 0.001"/>
      </geometry>
      <origin rpy="0 0 3.1415" xyz="0 0 0"/>
    </collision>
    <inertial>
      <origin rpy="0 0 3.1415" xyz="0 0.001 -0.011"/>
      <mass value="2.6e-3"/>
      <inertia ixx="1e-3" ixy="0" ixz="0" iyy="1e-3" iyz="0" izz="1e-3"/>
    </inertial>
  </link>
  <link name="right_middle_dist">
    <visual>
      <geometry>
        <mesh filename="package://inmoov_meshes/meshes/middle3_3.stl" scale="0.001 0.001 0.001"/>
      </geometry>
      <origin rpy="0 0 3.1415" xyz="0 0 0"/>
      <material name="cframe">
        <color rgba="0.25 0.25 0.25 1"/>
      </material>
    </visual>
    <collision name="rmiddle_collision">
      <geometry>
        <mesh filename="package://inmoov_meshes/meshes/middle3_3.stl" scale="0.001 0.001 0.001"/>
      </geometry>
      <origin rpy="0 0 3.1415" xyz="0 0 0"/>
    </collision>
    <inertial>
      <origin rpy="0 0 3.1415" xyz="0 0 -0.010"/>
      <mass value="2.6e-3"/>
      <inertia ixx="1e-3" ixy="0" ixz="0" iyy="1e-3" iyz="0" izz="1e-3"/>
    </inertial>
  </link>
  <link name="right_ring_meta">
    <visual>
      <geometry>
        <mesh filename="package://inmoov_meshes/meshes/right_ring3_1.stl" scale="0.001 0.001 0.001"/>
      </geometry>
      <origin rpy="0 0 3.1415" xyz="0 0 0"/>
      <material name="cframe">
        <color rgba="0.25 0.25 0.25 1"/>
      </material>
    </visual>
    <collision>
      <geometry>
        <mesh filename="package://inmoov_meshes/meshes/right_ring3_1.stl" scale="0.001 0.001 0.001"/>
      </geometry>
      <origin rpy="0 0 3.1415" xyz="0 0 0"/>
    </collision>
    <inertial>
      <origin rpy="0 0 3.1415" xyz="-0.0 0 -0.002"/>
      <mass value="2.6e-3"/>
      <inertia ixx="1e-3" ixy="0" ixz="0" iyy="1e-3" iyz="0" izz="1e-3"/>
    </inertial>
  </link>
  <link name="right_ring_prox">
    <visual>
      <geometry>
        <mesh filename="package://inmoov_meshes/meshes/ring3_2.stl" scale="0.001 0.001 0.001"/>
      </geometry>
      <origin rpy="0 0 3.1415" xyz="0 0 0"/>
      <material name="cframe">
        <color rgba="0.25 0.25 0.25 1"/>
      </material>
    </visual>
    <collision>
      <geometry>
        <mesh filename="package://inmoov_meshes/meshes/ring3_2.stl" scale="0.001 0.001 0.001"/>
      </geometry>
      <origin rpy="0 0 3.1415" xyz="0 0 0"/>
    </collision>
    <inertial>
      <origin rpy="0 0 3.1415" xyz="0 0 -0.016"/>
      <mass value="2.6e-3"/>
      <inertia ixx="1e-3" ixy="0" ixz="0" iyy="1e-3" iyz="0" izz="1e-3"/>
    </inertial>
  </link>
  <link name="right_ring_mid">
    <visual>
      <geometry>
        <mesh filename="package://inmoov_meshes/meshes/ring3_3.stl" scale="0.001 0.001 0.001"/>
      </geometry>
      <origin rpy="0 0 3.1415" xyz="0 0 0"/>
      <material name="cframe">
        <color rgba="0.25 0.25 0.25 1"/>
      </material>
    </visual>
    <collision>
      <geometry>
        <mesh filename="package://inmoov_meshes/meshes/ring3_3.stl" scale="0.001 0.001 0.001"/>
      </geometry>
      <origin rpy="0 0 3.1415" xyz="0 0 0"/>
    </collision>
    <inertial>
      <origin rpy="0 0 3.1415" xyz="0 0.001 -0.010"/>
      <mass value="2.6e-3"/>
      <inertia ixx="1e-3" ixy="0" ixz="0" iyy="1e-3" iyz="0" izz="1e-3"/>
    </inertial>
  </link>
  <link name="right_ring_dist">
    <visual>
      <geometry>
        <mesh filename="package://inmoov_meshes/meshes/ring3_4.stl" scale="0.001 0.001 0.001"/>
      </geometry>
      <origin rpy="0 0 3.1415" xyz="0 0 0"/>
      <material name="cframe">
        <color rgba="0.25 0.25 0.25 1"/>
      </material>
    </visual>
    <collision name="rring_collision">
      <geometry>
        <mesh filename="package://inmoov_meshes/meshes/ring3_4.stl" scale="0.001 0.001 0.001"/>
      </geometry>
      <origin rpy="0 0 3.1415" xyz="0 0 0"/>
    </collision>
    <inertial>
      <origin rpy="0 0 3.1415" xyz="0 0 -0.012"/>
      <mass value="2.6e-3"/>
      <inertia ixx="1e-3" ixy="0" ixz="0" iyy="1e-3" iyz="0" izz="1e-3"/>
    </inertial>
  </link>
  <link name="right_pinky_meta">
    <visual>
      <geometry>
        <mesh filename="package://inmoov_meshes/meshes/right_pinky3_1.stl" scale="0.001 0.001 0.001"/>
      </geometry>
      <origin rpy="0 0 3.1415" xyz="0 0 0"/>
      <material name="cframe">
        <color rgba="0.25 0.25 0.25 1"/>
      </material>
    </visual>
    <collision>
      <geometry>
        <mesh filename="package://inmoov_meshes/meshes/right_pinky3_1.stl" scale="0.001 0.001 0.001"/>
      </geometry>
      <origin rpy="0 0 3.1415" xyz="0 0 0"/>
    </collision>
    <inertial>
      <origin rpy="0 0 3.1415" xyz="-0.0 0 -0.005"/>
      <mass value="2.6e-3"/>
      <inertia ixx="1e-3" ixy="0" ixz="0" iyy="1e-3" iyz="0" izz="1e-3"/>
    </inertial>
  </link>
  <link name="right_pinky_prox">
    <visual>
      <geometry>
        <mesh filename="package://inmoov_meshes/meshes/pinky3_2.stl" scale="0.001 0.001 0.001"/>
      </geometry>
      <origin rpy="0 0 3.1415" xyz="0 0 0"/>
      <material name="cframe">
        <color rgba="0.25 0.25 0.25 1"/>
      </material>
    </visual>
    <collision>
      <geometry>
        <mesh filename="package://inmoov_meshes/meshes/pinky3_2.stl" scale="0.001 0.001 0.001"/>
      </geometry>
      <origin rpy="0 0 3.1415" xyz="0 0 0"/>
    </collision>
    <inertial>
      <origin rpy="0 0 3.1415" xyz="0 0 -0.010"/>
      <mass value="2.6e-3"/>
      <inertia ixx="1e-3" ixy="0" ixz="0" iyy="1e-3" iyz="0" izz="1e-3"/>
    </inertial>
  </link>
  <link name="right_pinky_mid">
    <visual>
      <geometry>
        <mesh filename="package://inmoov_meshes/meshes/pinky3_3.stl" scale="0.001 0.001 0.001"/>
      </geometry>
      <origin rpy="0 0 3.1415" xyz="0 0 0"/>
      <material name="cframe">
        <color rgba="0.25 0.25 0.25 1"/>
      </material>
    </visual>
    <collision>
      <geometry>
        <mesh filename="package://inmoov_meshes/meshes/pinky3_3.stl" scale="0.001 0.001 0.001"/>
      </geometry>
      <origin rpy="0 0 3.1415" xyz="0 0 0"/>
    </collision>
    <inertial>
      <origin rpy="0 0 3.1415" xyz="0 0 -0.009"/>
      <mass value="2.6e-3"/>
      <inertia ixx="1e-3" ixy="0" ixz="0" iyy="1e-3" iyz="0" izz="1e-3"/>
    </inertial>
  </link>
  <link name="right_pinky_dist">
    <visual>
      <geometry>
        <mesh filename="package://inmoov_meshes/meshes/pinky3_4.stl" scale="0.001 0.001 0.001"/>
      </geometry>
      <origin rpy="0 0 3.1415" xyz="0 0 0"/>
      <material name="cframe">
        <color rgba="0.25 0.25 0.25 1"/>
      </material>
    </visual>
    <collision name="rpinky_collision">
      <geometry>
        <mesh filename="package://inmoov_meshes/meshes/pinky3_4.stl" scale="0.001 0.001 0.001"/>
      </geometry>
      <origin rpy="0 0 3.1415" xyz="0 0 0"/>
    </collision>
    <inertial>
      <origin rpy="0 0 3.1415" xyz="0 0 -0.010"/>
      <mass value="2.6e-3"/>
      <inertia ixx="1e-3" ixy="0" ixz="0" iyy="1e-3" iyz="0" izz="1e-3"/>
    </inertial>
  </link>
  <joint name="right_thumbCMC" type="revolute">
    <axis xyz="0 0 1"/>
    <limit effort="1.9613" lower="-1.57" upper="0" velocity="6.545"/>
    <origin rpy="3.1415 0.1 0" xyz="-0.029 0 -0.0577"/>
    <mimic joint="right_thumbMCP" multiplier="-0.75" offset="0"/>
    <parent link="right_hand"/>
    <child link="right_thumb_meta"/>
  </joint>
  <joint name="right_thumbMCP" type="revolute">
    <axis xyz="1 0 0"/>
    <limit effort="1.9613" lower="0" upper="1.5" velocity="6.545"/>
    <origin rpy="0 2.3 -0.3" xyz="-0.02725 -0.0006 0.014"/>
    <parent link="right_thumb_meta"/>
    <child link="right_thumb_prox"/>
    <dynamics damping="0.7"/>
  </joint>
  <joint name="right_thumbIP" type="revolute">
    <axis xyz="1 0 0"/>
    <limit effort="1.9613" lower="0" upper="1.57" velocity="6.545"/>
    <origin rpy="0 0 0" xyz="0 0 -0.035"/>
    <mimic joint="right_thumbMCP" multiplier="1" offset="0"/>
    <parent link="right_thumb_prox"/>
    <child link="right_thumb_dist"/>
  </joint>
  <joint name="right_indexMCP" type="revolute">
    <axis xyz="1 0 0"/>
    <limit effort="1.9613" lower="0" upper="1.5" velocity="6.545"/>
    <origin rpy="0 -0.1 3.1415" xyz="-0.0342 -0.0015 -0.119"/>
    <mimic joint="right_indexPIP" multiplier="1" offset="0"/>
    <parent link="right_hand"/>
    <child link="right_index_prox"/>
  </joint>
  <joint name="right_indexPIP" type="revolute">
    <axis xyz="1 0 0"/>
    <limit effort="1.9613" lower="0" upper="1.5" velocity="6.545"/>
    <origin rpy="0 0 0" xyz="0 0.001 -0.03595"/>
    <parent link="right_index_prox"/>
    <child link="right_index_mid"/>
    <dynamics damping="0.7"/>
  </joint>
  <joint name="right_indexDIP" type="revolute">
    <axis xyz="1 0 0"/>
    <limit effort="1.9613" lower="0" upper="1.5" velocity="6.545"/>
    <origin rpy="0 0 0" xyz="0 0 -0.024"/>
    <mimic joint="right_indexPIP" multiplier="1" offset="0"/>
    <parent link="right_index_mid"/>
    <child link="right_index_dist"/>
  </joint>
  <joint name="right_middleMCP" type="revolute">
    <axis xyz="1 0 0"/>
    <limit effort="1.9613" lower="0" upper="1.5" velocity="6.545"/>
    <origin rpy="0 0 3.1415" xyz="-0.007 -0.00175 -0.12325"/>
    <mimic joint="right_middlePIP" multiplier="1" offset="0"/>
    <parent link="right_hand"/>
    <child link="right_middle_prox"/>
  </joint>
  <joint name="right_middlePIP" type="revolute">
    <axis xyz="1 0 0"/>
    <limit effort="1.9613" lower="0" upper="1.5" velocity="6.545"/>
    <origin rpy="0 0 0" xyz="0 0.000 -0.0389"/>
    <parent link="right_middle_prox"/>
    <child link="right_middle_mid"/>
    <dynamics damping="0.7"/>
  </joint>
  <joint name="right_middleDIP" type="revolute">
    <axis xyz="1 0 0"/>
    <limit effort="1.9613" lower="0" upper="1.57" velocity="6.545"/>
    <origin rpy="0 0 0" xyz="0 0.0005 -0.0259"/>
    <mimic joint="right_middlePIP" multiplier="1" offset="0"/>
    <parent link="right_middle_mid"/>
    <child link="right_middle_dist"/>
  </joint>
  <joint name="right_ringCMC" type="revolute">
    <axis xyz="0 0 1"/>
    <limit effort="1.9613" lower="-1.57" upper="0" velocity="6.545"/>
    <origin rpy="0 -0.7 3.1415" xyz="0.00705 0 -0.0794"/>
    <mimic joint="right_ringMCP" multiplier="0.1" offset="0"/>
    <parent link="right_hand"/>
    <child link="right_ring_meta"/>
  </joint>
  <joint name="right_ringMCP" type="revolute">
    <axis xyz="1 0 0"/>
    <limit effort="1.9613" lower="0" upper="1.5" velocity="6.545"/>
    <origin rpy="0 0.7775 0" xyz="-0.0351 0.00126 -0.0166"/>
    <parent link="right_ring_meta"/>
    <child link="right_ring_prox"/>
    <dynamics damping="0.7"/>
  </joint>
  <joint name="right_ringPIP" type="revolute">
    <axis xyz="1 0 0"/>
    <limit effort="1.9613" lower="0" upper="1.57" velocity="6.545"/>
    <origin rpy="0 0 0" xyz="0 0.0005 -0.0345"/>
    <mimic joint="right_ringMCP" multiplier="1" offset="0"/>
    <parent link="right_ring_prox"/>
    <child link="right_ring_mid"/>
  </joint>
  <joint name="right_ringDIP" type="revolute">
    <axis xyz="1 0 0"/>
    <limit effort="1.9613" lower="0" upper="1.57" velocity="6.545"/>
    <origin rpy="0 0 0" xyz="0 0.0004 -0.0229"/>
    <mimic joint="right_ringMCP" multiplier="1" offset="0"/>
    <parent link="right_ring_mid"/>
    <child link="right_ring_dist"/>
  </joint>
  <joint name="right_pinkyCMC" type="revolute">
    <axis xyz="0 0 1"/>
    <limit effort="1.9613" lower="-1.57" upper="0" velocity="6.545"/>
    <origin rpy="0 -0.7 3.1415" xyz="0.027 0 -0.0555"/>
    <mimic joint="right_pinkyMCP" multiplier="0.1" offset="0"/>
    <parent link="right_hand"/>
    <child link="right_pinky_meta"/>
  </joint>
  <joint name="right_pinkyMCP" type="revolute">
    <axis xyz="1 0 0"/>
    <limit effort="1.9613" lower="0" upper="1.5" velocity="6.545"/>
    <origin rpy="0 0.93 0" xyz="-0.046 -0 -0.0228"/>
    <parent link="right_pinky_meta"/>
    <child link="right_pinky_prox"/>
    <dynamics damping="0.7"/>
  </joint>
  <joint name="right_pinkyPIP" type="revolute">
    <axis xyz="1 0 0"/>
    <limit effort="1.9613" lower="0" upper="1.57" velocity="6.545"/>
    <origin rpy="0 0 0" xyz="0 0.0005 -0.031"/>
    <mimic joint="right_pinkyMCP" multiplier="1" offset="0"/>
    <parent link="right_pinky_prox"/>
    <child link="right_pinky_mid"/>
  </joint>
  <joint name="right_pinkyDIP" type="revolute">
    <axis xyz="1 0 0"/>
    <limit effort="1.9613" lower="0" upper="1.57" velocity="6.545"/>
    <origin rpy="0 0 0" xyz="0 0.0004 -0.0208"/>
    <mimic joint="right_pinkyMCP" multiplier="1" offset="0"/>
    <parent link="right_pinky_mid"/>
    <child link="right_pinky_dist"/>
  </joint>
  <link name="right_handcover">
    <visual>
      <geometry>
        <mesh filename="package://inmoov_meshes/meshes/right_cover_hand.stl" scale="0.001 0.001 0.001"/>
      </geometry>
      <origin rpy="0 0 0" xyz="0 0 0"/>
      <material name="ccover">
        <color rgba="0.6 0.6 0.6 1"/>
      </material>
    </visual>
    <collision>
      <geometry>
        <mesh filename="package://inmoov_meshes/meshes/right_cover_hand.stl" scale="0.001 0.001 0.001"/>
      </geometry>
      <origin rpy="0 0 0" xyz="0 0 0"/>
    </collision>
    <inertial>
      <origin rpy="0 0 0" xyz="-0.0 0.004 0.036"/>
      <mass value="2.2e-2"/>
      <inertia ixx="1e-5" ixy="0" ixz="0" iyy="1e-4" iyz="0" izz="1e-5"/>
    </inertial>
  </link>
  <link name="right_cover_handring">
    <visual>
      <geometry>
        <mesh filename="package://inmoov_meshes/meshes/right_cover_handring.stl" scale="0.001 0.001 0.001"/>
      </geometry>
      <origin rpy="0 0 3.1415" xyz="0 0 0"/>
      <material name="ccover">
        <color rgba="0.6 0.6 0.6 1"/>
      </material>
    </visual>
    <collision>
      <geometry>
        <mesh filename="package://inmoov_meshes/meshes/right_cover_handring.stl" scale="0.001 0.001 0.001"/>
      </geometry>
      <origin rpy="0 0 3.1415" xyz="0 0 0"/>
    </collision>
    <inertial>
      <origin rpy="0 0 3.1415" xyz="0 0.003 -0.002"/>
      <mass value="2.6e-3"/>
      <inertia ixx="1e-6" ixy="0" ixz="0" iyy="1e-6" iyz="0" izz="1e-6"/>
    </inertial>
  </link>
  <link name="right_cover_handpinky">
    <visual>
      <geometry>
        <mesh filename="package://inmoov_meshes/meshes/right_cover_handpinky.stl" scale="0.001 0.001 0.001"/>
      </geometry>
      <origin rpy="0 0 3.1415" xyz="0 0 0"/>
      <material name="ccover">
        <color rgba="0.6 0.6 0.6 1"/>
      </material>
    </visual>
    <collision>
      <geometry>
        <mesh filename="package://inmoov_meshes/meshes/right_cover_handpinky.stl" scale="0.001 0.001 0.001"/>
      </geometry>
      <origin rpy="0 0 3.1415" xyz="0 0 0"/>
    </collision>
    <inertial>
      <origin rpy="0 0 3.1415" xyz="0 0.002 0.002"/>
      <mass value="2.6e-3"/>
      <inertia ixx="1e-6" ixy="0" ixz="0" iyy="1e-6" iyz="0" izz="1e-6"/>
    </inertial>
  </link>
  <link name="right_cover_thumb">
    <visual>
      <geometry>
        <mesh filename="package://inmoov_meshes/meshes/right_cover_thumb.stl" scale="0.001 0.001 0.001"/>
      </geometry>
      <origin rpy="3.1415 0 0" xyz="0 0 0"/>
      <material name="ccover">
        <color rgba="0.6 0.6 0.6 1"/>
      </material>
    </visual>
    <collision>
      <geometry>
        <mesh filename="package://inmoov_meshes/meshes/right_cover_thumb.stl" scale="0.001 0.001 0.001"/>
      </geometry>
      <origin rpy="3.1415 0 0" xyz="0 0 0"/>
    </collision>
    <inertial>
      <origin rpy="0 0 3.1415" xyz="0 0 -0.002"/>
      <mass value="2.6e-3"/>
      <inertia ixx="1e-6" ixy="0" ixz="0" iyy="1e-6" iyz="0" izz="1e-6"/>
    </inertial>
  </link>
  <link name="right_cover_index">
    <visual>
      <geometry>
        <mesh filename="package://inmoov_meshes/meshes/right_cover_index.stl" scale="0.001 0.001 0.001"/>
      </geometry>
      <origin rpy="0 0 3.1415" xyz="0 0 0"/>
      <material name="ccover">
        <color rgba="0.6 0.6 0.6 1"/>
      </material>
    </visual>
    <collision>
      <geometry>
        <mesh filename="package://inmoov_meshes/meshes/right_cover_index.stl" scale="0.001 0.001 0.001"/>
      </geometry>
      <origin rpy="0 0 3.1415" xyz="0 0 0"/>
    </collision>
    <inertial>
      <origin rpy="0 0 3.1415" xyz="0 0 -0.002"/>
      <mass value="2.6e-3"/>
      <inertia ixx="1e-6" ixy="0" ixz="0" iyy="1e-6" iyz="0" izz="1e-6"/>
    </inertial>
  </link>
  <link name="right_cover_middle">
    <visual>
      <geometry>
        <mesh filename="package://inmoov_meshes/meshes/right_cover_middle.stl" scale="0.001 0.001 0.001"/>
      </geometry>
      <origin rpy="0 0 3.1415" xyz="0 0 0"/>
      <material name="ccover">
        <color rgba="0.6 0.6 0.6 1"/>
      </material>
    </visual>
    <collision>
      <geometry>
        <mesh filename="package://inmoov_meshes/meshes/right_cover_middle.stl" scale="0.001 0.001 0.001"/>
      </geometry>
      <origin rpy="0 0 3.1415" xyz="0 0 0"/>
    </collision>
    <inertial>
      <origin rpy="0 0 3.1415" xyz="0 0 -0.002"/>
      <mass value="2.6e-3"/>
      <inertia ixx="1e-6" ixy="0" ixz="0" iyy="1e-6" iyz="0" izz="1e-6"/>
    </inertial>
  </link>
  <link name="right_cover_ring">
    <visual>
      <geometry>
        <mesh filename="package://inmoov_meshes/meshes/right_cover_ring.stl" scale="0.001 0.001 0.001"/>
      </geometry>
      <origin rpy="0 0 3.1415" xyz="0 0 0"/>
      <material name="ccover">
        <color rgba="0.6 0.6 0.6 1"/>
      </material>
    </visual>
    <collision>
      <geometry>
        <mesh filename="package://inmoov_meshes/meshes/right_cover_ring.stl" scale="0.001 0.001 0.001"/>
      </geometry>
      <origin rpy="0 0 3.1415" xyz="0 0 0"/>
    </collision>
    <inertial>
      <origin rpy="0 0 3.1415" xyz="0 0 -0.002"/>
      <mass value="2.6e-3"/>
      <inertia ixx="1e-6" ixy="0" ixz="0" iyy="1e-6" iyz="0" izz="1e-6"/>
    </inertial>
  </link>
  <link name="right_cover_pinky">
    <visual>
      <geometry>
        <mesh filename="package://inmoov_meshes/meshes/right_cover_pinky.stl" scale="0.001 0.001 0.001"/>
      </geometry>
      <origin rpy="0 0 3.1415" xyz="0 0 0"/>
      <material name="ccover">
        <color rgba="0.6 0.6 0.6 1"/>
      </material>
    </visual>
    <collision>
      <geometry>
        <mesh filename="package://inmoov_meshes/meshes/right_cover_pinky.stl" scale="0.001 0.001 0.001"/>
      </geometry>
      <origin rpy="0 0 3.1415" xyz="0 0 0"/>
    </collision>
    <inertial>
      <origin rpy="0 0 3.1415" xyz="0 0 -0.002"/>
      <mass value="2.6e-3"/>
      <inertia ixx="1e-6" ixy="0" ixz="0" iyy="1e-6" iyz="0" izz="1e-6"/>
    </inertial>
  </link>
  <joint name="right_handcover" type="fixed">
    <origin rpy="0 0 0" xyz="-0.0192 0.009 -0.0977"/>
    <parent link="right_hand"/>
    <child link="right_handcover"/>
  </joint>
  <joint name="right_cover_handring" type="fixed">
    <origin rpy="0 0.7 0" xyz="-0.015 -0.009 -0.0008"/>
    <parent link="right_ring_meta"/>
    <child link="right_cover_handring"/>
  </joint>
  <joint name="right_cover_handpinky" type="fixed">
    <origin rpy="0 0.7 0" xyz="-0.0205 -0.01 -0.0069"/>
    <parent link="right_pinky_meta"/>
    <child link="right_cover_handpinky"/>
  </joint>
  <joint name="right_cover_thumb" type="fixed">
    <origin rpy="0 3.1 0" xyz="-0.02125 -0.01 -0.0047"/>
    <parent link="right_thumb_meta"/>
    <child link="right_cover_thumb"/>
  </joint>
  <joint name="right_cover_index" type="fixed">
    <origin rpy="0.05 0 0" xyz="0 -0.0071 -0.012"/>
    <parent link="right_index_prox"/>
    <child link="right_cover_index"/>
  </joint>
  <joint name="right_cover_middle" type="fixed">
    <origin rpy="-0.05 0 0" xyz="0 -0.0071 -0.012"/>
    <parent link="right_middle_prox"/>
    <child link="right_cover_middle"/>
  </joint>
  <joint name="right_cover_ring" type="fixed">
    <origin rpy="-0.05 -0.1 0" xyz="0 -0.005 -0.011"/>
    <parent link="right_ring_prox"/>
    <child link="right_cover_ring"/>
  </joint>
  <joint name="right_cover_pinky" type="fixed">
    <origin rpy="-0.05 -0.1 0" xyz="0 -0.005 -0.0105"/>
    <parent link="right_pinky_prox"/>
    <child link="right_cover_pinky"/>
  </joint>
  <joint name="right_wrist" type="revolute">
    <axis xyz="0 0 1"/>
    <limit effort="0.9807" lower="-3.14" upper="0" velocity="5.236"/>
    <origin rpy="0 0 0" xyz="-0.01 -0.0144 -0.2885"/>
    <parent link="right_forearm"/>
    <child link="right_hand"/>
    <dynamics damping="0.7"/>
  </joint>
  <link name="left_shoulder_base">
    <visual>
      <geometry>
        <mesh filename="package://inmoov_meshes/meshes/left_shoulder_base.stl" scale="0.001 0.001 0.001"/>
      </geometry>
      <origin rpy="0 0 0" xyz="0 0 0"/>
      <material name="cframe">
        <color rgba="0.25 0.25 0.25 1"/>
      </material>
    </visual>
    <inertial>
      <origin rpy="0 0 0" xyz="0.018 -0.006 -0.060"/>
      <mass value="2.5e-1"/>
      <inertia ixx="1e-2" ixy="0" ixz="0" iyy="1e-2" iyz="0" izz="1e-2"/>
    </inertial>
  </link>
  <link name="left_shoulder">
    <visual>
      <geometry>
        <mesh filename="package://inmoov_meshes/meshes/left_shoulder.stl" scale="0.001 0.001 0.001"/>
      </geometry>
      <origin rpy="0 0 0" xyz="0 0 0"/>
      <material name="cframe">
        <color rgba="0.25 0.25 0.25 1"/>
      </material>
    </visual>
    <collision>
      <geometry>
        <mesh filename="package://inmoov_meshes/meshes/left_shoulder.stl" scale="0.001 0.001 0.001"/>
      </geometry>
      <origin rpy="0 0 0" xyz="0 0 0"/>
    </collision>
    <inertial>
      <origin rpy="0 0 0" xyz="-0.058 -0.009 -0.034"/>
      <mass value="1.5e-1"/>
      <inertia ixx="1e-2" ixy="0" ixz="0" iyy="1e-2" iyz="0" izz="1e-2"/>
    </inertial>
  </link>
  <link name="left_bicep">
    <visual>
      <geometry>
        <mesh filename="package://inmoov_meshes/meshes/bicep.stl" scale="0.001 0.001 0.001"/>
      </geometry>
      <origin rpy="0 0 0" xyz="0 0 0"/>
      <material name="cframe">
        <color rgba="0.25 0.25 0.25 1"/>
      </material>
    </visual>
    <inertial>
      <origin rpy="0 0 0" xyz="0 -0.010 -0.082"/>
      <mass value="1.48e-1"/>
      <inertia ixx="1e-2" ixy="0" ixz="0" iyy="1e-2" iyz="0" izz="1e-2"/>
    </inertial>
  </link>
  <link name="left_bicepcover">
    <visual>
      <geometry>
        <mesh filename="package://inmoov_meshes/meshes/bicepcover.stl" scale="0.001 0.001 0.001"/>
      </geometry>
      <origin rpy="0 0 0" xyz="0 0 0"/>
      <material name="ccover">
        <color rgba="0.6 0.6 0.6 1"/>
      </material>
    </visual>
    <collision>
      <geometry>
        <mesh filename="package://inmoov_meshes/meshes/bicepcover.stl" scale="0.001 0.001 0.001"/>
      </geometry>
      <origin rpy="0 0 0" xyz="0 0 0"/>
    </collision>
    <inertial>
      <origin rpy="0 0 0" xyz="0 0.023 -0.116"/>
      <mass value="1.5e-1"/>
      <inertia ixx="4.061e-3" ixy="0" ixz="0" iyy="3.552e-3" iyz="0" izz="2.504e-3"/>
    </inertial>
  </link>
  <link name="left_forearm">
    <visual>
      <geometry>
        <mesh filename="package://inmoov_meshes/meshes/left_forearm.stl" scale="0.001 0.001 0.001"/>
      </geometry>
      <origin rpy="0 0 0" xyz="-0.001 0 0"/>
      <material name="ccover">
        <color rgba="0.6 0.6 0.6 1"/>
      </material>
    </visual>
    <collision>
      <geometry>
        <mesh filename="package://inmoov_meshes/meshes/left_forearm.stl" scale="0.001 0.001 0.001"/>
      </geometry>
      <origin rpy="0 0 0" xyz="-0.001 0 0"/>
    </collision>
    <inertial>
      <origin rpy="0 0 0" xyz="0 0 -0.163"/>
      <mass value="6e-2"/>
      <inertia ixx="1e-2" ixy="0" ixz="0" iyy="1e-2" iyz="0" izz="1e-2"/>
    </inertial>
  </link>
  <joint name="left_shoulder_up" type="revolute">
    <axis xyz="1 0 0"/>
    <limit effort="2.422" lower="0" upper="3.14" velocity="7.48"/>
    <origin rpy="0 0 0" xyz="-0.012 0 -0.04"/>
    <parent link="left_shoulder_base"/>
    <child link="left_shoulder"/>
    <dynamics damping="0.7"/>
  </joint>
  <joint name="left_bicep_rotate" type="revolute">
    <axis xyz="0 0 1"/>
    <limit effort="2.422" lower="-0.872" upper="1.57" velocity="7.48"/>
    <origin rpy="0 0 0" xyz="-0.066 0 -0.060"/>
    <parent link="left_shoulder"/>
    <child link="left_bicep"/>
    <dynamics damping="0.7"/>
  </joint>
  <joint name="left_elbow" type="revolute">
    <axis xyz="1 0 0"/>
    <limit effort="2.422" lower="0" upper="1.57" velocity="7.48"/>
    <origin rpy="0 0 0" xyz="0 -0.0278 -0.2235"/>
    <parent link="left_bicep"/>
    <child link="left_forearm"/>
    <dynamics damping="0.7"/>
  </joint>
  <joint name="left_bicepcover" type="fixed">
    <origin rpy="0 0 0" xyz="0 0 0"/>
    <parent link="left_bicep"/>
    <child link="left_bicepcover"/>
  </joint>
  <joint name="left_shoulder_side" type="revolute">
    <axis xyz="0 1 0"/>
    <limit effort="2.422" lower="0" upper="1.22" velocity="7.48"/>
    <origin rpy="0 0 0" xyz="-0.143 0 0.298"/>
    <parent link="torso"/>
    <child link="left_shoulder_base"/>
    <dynamics damping="0.7"/>
  </joint>
  <link name="left_hand">
    <visual>
      <geometry>
        <mesh filename="package://inmoov_meshes/meshes/left_hand.stl" scale="0.001 0.001 0.001"/>
      </geometry>
      <origin rpy="0 0 0" xyz="0 0 0"/>
      <material name="cframe">
        <color rgba="0.25 0.25 0.25 1"/>
      </material>
    </visual>
    <collision>
      <geometry>
        <mesh filename="package://inmoov_meshes/meshes/left_hand.stl" scale="0.001 0.001 0.001"/>
      </geometry>
      <origin rpy="0 0 0" xyz="0 0 0"/>
    </collision>
    <inertial>
      <origin rpy="0 0 0" xyz="0.0157079632695 0 -0.054"/>
      <mass value="4.4e-2"/>
      <inertia ixx="1e-3" ixy="0" ixz="0" iyy="1e-3" iyz="0" izz="1e-3"/>
    </inertial>
  </link>
  <link name="left_thumb_meta">
    <visual>
      <geometry>
        <mesh filename="package://inmoov_meshes/meshes/left_thumb5_1.stl" scale="0.001 0.001 0.001"/>
      </geometry>
      <origin rpy="3.1415 0 0" xyz="0 0 0"/>
      <material name="cframe">
        <color rgba="0.25 0.25 0.25 1"/>
      </material>
    </visual>
    <collision>
      <geometry>
        <mesh filename="package://inmoov_meshes/meshes/left_thumb5_1.stl" scale="0.001 0.001 0.001"/>
      </geometry>
      <origin rpy="3.1415 0 0" xyz="0 0 0"/>
    </collision>
    <inertial>
      <origin rpy="3.1415 0 0" xyz="0.0439822971546 0.001 -0.003"/>
      <mass value="5.3e-3"/>
      <inertia ixx="1e-3" ixy="0" ixz="0" iyy="1e-3" iyz="0" izz="1e-3"/>
    </inertial>
  </link>
  <link name="left_thumb_prox">
    <visual>
      <geometry>
        <mesh filename="package://inmoov_meshes/meshes/thumb5_2.stl" scale="0.001 0.001 0.001"/>
      </geometry>
      <origin rpy="0 0 3.1415" xyz="0 0 0"/>
      <material name="cframe">
        <color rgba="0.25 0.25 0.25 1"/>
      </material>
    </visual>
    <collision>
      <geometry>
        <mesh filename="package://inmoov_meshes/meshes/thumb5_2.stl" scale="0.001 0.001 0.001"/>
      </geometry>
      <origin rpy="0 0 3.1415" xyz="0 0 0"/>
    </collision>
    <inertial>
      <origin rpy="0 0 3.1415" xyz="0 0 -0.016"/>
      <mass value="4.2e-3"/>
      <inertia ixx="1e-3" ixy="0" ixz="0" iyy="1e-3" iyz="0" izz="1e-3"/>
    </inertial>
  </link>
  <link name="left_thumb_dist">
    <visual>
      <geometry>
        <mesh filename="package://inmoov_meshes/meshes/thumb5_3.stl" scale="0.001 0.001 0.001"/>
      </geometry>
      <origin rpy="0 0 3.1415" xyz="0 0 0"/>
      <material name="cframe">
        <color rgba="0.25 0.25 0.25 1"/>
      </material>
    </visual>
    <collision name="lthumb_collision">
      <geometry>
        <mesh filename="package://inmoov_meshes/meshes/thumb5_3.stl" scale="0.001 0.001 0.001"/>
      </geometry>
      <origin rpy="0 0 3.1415" xyz="0 0 0"/>
    </collision>
    <inertial>
      <origin rpy="0 0 3.1415" xyz="0 0 -0.013"/>
      <mass value="2.6e-3"/>
      <inertia ixx="1e-3" ixy="0" ixz="0" iyy="1e-3" iyz="0" izz="1e-3"/>
    </inertial>
  </link>
  <link name="left_index_prox">
    <visual>
      <geometry>
        <mesh filename="package://inmoov_meshes/meshes/index3_1.stl" scale="0.001 0.001 0.001"/>
      </geometry>
      <origin rpy="0 0 3.1415" xyz="0 0 0"/>
      <material name="cframe">
        <color rgba="0.25 0.25 0.25 1"/>
      </material>
    </visual>
    <collision>
      <geometry>
        <mesh filename="package://inmoov_meshes/meshes/index3_1.stl" scale="0.001 0.001 0.001"/>
      </geometry>
      <origin rpy="0 0 3.1415" xyz="0 0 0"/>
    </collision>
    <inertial>
      <origin rpy="0 0 3.1415" xyz="0 0 -0.018"/>
      <mass value="2.6e-3"/>
      <inertia ixx="1e-3" ixy="0" ixz="0" iyy="1e-3" iyz="0" izz="1e-3"/>
    </inertial>
  </link>
  <link name="left_index_mid">
    <visual>
      <geometry>
        <mesh filename="package://inmoov_meshes/meshes/index3_2.stl" scale="0.001 0.001 0.001"/>
      </geometry>
      <origin rpy="0 0 3.1415" xyz="0 0 0"/>
      <material name="cframe">
        <color rgba="0.25 0.25 0.25 1"/>
      </material>
    </visual>
    <collision>
      <geometry>
        <mesh filename="package://inmoov_meshes/meshes/index3_2.stl" scale="0.001 0.001 0.001"/>
      </geometry>
      <origin rpy="0 0 3.1415" xyz="0 0 0"/>
    </collision>
    <inertial>
      <origin rpy="0 0 3.1415" xyz="0 0.001 -0.011"/>
      <mass value="2.6e-3"/>
      <inertia ixx="1e-3" ixy="0" ixz="0" iyy="1e-3" iyz="0" izz="1e-3"/>
    </inertial>
  </link>
  <link name="left_index_dist">
    <visual>
      <geometry>
        <mesh filename="package://inmoov_meshes/meshes/index3_3.stl" scale="0.001 0.001 0.001"/>
      </geometry>
      <origin rpy="0 0 3.1415" xyz="0 0 0"/>
      <material name="cframe">
        <color rgba="0.25 0.25 0.25 1"/>
      </material>
    </visual>
    <collision name="lindex_collision">
      <geometry>
        <mesh filename="package://inmoov_meshes/meshes/index3_3.stl" scale="0.001 0.001 0.001"/>
      </geometry>
      <origin rpy="0 0 3.1415" xyz="0 0 0"/>
    </collision>
    <inertial>
      <origin rpy="0 0 3.1415" xyz="0 0 -0.014"/>
      <mass value="2.6e-3"/>
      <inertia ixx="1e-3" ixy="0" ixz="0" iyy="1e-3" iyz="0" izz="1e-3"/>
    </inertial>
  </link>
  <link name="left_middle_prox">
    <visual>
      <geometry>
        <mesh filename="package://inmoov_meshes/meshes/middle3_1.stl" scale="0.001 0.001 0.001"/>
      </geometry>
      <origin rpy="0 0 3.1415" xyz="0 0 0"/>
      <material name="cframe">
        <color rgba="0.25 0.25 0.25 1"/>
      </material>
    </visual>
    <collision>
      <geometry>
        <mesh filename="package://inmoov_meshes/meshes/middle3_1.stl" scale="0.001 0.001 0.001"/>
      </geometry>
      <origin rpy="0 0 3.1415" xyz="0 0 0"/>
    </collision>
    <inertial>
      <origin rpy="0 0 3.1415" xyz="0 0 -0.018"/>
      <mass value="2.6e-3"/>
      <inertia ixx="1e-3" ixy="0" ixz="0" iyy="1e-3" iyz="0" izz="1e-3"/>
    </inertial>
  </link>
  <link name="left_middle_mid">
    <visual>
      <geometry>
        <mesh filename="package://inmoov_meshes/meshes/middle3_2.stl" scale="0.001 0.001 0.001"/>
      </geometry>
      <origin rpy="0 0 3.1415" xyz="0 0 0"/>
      <material name="cframe">
        <color rgba="0.25 0.25 0.25 1"/>
      </material>
    </visual>
    <collision>
      <geometry>
        <mesh filename="package://inmoov_meshes/meshes/middle3_2.stl" scale="0.001 0.001 0.001"/>
      </geometry>
      <origin rpy="0 0 3.1415" xyz="0 0 0"/>
    </collision>
    <inertial>
      <origin rpy="0 0 3.1415" xyz="0 0.001 -0.011"/>
      <mass value="2.6e-3"/>
      <inertia ixx="1e-3" ixy="0" ixz="0" iyy="1e-3" iyz="0" izz="1e-3"/>
    </inertial>
  </link>
  <link name="left_middle_dist">
    <visual>
      <geometry>
        <mesh filename="package://inmoov_meshes/meshes/middle3_3.stl" scale="0.001 0.001 0.001"/>
      </geometry>
      <origin rpy="0 0 3.1415" xyz="0 0 0"/>
      <material name="cframe">
        <color rgba="0.25 0.25 0.25 1"/>
      </material>
    </visual>
    <collision name="lmiddle_collision">
      <geometry>
        <mesh filename="package://inmoov_meshes/meshes/middle3_3.stl" scale="0.001 0.001 0.001"/>
      </geometry>
      <origin rpy="0 0 3.1415" xyz="0 0 0"/>
    </collision>
    <inertial>
      <origin rpy="0 0 3.1415" xyz="0 0 -0.010"/>
      <mass value="2.6e-3"/>
      <inertia ixx="1e-3" ixy="0" ixz="0" iyy="1e-3" iyz="0" izz="1e-3"/>
    </inertial>
  </link>
  <link name="left_ring_meta">
    <visual>
      <geometry>
        <mesh filename="package://inmoov_meshes/meshes/left_ring3_1.stl" scale="0.001 0.001 0.001"/>
      </geometry>
      <origin rpy="0 0 3.1415" xyz="0 0 0"/>
      <material name="cframe">
        <color rgba="0.25 0.25 0.25 1"/>
      </material>
    </visual>
    <collision>
      <geometry>
        <mesh filename="package://inmoov_meshes/meshes/left_ring3_1.stl" scale="0.001 0.001 0.001"/>
      </geometry>
      <origin rpy="0 0 3.1415" xyz="0 0 0"/>
    </collision>
    <inertial>
      <origin rpy="0 0 3.1415" xyz="-0.0502654824624 0 -0.002"/>
      <mass value="2.6e-3"/>
      <inertia ixx="1e-3" ixy="0" ixz="0" iyy="1e-3" iyz="0" izz="1e-3"/>
    </inertial>
  </link>
  <link name="left_ring_prox">
    <visual>
      <geometry>
        <mesh filename="package://inmoov_meshes/meshes/ring3_2.stl" scale="0.001 0.001 0.001"/>
      </geometry>
      <origin rpy="0 0 3.1415" xyz="0 0 0"/>
      <material name="cframe">
        <color rgba="0.25 0.25 0.25 1"/>
      </material>
    </visual>
    <collision>
      <geometry>
        <mesh filename="package://inmoov_meshes/meshes/ring3_2.stl" scale="0.001 0.001 0.001"/>
      </geometry>
      <origin rpy="0 0 3.1415" xyz="0 0 0"/>
    </collision>
    <inertial>
      <origin rpy="0 0 3.1415" xyz="0 0 -0.016"/>
      <mass value="2.6e-3"/>
      <inertia ixx="1e-3" ixy="0" ixz="0" iyy="1e-3" iyz="0" izz="1e-3"/>
    </inertial>
  </link>
  <link name="left_ring_mid">
    <visual>
      <geometry>
        <mesh filename="package://inmoov_meshes/meshes/ring3_3.stl" scale="0.001 0.001 0.001"/>
      </geometry>
      <origin rpy="0 0 3.1415" xyz="0 0 0"/>
      <material name="cframe">
        <color rgba="0.25 0.25 0.25 1"/>
      </material>
    </visual>
    <collision>
      <geometry>
        <mesh filename="package://inmoov_meshes/meshes/ring3_3.stl" scale="0.001 0.001 0.001"/>
      </geometry>
      <origin rpy="0 0 3.1415" xyz="0 0 0"/>
    </collision>
    <inertial>
      <origin rpy="0 0 3.1415" xyz="0 0.001 -0.010"/>
      <mass value="2.6e-3"/>
      <inertia ixx="1e-3" ixy="0" ixz="0" iyy="1e-3" iyz="0" izz="1e-3"/>
    </inertial>
  </link>
  <link name="left_ring_dist">
    <visual>
      <geometry>
        <mesh filename="package://inmoov_meshes/meshes/ring3_4.stl" scale="0.001 0.001 0.001"/>
      </geometry>
      <origin rpy="0 0 3.1415" xyz="0 0 0"/>
      <material name="cframe">
        <color rgba="0.25 0.25 0.25 1"/>
      </material>
    </visual>
    <collision name="lring_collision">
      <geometry>
        <mesh filename="package://inmoov_meshes/meshes/ring3_4.stl" scale="0.001 0.001 0.001"/>
      </geometry>
      <origin rpy="0 0 3.1415" xyz="0 0 0"/>
    </collision>
    <inertial>
      <origin rpy="0 0 3.1415" xyz="0 0 -0.012"/>
      <mass value="2.6e-3"/>
      <inertia ixx="1e-3" ixy="0" ixz="0" iyy="1e-3" iyz="0" izz="1e-3"/>
    </inertial>
  </link>
  <link name="left_pinky_meta">
    <visual>
      <geometry>
        <mesh filename="package://inmoov_meshes/meshes/left_pinky3_1.stl" scale="0.001 0.001 0.001"/>
      </geometry>
      <origin rpy="0 0 3.1415" xyz="0 0 0"/>
      <material name="cframe">
        <color rgba="0.25 0.25 0.25 1"/>
      </material>
    </visual>
    <collision>
      <geometry>
        <mesh filename="package://inmoov_meshes/meshes/left_pinky3_1.stl" scale="0.001 0.001 0.001"/>
      </geometry>
      <origin rpy="0 0 3.1415" xyz="0 0 0"/>
    </collision>
    <inertial>
      <origin rpy="0 0 3.1415" xyz="-0.0565486677702 0 -0.005"/>
      <mass value="2.6e-3"/>
      <inertia ixx="1e-3" ixy="0" ixz="0" iyy="1e-3" iyz="0" izz="1e-3"/>
    </inertial>
  </link>
  <link name="left_pinky_prox">
    <visual>
      <geometry>
        <mesh filename="package://inmoov_meshes/meshes/pinky3_2.stl" scale="0.001 0.001 0.001"/>
      </geometry>
      <origin rpy="0 0 3.1415" xyz="0 0 0"/>
      <material name="cframe">
        <color rgba="0.25 0.25 0.25 1"/>
      </material>
    </visual>
    <collision>
      <geometry>
        <mesh filename="package://inmoov_meshes/meshes/pinky3_2.stl" scale="0.001 0.001 0.001"/>
      </geometry>
      <origin rpy="0 0 3.1415" xyz="0 0 0"/>
    </collision>
    <inertial>
      <origin rpy="0 0 3.1415" xyz="0 0 -0.010"/>
      <mass value="2.6e-3"/>
      <inertia ixx="1e-3" ixy="0" ixz="0" iyy="1e-3" iyz="0" izz="1e-3"/>
    </inertial>
  </link>
  <link name="left_pinky_mid">
    <visual>
      <geometry>
        <mesh filename="package://inmoov_meshes/meshes/pinky3_3.stl" scale="0.001 0.001 0.001"/>
      </geometry>
      <origin rpy="0 0 3.1415" xyz="0 0 0"/>
      <material name="cframe">
        <color rgba="0.25 0.25 0.25 1"/>
      </material>
    </visual>
    <collision>
      <geometry>
        <mesh filename="package://inmoov_meshes/meshes/pinky3_3.stl" scale="0.001 0.001 0.001"/>
      </geometry>
      <origin rpy="0 0 3.1415" xyz="0 0 0"/>
    </collision>
    <inertial>
      <origin rpy="0 0 3.1415" xyz="0 0 -0.009"/>
      <mass value="2.6e-3"/>
      <inertia ixx="1e-3" ixy="0" ixz="0" iyy="1e-3" iyz="0" izz="1e-3"/>
    </inertial>
  </link>
  <link name="left_pinky_dist">
    <visual>
      <geometry>
        <mesh filename="package://inmoov_meshes/meshes/pinky3_4.stl" scale="0.001 0.001 0.001"/>
      </geometry>
      <origin rpy="0 0 3.1415" xyz="0 0 0"/>
      <material name="cframe">
        <color rgba="0.25 0.25 0.25 1"/>
      </material>
    </visual>
    <collision name="lpinky_collision">
      <geometry>
        <mesh filename="package://inmoov_meshes/meshes/pinky3_4.stl" scale="0.001 0.001 0.001"/>
      </geometry>
      <origin rpy="0 0 3.1415" xyz="0 0 0"/>
    </collision>
    <inertial>
      <origin rpy="0 0 3.1415" xyz="0 0 -0.010"/>
      <mass value="2.6e-3"/>
      <inertia ixx="1e-3" ixy="0" ixz="0" iyy="1e-3" iyz="0" izz="1e-3"/>
    </inertial>
  </link>
  <joint name="left_thumbCMC" type="revolute">
    <axis xyz="0 0 1"/>
    <limit effort="1.9613" lower="0" upper="1.57" velocity="6.545"/>
    <origin rpy="3.1415 -0.1 0" xyz="0.029 0 -0.0577"/>
    <mimic joint="left_thumbMCP" multiplier="0.75" offset="0"/>
    <parent link="left_hand"/>
    <child link="left_thumb_meta"/>
  </joint>
  <joint name="left_thumbMCP" type="revolute">
    <axis xyz="1 0 0"/>
    <limit effort="1.9613" lower="0" upper="1.5" velocity="6.545"/>
    <origin rpy="0 -2.3 0.3" xyz="0.02725 -0.0006 0.014"/>
    <parent link="left_thumb_meta"/>
    <child link="left_thumb_prox"/>
    <dynamics damping="0.7"/>
  </joint>
  <joint name="left_thumbIP" type="revolute">
    <axis xyz="1 0 0"/>
    <limit effort="1.9613" lower="0" upper="1.57" velocity="6.545"/>
    <origin rpy="0 0 0" xyz="0 0 -0.035"/>
    <mimic joint="left_thumbMCP" multiplier="1" offset="0"/>
    <parent link="left_thumb_prox"/>
    <child link="left_thumb_dist"/>
  </joint>
  <joint name="left_indexMCP" type="revolute">
    <axis xyz="1 0 0"/>
    <limit effort="1.9613" lower="0" upper="1.5" velocity="6.545"/>
    <origin rpy="0 0.1 3.1415" xyz="0.0342 -0.0015 -0.119"/>
    <mimic joint="left_indexPIP" multiplier="1" offset="0"/>
    <parent link="left_hand"/>
    <child link="left_index_prox"/>
  </joint>
  <joint name="left_indexPIP" type="revolute">
    <axis xyz="1 0 0"/>
    <limit effort="1.9613" lower="0" upper="1.5" velocity="6.545"/>
    <origin rpy="0 0 0" xyz="0 0.001 -0.03595"/>
    <parent link="left_index_prox"/>
    <child link="left_index_mid"/>
    <dynamics damping="0.7"/>
  </joint>
  <joint name="left_indexDIP" type="revolute">
    <axis xyz="1 0 0"/>
    <limit effort="1.9613" lower="0" upper="1.5" velocity="6.545"/>
    <origin rpy="0 0 0" xyz="0 0 -0.024"/>
    <mimic joint="left_indexPIP" multiplier="1" offset="0"/>
    <parent link="left_index_mid"/>
    <child link="left_index_dist"/>
  </joint>
  <joint name="left_middleMCP" type="revolute">
    <axis xyz="1 0 0"/>
    <limit effort="1.9613" lower="0" upper="1.5" velocity="6.545"/>
    <origin rpy="0 0 3.1415" xyz="0.007 -0.00175 -0.12325"/>
    <mimic joint="left_middlePIP" multiplier="1" offset="0"/>
    <parent link="left_hand"/>
    <child link="left_middle_prox"/>
  </joint>
  <joint name="left_middlePIP" type="revolute">
    <axis xyz="1 0 0"/>
    <limit effort="1.9613" lower="0" upper="1.5" velocity="6.545"/>
    <origin rpy="0 0 0" xyz="0 0.000 -0.0389"/>
    <parent link="left_middle_prox"/>
    <child link="left_middle_mid"/>
    <dynamics damping="0.7"/>
  </joint>
  <joint name="left_middleDIP" type="revolute">
    <axis xyz="1 0 0"/>
    <limit effort="1.9613" lower="0" upper="1.57" velocity="6.545"/>
    <origin rpy="0 0 0" xyz="0 0.0005 -0.0259"/>
    <mimic joint="left_middlePIP" multiplier="1" offset="0"/>
    <parent link="left_middle_mid"/>
    <child link="left_middle_dist"/>
  </joint>
  <joint name="left_ringCMC" type="revolute">
    <axis xyz="0 0 1"/>
    <limit effort="1.9613" lower="0" upper="1.57" velocity="6.545"/>
    <origin rpy="0 0.7 3.1415" xyz="-0.00705 0 -0.0794"/>
    <mimic joint="left_ringMCP" multiplier="0.1" offset="0"/>
    <parent link="left_hand"/>
    <child link="left_ring_meta"/>
  </joint>
  <joint name="left_ringMCP" type="revolute">
    <axis xyz="1 0 0"/>
    <limit effort="1.9613" lower="0" upper="1.5" velocity="6.545"/>
    <origin rpy="0 -0.7775 0" xyz="0.0351 0.00126 -0.0166"/>
    <parent link="left_ring_meta"/>
    <child link="left_ring_prox"/>
    <dynamics damping="0.7"/>
  </joint>
  <joint name="left_ringPIP" type="revolute">
    <axis xyz="1 0 0"/>
    <limit effort="1.9613" lower="0" upper="1.57" velocity="6.545"/>
    <origin rpy="0 0 0" xyz="0 0.0005 -0.0345"/>
    <mimic joint="left_ringMCP" multiplier="1" offset="0"/>
    <parent link="left_ring_prox"/>
    <child link="left_ring_mid"/>
  </joint>
  <joint name="left_ringDIP" type="revolute">
    <axis xyz="1 0 0"/>
    <limit effort="1.9613" lower="0" upper="1.57" velocity="6.545"/>
    <origin rpy="0 0 0" xyz="0 0.0004 -0.0229"/>
    <mimic joint="left_ringMCP" multiplier="1" offset="0"/>
    <parent link="left_ring_mid"/>
    <child link="left_ring_dist"/>
  </joint>
  <joint name="left_pinkyCMC" type="revolute">
    <axis xyz="0 0 1"/>
    <limit effort="1.9613" lower="0" upper="1.57" velocity="6.545"/>
    <origin rpy="0 0.7 3.1415" xyz="-0.027 0 -0.0555"/>
    <mimic joint="left_pinkyMCP" multiplier="0.1" offset="0"/>
    <parent link="left_hand"/>
    <child link="left_pinky_meta"/>
  </joint>
  <joint name="left_pinkyMCP" type="revolute">
    <axis xyz="1 0 0"/>
    <limit effort="1.9613" lower="0" upper="1.5" velocity="6.545"/>
    <origin rpy="0 -0.93 0" xyz="0.046 -0 -0.0228"/>
    <parent link="left_pinky_meta"/>
    <child link="left_pinky_prox"/>
    <dynamics damping="0.7"/>
  </joint>
  <joint name="left_pinkyPIP" type="revolute">
    <axis xyz="1 0 0"/>
    <limit effort="1.9613" lower="0" upper="1.57" velocity="6.545"/>
    <origin rpy="0 0 0" xyz="0 0.0005 -0.031"/>
    <mimic joint="left_pinkyMCP" multiplier="1" offset="0"/>
    <parent link="left_pinky_prox"/>
    <child link="left_pinky_mid"/>
  </joint>
  <joint name="left_pinkyDIP" type="revolute">
    <axis xyz="1 0 0"/>
    <limit effort="1.9613" lower="0" upper="1.57" velocity="6.545"/>
    <origin rpy="0 0 0" xyz="0 0.0004 -0.0208"/>
    <mimic joint="left_pinkyMCP" multiplier="1" offset="0"/>
    <parent link="left_pinky_mid"/>
    <child link="left_pinky_dist"/>
  </joint>
  <link name="left_handcover">
    <visual>
      <geometry>
        <mesh filename="package://inmoov_meshes/meshes/left_cover_hand.stl" scale="0.001 0.001 0.001"/>
      </geometry>
      <origin rpy="0 0 0" xyz="0 0 0"/>
      <material name="ccover">
        <color rgba="0.6 0.6 0.6 1"/>
      </material>
    </visual>
    <collision>
      <geometry>
        <mesh filename="package://inmoov_meshes/meshes/left_cover_hand.stl" scale="0.001 0.001 0.001"/>
      </geometry>
      <origin rpy="0 0 0" xyz="0 0 0"/>
    </collision>
    <inertial>
      <origin rpy="0 0 0" xyz="-0.0502654824624 0.004 0.036"/>
      <mass value="2.2e-2"/>
      <inertia ixx="1e-5" ixy="0" ixz="0" iyy="1e-4" iyz="0" izz="1e-5"/>
    </inertial>
  </link>
  <link name="left_cover_handring">
    <visual>
      <geometry>
        <mesh filename="package://inmoov_meshes/meshes/left_cover_handring.stl" scale="0.001 0.001 0.001"/>
      </geometry>
      <origin rpy="0 0 3.1415" xyz="0 0 0"/>
      <material name="ccover">
        <color rgba="0.6 0.6 0.6 1"/>
      </material>
    </visual>
    <collision>
      <geometry>
        <mesh filename="package://inmoov_meshes/meshes/left_cover_handring.stl" scale="0.001 0.001 0.001"/>
      </geometry>
      <origin rpy="0 0 3.1415" xyz="0 0 0"/>
    </collision>
    <inertial>
      <origin rpy="0 0 3.1415" xyz="0 0.003 -0.002"/>
      <mass value="2.6e-3"/>
      <inertia ixx="1e-6" ixy="0" ixz="0" iyy="1e-6" iyz="0" izz="1e-6"/>
    </inertial>
  </link>
  <link name="left_cover_handpinky">
    <visual>
      <geometry>
        <mesh filename="package://inmoov_meshes/meshes/left_cover_handpinky.stl" scale="0.001 0.001 0.001"/>
      </geometry>
      <origin rpy="0 0 3.1415" xyz="0 0 0"/>
      <material name="ccover">
        <color rgba="0.6 0.6 0.6 1"/>
      </material>
    </visual>
    <collision>
      <geometry>
        <mesh filename="package://inmoov_meshes/meshes/left_cover_handpinky.stl" scale="0.001 0.001 0.001"/>
      </geometry>
      <origin rpy="0 0 3.1415" xyz="0 0 0"/>
    </collision>
    <inertial>
      <origin rpy="0 0 3.1415" xyz="0 0.002 0.002"/>
      <mass value="2.6e-3"/>
      <inertia ixx="1e-6" ixy="0" ixz="0" iyy="1e-6" iyz="0" izz="1e-6"/>
    </inertial>
  </link>
  <link name="left_cover_thumb">
    <visual>
      <geometry>
        <mesh filename="package://inmoov_meshes/meshes/left_cover_thumb.stl" scale="0.001 0.001 0.001"/>
      </geometry>
      <origin rpy="3.1415 0 0" xyz="0 0 0"/>
      <material name="ccover">
        <color rgba="0.6 0.6 0.6 1"/>
      </material>
    </visual>
    <collision>
      <geometry>
        <mesh filename="package://inmoov_meshes/meshes/left_cover_thumb.stl" scale="0.001 0.001 0.001"/>
      </geometry>
      <origin rpy="3.1415 0 0" xyz="0 0 0"/>
    </collision>
    <inertial>
      <origin rpy="0 0 3.1415" xyz="0 0 -0.002"/>
      <mass value="2.6e-3"/>
      <inertia ixx="1e-6" ixy="0" ixz="0" iyy="1e-6" iyz="0" izz="1e-6"/>
    </inertial>
  </link>
  <link name="left_cover_index">
    <visual>
      <geometry>
        <mesh filename="package://inmoov_meshes/meshes/left_cover_index.stl" scale="0.001 0.001 0.001"/>
      </geometry>
      <origin rpy="0 0 3.1415" xyz="0 0 0"/>
      <material name="ccover">
        <color rgba="0.6 0.6 0.6 1"/>
      </material>
    </visual>
    <collision>
      <geometry>
        <mesh filename="package://inmoov_meshes/meshes/left_cover_index.stl" scale="0.001 0.001 0.001"/>
      </geometry>
      <origin rpy="0 0 3.1415" xyz="0 0 0"/>
    </collision>
    <inertial>
      <origin rpy="0 0 3.1415" xyz="0 0 -0.002"/>
      <mass value="2.6e-3"/>
      <inertia ixx="1e-6" ixy="0" ixz="0" iyy="1e-6" iyz="0" izz="1e-6"/>
    </inertial>
  </link>
  <link name="left_cover_middle">
    <visual>
      <geometry>
        <mesh filename="package://inmoov_meshes/meshes/left_cover_middle.stl" scale="0.001 0.001 0.001"/>
      </geometry>
      <origin rpy="0 0 3.1415" xyz="0 0 0"/>
      <material name="ccover">
        <color rgba="0.6 0.6 0.6 1"/>
      </material>
    </visual>
    <collision>
      <geometry>
        <mesh filename="package://inmoov_meshes/meshes/left_cover_middle.stl" scale="0.001 0.001 0.001"/>
      </geometry>
      <origin rpy="0 0 3.1415" xyz="0 0 0"/>
    </collision>
    <inertial>
      <origin rpy="0 0 3.1415" xyz="0 0 -0.002"/>
      <mass value="2.6e-3"/>
      <inertia ixx="1e-6" ixy="0" ixz="0" iyy="1e-6" iyz="0" izz="1e-6"/>
    </inertial>
  </link>
  <link name="left_cover_ring">
    <visual>
      <geometry>
        <mesh filename="package://inmoov_meshes/meshes/left_cover_ring.stl" scale="0.001 0.001 0.001"/>
      </geometry>
      <origin rpy="0 0 3.1415" xyz="0 0 0"/>
      <material name="ccover">
        <color rgba="0.6 0.6 0.6 1"/>
      </material>
    </visual>
    <collision>
      <geometry>
        <mesh filename="package://inmoov_meshes/meshes/left_cover_ring.stl" scale="0.001 0.001 0.001"/>
      </geometry>
      <origin rpy="0 0 3.1415" xyz="0 0 0"/>
    </collision>
    <inertial>
      <origin rpy="0 0 3.1415" xyz="0 0 -0.002"/>
      <mass value="2.6e-3"/>
      <inertia ixx="1e-6" ixy="0" ixz="0" iyy="1e-6" iyz="0" izz="1e-6"/>
    </inertial>
  </link>
  <link name="left_cover_pinky">
    <visual>
      <geometry>
        <mesh filename="package://inmoov_meshes/meshes/left_cover_pinky.stl" scale="0.001 0.001 0.001"/>
      </geometry>
      <origin rpy="0 0 3.1415" xyz="0 0 0"/>
      <material name="ccover">
        <color rgba="0.6 0.6 0.6 1"/>
      </material>
    </visual>
    <collision>
      <geometry>
        <mesh filename="package://inmoov_meshes/meshes/left_cover_pinky.stl" scale="0.001 0.001 0.001"/>
      </geometry>
      <origin rpy="0 0 3.1415" xyz="0 0 0"/>
    </collision>
    <inertial>
      <origin rpy="0 0 3.1415" xyz="0 0 -0.002"/>
      <mass value="2.6e-3"/>
      <inertia ixx="1e-6" ixy="0" ixz="0" iyy="1e-6" iyz="0" izz="1e-6"/>
    </inertial>
  </link>
  <joint name="left_handcover" type="fixed">
    <origin rpy="0 0 0" xyz="0.0192 0.009 -0.0977"/>
    <parent link="left_hand"/>
    <child link="left_handcover"/>
  </joint>
  <joint name="left_cover_handring" type="fixed">
    <origin rpy="0 -0.7 0" xyz="0.015 -0.009 -0.0008"/>
    <parent link="left_ring_meta"/>
    <child link="left_cover_handring"/>
  </joint>
  <joint name="left_cover_handpinky" type="fixed">
    <origin rpy="0 -0.7 0" xyz="0.0205 -0.01 -0.0069"/>
    <parent link="left_pinky_meta"/>
    <child link="left_cover_handpinky"/>
  </joint>
  <joint name="left_cover_thumb" type="fixed">
    <origin rpy="0 -3.1 0" xyz="0.02125 -0.01 -0.0047"/>
    <parent link="left_thumb_meta"/>
    <child link="left_cover_thumb"/>
  </joint>
  <joint name="left_cover_index" type="fixed">
    <origin rpy="-0.05 0 0" xyz="0 -0.0071 -0.012"/>
    <parent link="left_index_prox"/>
    <child link="left_cover_index"/>
  </joint>
  <joint name="left_cover_middle" type="fixed">
    <origin rpy="0.05 0 0" xyz="0 -0.0071 -0.012"/>
    <parent link="left_middle_prox"/>
    <child link="left_cover_middle"/>
  </joint>
  <joint name="left_cover_ring" type="fixed">
    <origin rpy="0.05 0.1 0" xyz="0 -0.005 -0.011"/>
    <parent link="left_ring_prox"/>
    <child link="left_cover_ring"/>
  </joint>
  <joint name="left_cover_pinky" type="fixed">
    <origin rpy="0.05 0.1 0" xyz="0 -0.005 -0.0105"/>
    <parent link="left_pinky_prox"/>
    <child link="left_cover_pinky"/>
  </joint>
  <joint name="left_wrist" type="revolute">
    <axis xyz="0 0 1"/>
    <limit effort="0.9807" lower="0" upper="3.14" velocity="5.236"/>
    <origin rpy="0 0 0" xyz="0.01 -0.0144 -0.2885"/>
    <parent link="left_forearm"/>
    <child link="left_hand"/>
    <dynamics damping="0.7"/>
  </joint>
  <!--EYE MOUNTED CAMERAS-->
  <gazebo reference="left_camera">
    <sensor name="cameraL" type="camera">
      <update_rate>30.0</update_rate>
      <camera name="leftcamera">
        <pose>0 0.008 0 0 0 1.5708</pose>
        <horizontal_fov>1.195551</horizontal_fov>
        <image>
          <width>1280</width>
          <height>720</height>
          <format>R8G8B8</format>
        </image>
        <clip>
          <near>0.02</near>
          <far>300</far>
        </clip>
        <noise>
          <type>gaussian</type>
          <mean>0.0</mean>
          <stddev>0.007</stddev>
        </noise>
      </camera>
      <plugin filename="libgazebo_ros_camera.so" name="camera_controller">
        <alwaysOn>true</alwaysOn>
        <updateRate>0.0</updateRate>
        <cameraName>inmoov/cameraLeft</cameraName>
        <imageTopicName>image_raw</imageTopicName>
        <cameraInfoTopicName>camera_info</cameraInfoTopicName>
        <frameName>left_camera</frameName>
        <hackBaseline>0.07</hackBaseline>
        <distortionK1>0.0</distortionK1>
        <distortionK2>0.0</distortionK2>
        <distortionK3>0.0</distortionK3>
        <distortionT1>0.0</distortionT1>
        <distortionT2>0.0</distortionT2>
      </plugin>
    </sensor>
  </gazebo>
  <gazebo reference="right_camera">
    <sensor name="cameraR" type="camera">
      <update_rate>30.0</update_rate>
      <camera name="rightcamera">
        <pose>0 0.008 0 0 0 1.5708</pose>
        <horizontal_fov>1.195551</horizontal_fov>
        <image>
          <width>1280</width>
          <height>720</height>
          <format>R8G8B8</format>
        </image>
        <clip>
          <near>0.02</near>
          <far>300</far>
        </clip>
        <noise>
          <type>gaussian</type>
          <mean>0.0</mean>
          <stddev>0.007</stddev>
        </noise>
      </camera>
      <plugin filename="libgazebo_ros_camera.so" name="camera_controller">
        <alwaysOn>true</alwaysOn>
        <updateRate>0.0</updateRate>
        <cameraName>inmoov/cameraRight</cameraName>
        <imageTopicName>image_raw</imageTopicName>
        <cameraInfoTopicName>camera_info</cameraInfoTopicName>
        <frameName>right_camera</frameName>
        <hackBaseline>0.07</hackBaseline>
        <distortionK1>0.0</distortionK1>
        <distortionK2>0.0</distortionK2>
        <distortionK3>0.0</distortionK3>
        <distortionT1>0.0</distortionT1>
        <distortionT2>0.0</distortionT2>
      </plugin>
    </sensor>
  </gazebo>
  <!--KINECT-->
  <gazebo reference="kinectIR">
    <sensor name="cameraK" type="depth">
      <update_rate>30.0</update_rate>
      <camera>
        <horizontal_fov>1.01229</horizontal_fov>
        <image>
          <width>640</width>
          <height>480</height>
          <format>R8G8B8</format>
        </image>
        <clip>
          <near>0.04</near>
          <far>4.0</far>
        </clip>
      </camera>
      <plugin filename="libgazebo_ros_openni_kinect.so" name="kinect_camera_controller">
        <alwaysOn>true</alwaysOn>
        <updateRate>10</updateRate>
        <cameraName>inmoov/kinect</cameraName>
        <imageTopicName>rgb/image_color</imageTopicName>
        <depthImageTopicName>depth/image_raw</depthImageTopicName>
        <pointCloudTopicName>depth/points</pointCloudTopicName>
        <cameraInfoTopicName>rgb/camera_info</cameraInfoTopicName>
        <depthImageCameraInfoTopicName>depth/camera_info</depthImageCameraInfoTopicName>
        <frameName>kinectIR_frame</frameName>
        <baseline>0.1</baseline>
        <distortion_k1>0.0</distortion_k1>
        <distortion_k2>0.0</distortion_k2>
        <distortion_k3>0.0</distortion_k3>
        <distortion_t1>0.0</distortion_t1>
        <distortion_t2>0.0</distortion_t2>
        <pointCloudCutoff>0.4</pointCloudCutoff>
      </plugin>
    </sensor>
  </gazebo>
  <!--PIR SENSOR-->
  <!--not currently possible(?)-->
  <!--TOUCH SENSORS-->
  <gazebo reference="left_thumb_dist">
    <sensor name="lthumb_contact" type="contact">
      <always_on>true</always_on>
      <update_rate>30</update_rate>
      <contact>
        <collision>left_thumb_dist_fixed_joint_lump__lthumb_collision_collision</collision>
      </contact>
      <plugin filename="libgazebo_ros_bumper.so" name="lthumb_contact_plugin">
        <bumperTopicName>lthumb_contact_state</bumperTopicName>
        <frameName>left_thumb_dist</frameName>
      </plugin>
    </sensor>
  </gazebo>
  <gazebo reference="left_index_dist">
    <sensor name="lindex_contact" type="contact">
      <always_on>true</always_on>
      <update_rate>30</update_rate>
      <contact>
        <collision>left_index_dist_fixed_joint_lump__lindex_collision_collision</collision>
      </contact>
      <plugin filename="libgazebo_ros_bumper.so" name="lindex_contact_plugin">
        <bumperTopicName>lindex_contact_state</bumperTopicName>
        <frameName>left_index_dist</frameName>
      </plugin>
    </sensor>
  </gazebo>
  <gazebo reference="left_middle_dist">
    <sensor name="lmiddle_contact" type="contact">
      <always_on>true</always_on>
      <update_rate>30</update_rate>
      <contact>
        <collision>left_middle_dist_fixed_joint_lump__lmiddle_collision_collision</collision>
      </contact>
      <plugin filename="libgazebo_ros_bumper.so" name="lmiddle_contact_plugin">
        <bumperTopicName>lmiddle_contact_state</bumperTopicName>
        <frameName>left_middle_dist</frameName>
      </plugin>
    </sensor>
  </gazebo>
  <gazebo reference="left_ring_dist">
    <sensor name="lring_contact" type="contact">
      <always_on>true</always_on>
      <update_rate>30</update_rate>
      <contact>
        <collision>left_ring_dist_fixed_joint_lump__lring_collision_collision</collision>
      </contact>
      <plugin filename="libgazebo_ros_bumper.so" name="lring_contact_plugin">
        <bumperTopicName>lring_contact_state</bumperTopicName>
        <frameName>left_ring_dist</frameName>
      </plugin>
    </sensor>
  </gazebo>
  <gazebo reference="left_pinky_dist">
    <sensor name="lpinky_contact" type="contact">
      <always_on>true</always_on>
      <update_rate>30</update_rate>
      <contact>
        <collision>left_pinky_dist_fixed_joint_lump__lpinky_collision_collision</collision>
      </contact>
      <plugin filename="libgazebo_ros_bumper.so" name="lpinky_contact_plugin">
        <bumperTopicName>lpinky_contact_state</bumperTopicName>
        <frameName>left_pinky_dist</frameName>
      </plugin>
    </sensor>
  </gazebo>
  <gazebo reference="right_thumb_dist">
    <sensor name="rthumb_contact" type="contact">
      <always_on>true</always_on>
      <update_rate>30</update_rate>
      <contact>
        <collision>right_thumb_dist_fixed_joint_lump__rthumb_collision_collision</collision>
      </contact>
      <plugin filename="libgazebo_ros_bumper.so" name="rthumb_contact_plugin">
        <bumperTopicName>rthumb_contact_state</bumperTopicName>
        <frameName>right_thumb_dist</frameName>
      </plugin>
    </sensor>
  </gazebo>
  <gazebo reference="right_index_dist">
    <sensor name="rindex_contact" type="contact">
      <always_on>true</always_on>
      <update_rate>30</update_rate>
      <contact>
        <collision>right_index_dist_fixed_joint_lump__rindex_collision_collision</collision>
      </contact>
      <plugin filename="libgazebo_ros_bumper.so" name="rindex_contact_plugin">
        <bumperTopicName>rindex_contact_state</bumperTopicName>
        <frameName>right_index_dist</frameName>
      </plugin>
    </sensor>
  </gazebo>
  <gazebo reference="right_middle_dist">
    <sensor name="rmiddle_contact" type="contact">
      <always_on>true</always_on>
      <update_rate>30</update_rate>
      <contact>
        <collision>right_middle_dist_fixed_joint_lump__rmiddle_collision_collision</collision>
      </contact>
      <plugin filename="libgazebo_ros_bumper.so" name="rmiddle_contact_plugin">
        <bumperTopicName>rmiddle_contact_state</bumperTopicName>
        <frameName>right_middle_dist</frameName>
      </plugin>
    </sensor>
  </gazebo>
  <gazebo reference="right_ring_dist">
    <sensor name="rring_contact" type="contact">
      <always_on>true</always_on>
      <update_rate>30</update_rate>
      <contact>
        <collision>right_ring_dist_fixed_joint_lump__rring_collision_collision</collision>
      </contact>
      <plugin filename="libgazebo_ros_bumper.so" name="rring_contact_plugin">
        <bumperTopicName>rring_contact_state</bumperTopicName>
        <frameName>right_ring_dist</frameName>
      </plugin>
    </sensor>
  </gazebo>
  <gazebo reference="right_pinky_dist">
    <sensor name="rpinky_contact" type="contact">
      <always_on>true</always_on>
      <update_rate>30</update_rate>
      <contact>
        <collision>right_pinky_dist_fixed_joint_lump__rpinky_collision_collision</collision>
      </contact>
      <plugin filename="libgazebo_ros_bumper.so" name="rpinky_contact_plugin">
        <bumperTopicName>rpinky_contact_state</bumperTopicName>
        <frameName>right_pinky_dist</frameName>
      </plugin>
    </sensor>
  </gazebo>
  <!--GAZEBO_ROS_CONTROL PLUGIN-->
  <gazebo>
    <plugin filename="libgazebo_ros_control.so" name="gazebo_ros_control">
      <robotNamespace>/inmoov</robotNamespace>
    </plugin>
  </gazebo>
  <!--TRANSMISSION PLUGINS-->
  <!--Head & Face-->
  <transmission name="head_tran1">
    <type>transmission_interface/SimpleTransmission</type>
    <joint name="head_tilt">
      <hardwareInterface>hardware_interface/PositionJointInterface</hardwareInterface>
    </joint>
    <actuator name="headmotor1">
      <hardwareInterface>hardware_interface/PositionJointInterface</hardwareInterface>
      <mechanicalReduction>1</mechanicalReduction>
    </actuator>
  </transmission>
  <transmission name="head_tran2">
    <type>transmission_interface/SimpleTransmission</type>
    <joint name="head_updown">
      <hardwareInterface>hardware_interface/PositionJointInterface</hardwareInterface>
    </joint>
    <actuator name="headmotor2">
      <hardwareInterface>hardware_interface/PositionJointInterface</hardwareInterface>
      <mechanicalReduction>1</mechanicalReduction>
    </actuator>
  </transmission>
  <transmission name="head_tran3">
    <type>transmission_interface/SimpleTransmission</type>
    <joint name="head_leftright">
      <hardwareInterface>hardware_interface/PositionJointInterface</hardwareInterface>
    </joint>
    <actuator name="headmotor3">
      <hardwareInterface>hardware_interface/PositionJointInterface</hardwareInterface>
      <mechanicalReduction>1</mechanicalReduction>
    </actuator>
  </transmission>
  <transmission name="jaw_tran">
    <type>transmission_interface/SimpleTransmission</type>
    <joint name="jaw">
      <hardwareInterface>hardware_interface/EffortJointInterface</hardwareInterface>
    </joint>
    <actuator name="jawmotor">
      <hardwareInterface>hardware_interface/EffortJointInterface</hardwareInterface>
      <mechanicalReduction>1</mechanicalReduction>
    </actuator>
  </transmission>
  <transmission name="eye_tran1">
    <type>transmission_interface/SimpleTransmission</type>
    <joint name="eyes_updown">
      <hardwareInterface>hardware_interface/EffortJointInterface</hardwareInterface>
    </joint>
    <actuator name="eyemotor1">
      <hardwareInterface>hardware_interface/EffortJointInterface</hardwareInterface>
      <mechanicalReduction>1</mechanicalReduction>
    </actuator>
  </transmission>
  <transmission name="eye_tran2">
    <type>transmission_interface/SimpleTransmission</type>
    <joint name="eye_leftright">
      <hardwareInterface>hardware_interface/EffortJointInterface</hardwareInterface>
    </joint>
    <actuator name="eyemotor2">
      <hardwareInterface>hardware_interface/EffortJointInterface</hardwareInterface>
      <mechanicalReduction>1</mechanicalReduction>
    </actuator>
  </transmission>
  <transmission name="eye_tran3">
    <type>transmission_interface/SimpleTransmission</type>
    <joint name="left_eye_leftright">
      <hardwareInterface>hardware_interface/EffortJointInterface</hardwareInterface>
    </joint>
    <actuator name="eyemotor3">
      <hardwareInterface>hardware_interface/EffortJointInterface</hardwareInterface>
      <mechanicalReduction>1</mechanicalReduction>
    </actuator>
  </transmission>
  <!--Torso-->
  <transmission name="waist_tran1">
    <type>transmission_interface/SimpleTransmission</type>
    <joint name="waist_rotate">
      <hardwareInterface>hardware_interface/PositionJointInterface</hardwareInterface>
    </joint>
    <actuator name="waistmotor1">
      <hardwareInterface>hardware_interface/PositionJointInterface</hardwareInterface>
      <mechanicalReduction>1</mechanicalReduction>
    </actuator>
  </transmission>
  <transmission name="waist_tran2">
    <type>transmission_interface/SimpleTransmission</type>
    <joint name="waist_lean">
      <hardwareInterface>hardware_interface/PositionJointInterface</hardwareInterface>
    </joint>
    <actuator name="waistmotor2">
      <hardwareInterface>hardware_interface/PositionJointInterface</hardwareInterface>
      <mechanicalReduction>1</mechanicalReduction>
    </actuator>
  </transmission>
  <!--Right Arm-->
  <transmission name="rshoulder_tran1">
    <type>transmission_interface/SimpleTransmission</type>
    <joint name="right_shoulder_side">
      <hardwareInterface>hardware_interface/PositionJointInterface</hardwareInterface>
    </joint>
    <actuator name="rshouldermotor1">
      <hardwareInterface>hardware_interface/PositionJointInterface</hardwareInterface>
      <mechanicalReduction>1</mechanicalReduction>
    </actuator>
  </transmission>
  <transmission name="rshoulder_tran2">
    <type>transmission_interface/SimpleTransmission</type>
    <joint name="right_shoulder_up">
      <hardwareInterface>hardware_interface/PositionJointInterface</hardwareInterface>
    </joint>
    <actuator name="rshouldermotor2">
      <hardwareInterface>hardware_interface/PositionJointInterface</hardwareInterface>
      <mechanicalReduction>1</mechanicalReduction>
    </actuator>
  </transmission>
  <transmission name="rbicep_tran1">
    <type>transmission_interface/SimpleTransmission</type>
    <joint name="right_bicep_rotate">
      <hardwareInterface>hardware_interface/PositionJointInterface</hardwareInterface>
    </joint>
    <actuator name="rbicepmotor1">
      <hardwareInterface>hardware_interface/PositionJointInterface</hardwareInterface>
      <mechanicalReduction>1</mechanicalReduction>
    </actuator>
  </transmission>
  <transmission name="relbow_tran2">
    <type>transmission_interface/SimpleTransmission</type>
    <joint name="right_elbow">
      <hardwareInterface>hardware_interface/PositionJointInterface</hardwareInterface>
    </joint>
    <actuator name="relbowmotor2">
      <hardwareInterface>hardware_interface/PositionJointInterface</hardwareInterface>
      <mechanicalReduction>1</mechanicalReduction>
    </actuator>
  </transmission>
  <!--Left Arm-->
  <transmission name="lshoulder_tran1">
    <type>transmission_interface/SimpleTransmission</type>
    <joint name="left_shoulder_side">
      <hardwareInterface>hardware_interface/PositionJointInterface</hardwareInterface>
    </joint>
    <actuator name="lshouldermotor1">
      <hardwareInterface>hardware_interface/PositionJointInterface</hardwareInterface>
      <mechanicalReduction>1</mechanicalReduction>
    </actuator>
  </transmission>
  <transmission name="lshoulder_tran2">
    <type>transmission_interface/SimpleTransmission</type>
    <joint name="left_shoulder_up">
      <hardwareInterface>hardware_interface/PositionJointInterface</hardwareInterface>
    </joint>
    <actuator name="lshouldermotor2">
      <hardwareInterface>hardware_interface/PositionJointInterface</hardwareInterface>
      <mechanicalReduction>1</mechanicalReduction>
    </actuator>
  </transmission>
  <transmission name="lbicep_tran1">
    <type>transmission_interface/SimpleTransmission</type>
    <joint name="left_bicep_rotate">
      <hardwareInterface>hardware_interface/PositionJointInterface</hardwareInterface>
    </joint>
    <actuator name="lbicepmotor1">
      <hardwareInterface>hardware_interface/PositionJointInterface</hardwareInterface>
      <mechanicalReduction>1</mechanicalReduction>
    </actuator>
  </transmission>
  <transmission name="lelbow_tran2">
    <type>transmission_interface/SimpleTransmission</type>
    <joint name="left_elbow">
      <hardwareInterface>hardware_interface/PositionJointInterface</hardwareInterface>
    </joint>
    <actuator name="lelbowmotor2">
      <hardwareInterface>hardware_interface/PositionJointInterface</hardwareInterface>
      <mechanicalReduction>1</mechanicalReduction>
    </actuator>
  </transmission>
  <!--Right Hand-->
  <transmission name="rthumb_tran">
    <type>transmission_interface/SimpleTransmission</type>
    <joint name="right_thumbMCP">
      <hardwareInterface>hardware_interface/EffortJointInterface</hardwareInterface>
    </joint>
    <actuator name="rthumbmotor">
      <hardwareInterface>hardware_interface/EffortJointInterface</hardwareInterface>
      <mechanicalReduction>1</mechanicalReduction>
    </actuator>
  </transmission>
  <transmission name="rthumb_tran1">
    <type>transmission_interface/SimpleTransmission</type>
    <joint name="right_thumbCMC">
      <hardwareInterface>hardware_interface/EffortJointInterface</hardwareInterface>
    </joint>
    <actuator name="rthumbmotor1">
      <hardwareInterface>hardware_interface/EffortJointInterface</hardwareInterface>
      <mechanicalReduction>1</mechanicalReduction>
    </actuator>
  </transmission>
  <transmission name="rthumb_tran3">
    <type>transmission_interface/SimpleTransmission</type>
    <joint name="right_thumbIP">
      <hardwareInterface>hardware_interface/EffortJointInterface</hardwareInterface>
    </joint>
    <actuator name="rthumbmotor3">
      <hardwareInterface>hardware_interface/EffortJointInterface</hardwareInterface>
      <mechanicalReduction>1</mechanicalReduction>
    </actuator>
  </transmission>
  <transmission name="rindex_tran">
    <type>transmission_interface/SimpleTransmission</type>
    <joint name="right_indexPIP">
      <hardwareInterface>hardware_interface/EffortJointInterface</hardwareInterface>
    </joint>
    <actuator name="rindexmotor">
      <hardwareInterface>hardware_interface/EffortJointInterface</hardwareInterface>
      <mechanicalReduction>1</mechanicalReduction>
    </actuator>
  </transmission>
  <transmission name="rindex_tran1">
    <type>transmission_interface/SimpleTransmission</type>
    <joint name="right_indexMCP">
      <hardwareInterface>hardware_interface/EffortJointInterface</hardwareInterface>
    </joint>
    <actuator name="rindexmotor1">
      <hardwareInterface>hardware_interface/EffortJointInterface</hardwareInterface>
      <mechanicalReduction>1</mechanicalReduction>
    </actuator>
  </transmission>
  <transmission name="rindex_tran3">
    <type>transmission_interface/SimpleTransmission</type>
    <joint name="right_indexDIP">
      <hardwareInterface>hardware_interface/EffortJointInterface</hardwareInterface>
    </joint>
    <actuator name="rindexmotor3">
      <hardwareInterface>hardware_interface/EffortJointInterface</hardwareInterface>
      <mechanicalReduction>1</mechanicalReduction>
    </actuator>
  </transmission>
  <transmission name="rmiddle_tran">
    <type>transmission_interface/SimpleTransmission</type>
    <joint name="right_middlePIP">
      <hardwareInterface>hardware_interface/EffortJointInterface</hardwareInterface>
    </joint>
    <actuator name="rmiddlemotor">
      <hardwareInterface>hardware_interface/EffortJointInterface</hardwareInterface>
      <mechanicalReduction>1</mechanicalReduction>
    </actuator>
  </transmission>
  <transmission name="rmiddle_tran1">
    <type>transmission_interface/SimpleTransmission</type>
    <joint name="right_middleMCP">
      <hardwareInterface>hardware_interface/EffortJointInterface</hardwareInterface>
    </joint>
    <actuator name="rmiddlemotor1">
      <hardwareInterface>hardware_interface/EffortJointInterface</hardwareInterface>
      <mechanicalReduction>1</mechanicalReduction>
    </actuator>
  </transmission>
  <transmission name="rmiddle_tran3">
    <type>transmission_interface/SimpleTransmission</type>
    <joint name="right_middleDIP">
      <hardwareInterface>hardware_interface/EffortJointInterface</hardwareInterface>
    </joint>
    <actuator name="rmiddlemotor3">
      <hardwareInterface>hardware_interface/EffortJointInterface</hardwareInterface>
      <mechanicalReduction>1</mechanicalReduction>
    </actuator>
  </transmission>
  <transmission name="rring_tran">
    <type>transmission_interface/SimpleTransmission</type>
    <joint name="right_ringMCP">
      <hardwareInterface>hardware_interface/EffortJointInterface</hardwareInterface>
    </joint>
    <actuator name="rringmotor">
      <hardwareInterface>hardware_interface/EffortJointInterface</hardwareInterface>
      <mechanicalReduction>1</mechanicalReduction>
    </actuator>
  </transmission>
  <transmission name="rring_tran1">
    <type>transmission_interface/SimpleTransmission</type>
    <joint name="right_ringCMC">
      <hardwareInterface>hardware_interface/EffortJointInterface</hardwareInterface>
    </joint>
    <actuator name="rringmotor1">
      <hardwareInterface>hardware_interface/EffortJointInterface</hardwareInterface>
      <mechanicalReduction>1</mechanicalReduction>
    </actuator>
  </transmission>
  <transmission name="rring_tran3">
    <type>transmission_interface/SimpleTransmission</type>
    <joint name="right_ringPIP">
      <hardwareInterface>hardware_interface/EffortJointInterface</hardwareInterface>
    </joint>
    <actuator name="rringmotor3">
      <hardwareInterface>hardware_interface/EffortJointInterface</hardwareInterface>
      <mechanicalReduction>1</mechanicalReduction>
    </actuator>
  </transmission>
  <transmission name="rring_tran4">
    <type>transmission_interface/SimpleTransmission</type>
    <joint name="right_ringDIP">
      <hardwareInterface>hardware_interface/EffortJointInterface</hardwareInterface>
    </joint>
    <actuator name="rringmotor4">
      <hardwareInterface>hardware_interface/EffortJointInterface</hardwareInterface>
      <mechanicalReduction>1</mechanicalReduction>
    </actuator>
  </transmission>
  <transmission name="rpinky_tran">
    <type>transmission_interface/SimpleTransmission</type>
    <joint name="right_pinkyMCP">
      <hardwareInterface>hardware_interface/EffortJointInterface</hardwareInterface>
    </joint>
    <actuator name="rpinkymotor">
      <hardwareInterface>hardware_interface/EffortJointInterface</hardwareInterface>
      <mechanicalReduction>1</mechanicalReduction>
    </actuator>
  </transmission>
  <transmission name="rpinky_tran1">
    <type>transmission_interface/SimpleTransmission</type>
    <joint name="right_pinkyCMC">
      <hardwareInterface>hardware_interface/EffortJointInterface</hardwareInterface>
    </joint>
    <actuator name="rpinkymotor1">
      <hardwareInterface>hardware_interface/EffortJointInterface</hardwareInterface>
      <mechanicalReduction>1</mechanicalReduction>
    </actuator>
  </transmission>
  <transmission name="rpinky_tran3">
    <type>transmission_interface/SimpleTransmission</type>
    <joint name="right_pinkyPIP">
      <hardwareInterface>hardware_interface/EffortJointInterface</hardwareInterface>
    </joint>
    <actuator name="rpinkymotor3">
      <hardwareInterface>hardware_interface/EffortJointInterface</hardwareInterface>
      <mechanicalReduction>1</mechanicalReduction>
    </actuator>
  </transmission>
  <transmission name="rpinky_tran4">
    <type>transmission_interface/SimpleTransmission</type>
    <joint name="right_pinkyDIP">
      <hardwareInterface>hardware_interface/EffortJointInterface</hardwareInterface>
    </joint>
    <actuator name="rpinkymotor4">
      <hardwareInterface>hardware_interface/EffortJointInterface</hardwareInterface>
      <mechanicalReduction>1</mechanicalReduction>
    </actuator>
  </transmission>
  <transmission name="rwrist_tran">
    <type>transmission_interface/SimpleTransmission</type>
    <joint name="right_wrist">
      <hardwareInterface>hardware_interface/PositionJointInterface</hardwareInterface>
    </joint>
    <actuator name="rwristmotor">
      <hardwareInterface>hardware_interface/PositionJointInterface</hardwareInterface>
      <mechanicalReduction>1</mechanicalReduction>
    </actuator>
  </transmission>
  <!--Left Hand-->
  <transmission name="lthumb_tran">
    <type>transmission_interface/SimpleTransmission</type>
    <joint name="left_thumbMCP">
      <hardwareInterface>hardware_interface/EffortJointInterface</hardwareInterface>
    </joint>
    <actuator name="lthumbmotor">
      <hardwareInterface>hardware_interface/EffortJointInterface</hardwareInterface>
      <mechanicalReduction>1</mechanicalReduction>
    </actuator>
  </transmission>
  <transmission name="lthumb_tran1">
    <type>transmission_interface/SimpleTransmission</type>
    <joint name="left_thumbCMC">
      <hardwareInterface>hardware_interface/EffortJointInterface</hardwareInterface>
    </joint>
    <actuator name="lthumbmotor1">
      <hardwareInterface>hardware_interface/EffortJointInterface</hardwareInterface>
      <mechanicalReduction>1</mechanicalReduction>
    </actuator>
  </transmission>
  <transmission name="lthumb_tran3">
    <type>transmission_interface/SimpleTransmission</type>
    <joint name="left_thumbIP">
      <hardwareInterface>hardware_interface/EffortJointInterface</hardwareInterface>
    </joint>
    <actuator name="lthumbmotor3">
      <hardwareInterface>hardware_interface/EffortJointInterface</hardwareInterface>
      <mechanicalReduction>1</mechanicalReduction>
    </actuator>
  </transmission>
  <transmission name="lindex_tran">
    <type>transmission_interface/SimpleTransmission</type>
    <joint name="left_indexPIP">
      <hardwareInterface>hardware_interface/EffortJointInterface</hardwareInterface>
    </joint>
    <actuator name="lindexmotor">
      <hardwareInterface>hardware_interface/EffortJointInterface</hardwareInterface>
      <mechanicalReduction>1</mechanicalReduction>
    </actuator>
  </transmission>
  <transmission name="lindex_tran1">
    <type>transmission_interface/SimpleTransmission</type>
    <joint name="left_indexMCP">
      <hardwareInterface>hardware_interface/EffortJointInterface</hardwareInterface>
    </joint>
    <actuator name="lindexmotor1">
      <hardwareInterface>hardware_interface/EffortJointInterface</hardwareInterface>
      <mechanicalReduction>1</mechanicalReduction>
    </actuator>
  </transmission>
  <transmission name="lindex_tran3">
    <type>transmission_interface/SimpleTransmission</type>
    <joint name="left_indexDIP">
      <hardwareInterface>hardware_interface/EffortJointInterface</hardwareInterface>
    </joint>
    <actuator name="lindexmotor3">
      <hardwareInterface>hardware_interface/EffortJointInterface</hardwareInterface>
      <mechanicalReduction>1</mechanicalReduction>
    </actuator>
  </transmission>
  <transmission name="lmiddle_tran">
    <type>transmission_interface/SimpleTransmission</type>
    <joint name="left_middlePIP">
      <hardwareInterface>hardware_interface/EffortJointInterface</hardwareInterface>
    </joint>
    <actuator name="lmiddlemotor">
      <hardwareInterface>hardware_interface/EffortJointInterface</hardwareInterface>
      <mechanicalReduction>1</mechanicalReduction>
    </actuator>
  </transmission>
  <transmission name="lmiddle_tran1">
    <type>transmission_interface/SimpleTransmission</type>
    <joint name="left_middleMCP">
      <hardwareInterface>hardware_interface/EffortJointInterface</hardwareInterface>
    </joint>
    <actuator name="lmiddlemotor1">
      <hardwareInterface>hardware_interface/EffortJointInterface</hardwareInterface>
      <mechanicalReduction>1</mechanicalReduction>
    </actuator>
  </transmission>
  <transmission name="lmiddle_tran3">
    <type>transmission_interface/SimpleTransmission</type>
    <joint name="left_middleDIP">
      <hardwareInterface>hardware_interface/EffortJointInterface</hardwareInterface>
    </joint>
    <actuator name="lmiddlemotor3">
      <hardwareInterface>hardware_interface/EffortJointInterface</hardwareInterface>
      <mechanicalReduction>1</mechanicalReduction>
    </actuator>
  </transmission>
  <transmission name="lring_tran">
    <type>transmission_interface/SimpleTransmission</type>
    <joint name="left_ringMCP">
      <hardwareInterface>hardware_interface/EffortJointInterface</hardwareInterface>
    </joint>
    <actuator name="lringmotor">
      <hardwareInterface>hardware_interface/EffortJointInterface</hardwareInterface>
      <mechanicalReduction>1</mechanicalReduction>
    </actuator>
  </transmission>
  <transmission name="lring_tran1">
    <type>transmission_interface/SimpleTransmission</type>
    <joint name="left_ringCMC">
      <hardwareInterface>hardware_interface/EffortJointInterface</hardwareInterface>
    </joint>
    <actuator name="lringmotor1">
      <hardwareInterface>hardware_interface/EffortJointInterface</hardwareInterface>
      <mechanicalReduction>1</mechanicalReduction>
    </actuator>
  </transmission>
  <transmission name="lring_tran3">
    <type>transmission_interface/SimpleTransmission</type>
    <joint name="left_ringPIP">
      <hardwareInterface>hardware_interface/EffortJointInterface</hardwareInterface>
    </joint>
    <actuator name="lringmotor3">
      <hardwareInterface>hardware_interface/EffortJointInterface</hardwareInterface>
      <mechanicalReduction>1</mechanicalReduction>
    </actuator>
  </transmission>
  <transmission name="lring_tran4">
    <type>transmission_interface/SimpleTransmission</type>
    <joint name="left_ringDIP">
      <hardwareInterface>hardware_interface/EffortJointInterface</hardwareInterface>
    </joint>
    <actuator name="lringmotor4">
      <hardwareInterface>hardware_interface/EffortJointInterface</hardwareInterface>
      <mechanicalReduction>1</mechanicalReduction>
    </actuator>
  </transmission>
  <transmission name="lpinky_tran">
    <type>transmission_interface/SimpleTransmission</type>
    <joint name="left_pinkyMCP">
      <hardwareInterface>hardware_interface/EffortJointInterface</hardwareInterface>
    </joint>
    <actuator name="lpinkymotor">
      <hardwareInterface>hardware_interface/EffortJointInterface</hardwareInterface>
      <mechanicalReduction>1</mechanicalReduction>
    </actuator>
  </transmission>
  <transmission name="lpinky_tran1">
    <type>transmission_interface/SimpleTransmission</type>
    <joint name="left_pinkyCMC">
      <hardwareInterface>hardware_interface/EffortJointInterface</hardwareInterface>
    </joint>
    <actuator name="lpinkymotor1">
      <hardwareInterface>hardware_interface/EffortJointInterface</hardwareInterface>
      <mechanicalReduction>1</mechanicalReduction>
    </actuator>
  </transmission>
  <transmission name="lpinky_tran3">
    <type>transmission_interface/SimpleTransmission</type>
    <joint name="left_pinkyPIP">
      <hardwareInterface>hardware_interface/EffortJointInterface</hardwareInterface>
    </joint>
    <actuator name="lpinkymotor3">
      <hardwareInterface>hardware_interface/EffortJointInterface</hardwareInterface>
      <mechanicalReduction>1</mechanicalReduction>
    </actuator>
  </transmission>
  <transmission name="lpinky_tran4">
    <type>transmission_interface/SimpleTransmission</type>
    <joint name="left_pinkyDIP">
      <hardwareInterface>hardware_interface/EffortJointInterface</hardwareInterface>
    </joint>
    <actuator name="lpinkymotor4">
      <hardwareInterface>hardware_interface/EffortJointInterface</hardwareInterface>
      <mechanicalReduction>1</mechanicalReduction>
    </actuator>
  </transmission>
  <transmission name="lwrist_tran">
    <type>transmission_interface/SimpleTransmission</type>
    <joint name="left_wrist">
      <hardwareInterface>hardware_interface/PositionJointInterface</hardwareInterface>
    </joint>
    <actuator name="lwristmotor">
      <hardwareInterface>hardware_interface/PositionJointInterface</hardwareInterface>
      <mechanicalReduction>1</mechanicalReduction>
    </actuator>
  </transmission>
  <!--GENERAL-->
  <gazebo reference="base_link">
    <mu1>0.3</mu1>
    <mu2>0.3</mu2>
    <material>Gazebo/DarkGrey</material>
  </gazebo>
  <gazebo reference="pedestal">
    <mu1>0.3</mu1>
    <mu2>0.3</mu2>
    <material>Gazebo/DarkGrey</material>
  </gazebo>
  <gazebo reference="head_tilt">
    <mu1>0.3</mu1>
    <mu2>0.3</mu2>
    <material>Gazebo/DarkGrey</material>
  </gazebo>
  <!--TORSO-->
  <gazebo reference="mid_stomach">
    <mu1>0.3</mu1>
    <mu2>0.3</mu2>
    <material>Gazebo/Grey</material>
  </gazebo>
  <gazebo reference="disk">
    <mu1>0.3</mu1>
    <mu2>0.3</mu2>
    <material>Gazebo/White</material>
  </gazebo>
  <gazebo reference="top_stomach">
    <mu1>0.3</mu1>
    <mu2>0.3</mu2>
    <material>Gazebo/Grey</material>
  </gazebo>
  <gazebo reference="torso">
    <mu1>0.3</mu1>
    <mu2>0.3</mu2>
    <material>Gazebo/Grey</material>
  </gazebo>
  <gazebo reference="kinect">
    <mu1>0.3</mu1>
    <mu2>0.3</mu2>
    <material>Gazebo/Black</material>
  </gazebo>
  <gazebo reference="chestplate">
    <mu1>0.3</mu1>
    <mu2>0.3</mu2>
    <material>Gazebo/White</material>
  </gazebo>
  <!--HEAD-->
  <gazebo reference="head_base">
    <mu1>0.3</mu1>
    <mu2>0.3</mu2>
    <material>Gazebo/Grey</material>
  </gazebo>
  <gazebo reference="head">
    <mu1>0.3</mu1>
    <mu2>0.3</mu2>
    <material>Gazebo/Grey</material>
  </gazebo>
  <gazebo reference="jaw">
    <mu1>0.3</mu1>
    <mu2>0.3</mu2>
    <material>Gazebo/White</material>
  </gazebo>
  <gazebo reference="skull">
    <mu1>0.3</mu1>
    <mu2>0.3</mu2>
    <material>Gazebo/White</material>
  </gazebo>
  <gazebo reference="left_ear">
    <mu1>0.3</mu1>
    <mu2>0.3</mu2>
    <material>Gazebo/Grey</material>
  </gazebo>
  <gazebo reference="right_ear">
    <mu1>0.3</mu1>
    <mu2>0.3</mu2>
    <material>Gazebo/Grey</material>
  </gazebo>
  <!--FACE-->
  <gazebo reference="face">
    <mu1>0.3</mu1>
    <mu2>0.3</mu2>
    <material>Gazebo/White</material>
  </gazebo>
  <gazebo reference="eyesupport">
    <mu1>0.3</mu1>
    <mu2>0.3</mu2>
    <material>Gazebo/Grey</material>
  </gazebo>
  <gazebo reference="right_eyesupport">
    <mu1>0.3</mu1>
    <mu2>0.3</mu2>
    <material>Gazebo/Grey</material>
  </gazebo>
  <gazebo reference="right_camera">
    <mu1>0.3</mu1>
    <mu2>0.3</mu2>
    <material>Gazebo/Black</material>
  </gazebo>
  <gazebo reference="right_eye">
    <mu1>0.3</mu1>
    <mu2>0.3</mu2>
    <material>Gazebo/White</material>
  </gazebo>
  <gazebo reference="right_iris">
    <mu1>0.3</mu1>
    <mu2>0.3</mu2>
    <material>Gazebo/Blue</material>
  </gazebo>
  <gazebo reference="left_eyesupport">
    <mu1>0.3</mu1>
    <mu2>0.3</mu2>
    <material>Gazebo/Grey</material>
  </gazebo>
  <gazebo reference="left_camera">
    <mu1>0.3</mu1>
    <mu2>0.3</mu2>
    <material>Gazebo/Black</material>
  </gazebo>
  <gazebo reference="left_eye">
    <mu1>0.3</mu1>
    <mu2>0.3</mu2>
    <material>Gazebo/White</material>
  </gazebo>
  <gazebo reference="left_iris">
    <mu1>0.3</mu1>
    <mu2>0.3</mu2>
    <material>Gazebo/Blue</material>
  </gazebo>
  <!--RIGHT ARM-->
  <gazebo reference="right_shoulder_base">
    <mu1>0.3</mu1>
    <mu2>0.3</mu2>
    <material>Gazebo/Grey</material>
  </gazebo>
  <gazebo reference="right_shoulder">
    <mu1>0.3</mu1>
    <mu2>0.3</mu2>
    <material>Gazebo/Grey</material>
  </gazebo>
  <gazebo reference="right_bicep">
    <mu1>0.3</mu1>
    <mu2>0.3</mu2>
    <material>Gazebo/White</material>
  </gazebo>
  <gazebo reference="right_bicepcover">
    <mu1>0.3</mu1>
    <mu2>0.3</mu2>
    <material>Gazebo/White</material>
  </gazebo>
  <gazebo reference="right_forarm">
    <mu1>0.3</mu1>
    <mu2>0.3</mu2>
    <material>Gazebo/White</material>
  </gazebo>
  <!--LEFT ARM-->
  <gazebo reference="left_shoulder_base">
    <mu1>0.3</mu1>
    <mu2>0.3</mu2>
    <material>Gazebo/Grey</material>
  </gazebo>
  <gazebo reference="left_shoulder">
    <mu1>0.3</mu1>
    <mu2>0.3</mu2>
    <material>Gazebo/Grey</material>
  </gazebo>
  <gazebo reference="left_bicep">
    <mu1>0.3</mu1>
    <mu2>0.3</mu2>
    <material>Gazebo/White</material>
  </gazebo>
  <gazebo reference="left_bicepcover">
    <mu1>0.3</mu1>
    <mu2>0.3</mu2>
    <material>Gazebo/White</material>
  </gazebo>
  <gazebo reference="left_forarm">
    <mu1>0.3</mu1>
    <mu2>0.3</mu2>
    <material>Gazebo/White</material>
  </gazebo>
  <!--RIGHT HAND-->
  <gazebo reference="right_hand">
    <mu1>0.3</mu1>
    <mu2>0.3</mu2>
    <material>Gazebo/White</material>
  </gazebo>
  <gazebo reference="right_thumb_meta">
    <mu1>0.3</mu1>
    <mu2>0.3</mu2>
    <material>Gazebo/White</material>
  </gazebo>
  <gazebo reference="right_thumb_prox">
    <mu1>0.3</mu1>
    <mu2>0.3</mu2>
    <material>Gazebo/Grey</material>
  </gazebo>
  <gazebo reference="right_thumb_dist">
    <mu1>0.3</mu1>
    <mu2>0.3</mu2>
    <material>Gazebo/Grey</material>
  </gazebo>
  <gazebo reference="right_index_prox">
    <mu1>0.3</mu1>
    <mu2>0.3</mu2>
    <material>Gazebo/Grey</material>
  </gazebo>
  <gazebo reference="right_index_mid">
    <mu1>0.3</mu1>
    <mu2>0.3</mu2>
    <material>Gazebo/Grey</material>
  </gazebo>
  <gazebo reference="right_index_dist">
    <mu1>0.3</mu1>
    <mu2>0.3</mu2>
    <material>Gazebo/Grey</material>
  </gazebo>
  <gazebo reference="right_middle_prox">
    <mu1>0.3</mu1>
    <mu2>0.3</mu2>
    <material>Gazebo/Grey</material>
  </gazebo>
  <gazebo reference="right_middle_mid">
    <mu1>0.3</mu1>
    <mu2>0.3</mu2>
    <material>Gazebo/Grey</material>
  </gazebo>
  <gazebo reference="right_middle_dist">
    <mu1>0.3</mu1>
    <mu2>0.3</mu2>
    <material>Gazebo/Grey</material>
  </gazebo>
  <gazebo reference="right_ring_meta">
    <mu1>0.3</mu1>
    <mu2>0.3</mu2>
    <material>Gazebo/White</material>
  </gazebo>
  <gazebo reference="right_ring_prox">
    <mu1>0.3</mu1>
    <mu2>0.3</mu2>
    <material>Gazebo/Grey</material>
  </gazebo>
  <gazebo reference="right_ring_mid">
    <mu1>0.3</mu1>
    <mu2>0.3</mu2>
    <material>Gazebo/Grey</material>
  </gazebo>
  <gazebo reference="right_ring_dist">
    <mu1>0.3</mu1>
    <mu2>0.3</mu2>
    <material>Gazebo/Grey</material>
  </gazebo>
  <gazebo reference="right_pinky_meta">
    <mu1>0.3</mu1>
    <mu2>0.3</mu2>
    <material>Gazebo/White</material>
  </gazebo>
  <gazebo reference="right_pinky_prox">
    <mu1>0.3</mu1>
    <mu2>0.3</mu2>
    <material>Gazebo/Grey</material>
  </gazebo>
  <gazebo reference="right_pinky_mid">
    <mu1>0.3</mu1>
    <mu2>0.3</mu2>
    <material>Gazebo/Grey</material>
  </gazebo>
  <gazebo reference="right_pinky_dist">
    <mu1>0.3</mu1>
    <mu2>0.3</mu2>
    <material>Gazebo/Grey</material>
  </gazebo>
  <gazebo reference="left_handcover">
    <mu1>0.3</mu1>
    <mu2>0.3</mu2>
    <material>Gazebo/White</material>
  </gazebo>
  <gazebo reference="right_cover_handring">
    <mu1>0.3</mu1>
    <mu2>0.3</mu2>
    <material>Gazebo/White</material>
  </gazebo>
  <gazebo reference="right_cover_handpinky">
    <mu1>0.3</mu1>
    <mu2>0.3</mu2>
    <material>Gazebo/White</material>
  </gazebo>
  <gazebo reference="right_cover_thumb">
    <mu1>0.3</mu1>
    <mu2>0.3</mu2>
    <material>Gazebo/White</material>
  </gazebo>
  <gazebo reference="right_cover_index">
    <mu1>0.3</mu1>
    <mu2>0.3</mu2>
    <material>Gazebo/White</material>
  </gazebo>
  <gazebo reference="right_cover_ring">
    <mu1>0.3</mu1>
    <mu2>0.3</mu2>
    <material>Gazebo/White</material>
  </gazebo>
  <gazebo reference="right_cover_pinky">
    <mu1>0.3</mu1>
    <mu2>0.3</mu2>
    <material>Gazebo/White</material>
  </gazebo>
  <!--LEFT HAND-->
  <gazebo reference="left_hand">
    <mu1>0.3</mu1>
    <mu2>0.3</mu2>
    <material>Gazebo/White</material>
  </gazebo>
  <gazebo reference="left_thumb_meta">
    <mu1>0.3</mu1>
    <mu2>0.3</mu2>
    <material>Gazebo/White</material>
  </gazebo>
  <gazebo reference="left_thumb_prox">
    <mu1>0.3</mu1>
    <mu2>0.3</mu2>
    <material>Gazebo/Grey</material>
  </gazebo>
  <gazebo reference="left_thumb_dist">
    <mu1>0.3</mu1>
    <mu2>0.3</mu2>
    <material>Gazebo/Grey</material>
  </gazebo>
  <gazebo reference="left_index_prox">
    <mu1>0.3</mu1>
    <mu2>0.3</mu2>
    <material>Gazebo/Grey</material>
  </gazebo>
  <gazebo reference="left_index_mid">
    <mu1>0.3</mu1>
    <mu2>0.3</mu2>
    <material>Gazebo/Grey</material>
  </gazebo>
  <gazebo reference="left_index_dist">
    <mu1>0.3</mu1>
    <mu2>0.3</mu2>
    <material>Gazebo/Grey</material>
  </gazebo>
  <gazebo reference="left_middle_prox">
    <mu1>0.3</mu1>
    <mu2>0.3</mu2>
    <material>Gazebo/Grey</material>
  </gazebo>
  <gazebo reference="left_middle_mid">
    <mu1>0.3</mu1>
    <mu2>0.3</mu2>
    <material>Gazebo/Grey</material>
  </gazebo>
  <gazebo reference="left_middle_dist">
    <mu1>0.3</mu1>
    <mu2>0.3</mu2>
    <material>Gazebo/Grey</material>
  </gazebo>
  <gazebo reference="left_ring_meta">
    <mu1>0.3</mu1>
    <mu2>0.3</mu2>
    <material>Gazebo/White</material>
  </gazebo>
  <gazebo reference="left_ring_prox">
    <mu1>0.3</mu1>
    <mu2>0.3</mu2>
    <material>Gazebo/Grey</material>
  </gazebo>
  <gazebo reference="left_ring_mid">
    <mu1>0.3</mu1>
    <mu2>0.3</mu2>
    <material>Gazebo/Grey</material>
  </gazebo>
  <gazebo reference="left_ring_dist">
    <mu1>0.3</mu1>
    <mu2>0.3</mu2>
    <material>Gazebo/Grey</material>
  </gazebo>
  <gazebo reference="left_pinky_meta">
    <mu1>0.3</mu1>
    <mu2>0.3</mu2>
    <material>Gazebo/White</material>
  </gazebo>
  <gazebo reference="left_pinky_prox">
    <mu1>0.3</mu1>
    <mu2>0.3</mu2>
    <material>Gazebo/Grey</material>
  </gazebo>
  <gazebo reference="left_pinky_mid">
    <mu1>0.3</mu1>
    <mu2>0.3</mu2>
    <material>Gazebo/Grey</material>
  </gazebo>
  <gazebo reference="left_pinky_dist">
    <mu1>0.3</mu1>
    <mu2>0.3</mu2>
    <material>Gazebo/Grey</material>
  </gazebo>
  <gazebo reference="left_handcover">
    <mu1>0.3</mu1>
    <mu2>0.3</mu2>
    <material>Gazebo/White</material>
  </gazebo>
  <gazebo reference="left_cover_handring">
    <mu1>0.3</mu1>
    <mu2>0.3</mu2>
    <material>Gazebo/White</material>
  </gazebo>
  <gazebo reference="left_cover_handpinky">
    <mu1>0.3</mu1>
    <mu2>0.3</mu2>
    <material>Gazebo/White</material>
  </gazebo>
  <gazebo reference="left_cover_thumb">
    <mu1>0.3</mu1>
    <mu2>0.3</mu2>
    <material>Gazebo/White</material>
  </gazebo>
  <gazebo reference="left_cover_index">
    <mu1>0.3</mu1>
    <mu2>0.3</mu2>
    <material>Gazebo/White</material>
  </gazebo>
  <gazebo reference="left_cover_ring">
    <mu1>0.3</mu1>
    <mu2>0.3</mu2>
    <material>Gazebo/White</material>
  </gazebo>
  <gazebo reference="left_cover_pinky">
    <mu1>0.3</mu1>
    <mu2>0.3</mu2>
    <material>Gazebo/White</material>
  </gazebo>
</robot>
