<?xml version="1.0" ?>
<!-- =================================================================================== -->
<!-- |    This document was autogenerated by xacro from inmoov.urdf.xacro              | -->
<!-- |    EDITING THIS FILE BY HAND IS NOT RECOMMENDED                                 | -->
<!-- =================================================================================== -->
<robot name="inmoov" xmlns:xacro="http://ros.org/wiki/xacro">
  <link name="world"/>
  <joint name="fixed" type="fixed">
    <parent link="world"/>
    <child link="base_link"/>
  </joint>
  <link name="base_link">
    <visual>
      <geometry>
        <cylinder length="0.11" radius="0.26"/>
      </geometry>
      <origin rpy="0 0 0" xyz="0 0 0.055"/>
      <material name="cbase">
        <color rgba="0.1 0.1 0.1 1"/>
      </material>
    </visual>
    <collision>
      <geometry>
        <cylinder length="0.11" radius="0.26"/>
      </geometry>
      <origin rpy="0 0 0" xyz="0 0 0.055"/>
    </collision>
  </link>
  <joint name="base_to_pedestal" type="fixed">
    <parent link="base_link"/>
    <child link="pedestal"/>
    <origin rpy="0 0 0" xyz="0 0 0"/>
  </joint>
  <link name="pedestal">
    <visual>
      <geometry>
        <cylinder length="0.94" radius="0.0254"/>
      </geometry>
      <origin rpy="0 0 0" xyz="0 0 0.58"/>
      <material name="cbase">
        <color rgba="0.1 0.1 0.1 1"/>
      </material>
    </visual>
    <collision>
      <geometry>
        <cylinder length="0.94" radius="0.0254"/>
      </geometry>
      <origin rpy="0 0 0" xyz="0 0 0.58"/>
    </collision>
    <inertial>
      <origin rpy="0 0 0" xyz="0 0 0.58"/>
      <mass value="1"/>
      <inertia ixx="0.01" ixy="0" ixz="0" iyy="0.01" iyz="0" izz="0.01"/>
    </inertial>
  </link>
  <link name="head_tilt">
    <visual>
      <geometry>
        <mesh filename="package://inmoov_description/meshes/virtual.stl" scale="0.001 0.001 0.001"/>
      </geometry>
      <origin rpy="0 0 0" xyz="0 0 0"/>
      <material name="cframe">
        <color rgba="0.25 0.25 0.25 1"/>
      </material>
    </visual>
    <collision>
      <geometry>
        <mesh filename="package://inmoov_description/meshes/virtual.stl" scale="0.001 0.001 0.001"/>
      </geometry>
      <origin rpy="0 0 0" xyz="0 0 0"/>
    </collision>
    <inertial>
      <origin rpy="0 0 0" xyz="0 0 0"/>
      <mass value="1"/>
      <inertia ixx="0.0001" ixy="0" ixz="0" iyy="0.0001" iyz="0" izz="0.0001"/>
    </inertial>
  </link>
  <joint name="pedestal_to_mid_stomach" type="fixed">
    <parent link="pedestal"/>
    <child link="mid_stomach"/>
    <origin rpy="0 0 0" xyz="0 0 0"/>
  </joint>
  <link name="mid_stomach">
    <visual>
      <geometry>
        <mesh filename="package://inmoov_description/meshes/mid_stomach.stl" scale="0.001 0.001 0.001"/>
      </geometry>
      <origin rpy="0 0 0" xyz="0 0 1.152"/>
      <material name="cframe">
        <color rgba="0.25 0.25 0.25 1"/>
      </material>
    </visual>
    <collision>
      <geometry>
        <mesh filename="package://inmoov_description/meshes/mid_stomach.stl" scale="0.001 0.001 0.001"/>
      </geometry>
      <origin rpy="0 0 0" xyz="0 0 1.152"/>
    </collision>
    <inertial>
      <origin rpy="0 0 0" xyz="0 0 1.152"/>
      <mass value="0.75"/>
      <inertia ixx="0.0130" ixy="0" ixz="0" iyy="0.0271" iyz="0" izz="0.0294"/>
    </inertial>
  </link>
  <link name="disk">
    <visual>
      <geometry>
        <mesh filename="package://inmoov_description/meshes/disk.stl" scale="0.001 0.001 0.001"/>
      </geometry>
      <origin rpy="0 0 0" xyz="0 0.046 0"/>
      <material name="ccover">
        <color rgba="0.6 0.6 0.6 1"/>
      </material>
    </visual>
    <collision>
      <geometry>
        <mesh filename="package://inmoov_description/meshes/disk.stl" scale="0.001 0.001 0.001"/>
      </geometry>
      <origin rpy="0 0 0" xyz="0 0.046 0"/>
    </collision>
    <inertial>
      <origin rpy="0 0 0" xyz="0 0.046 0"/>
      <mass value="0.0976"/>
      <inertia ixx="0.0001" ixy="0" ixz="0" iyy="0.0002" iyz="0" izz="0.0001"/>
    </inertial>
  </link>
  <link name="top_stomach">
    <visual>
      <geometry>
        <mesh filename="package://inmoov_description/meshes/top_stomach.stl" scale="0.001 0.001 0.001"/>
      </geometry>
      <origin rpy="0 0 0" xyz="0 0 0"/>
      <material name="cframe">
        <color rgba="0.25 0.25 0.25 1"/>
      </material>
    </visual>
    <collision>
      <geometry>
        <mesh filename="package://inmoov_description/meshes/top_stomach.stl" scale="0.001 0.001 0.001"/>
      </geometry>
      <origin rpy="0 0 0" xyz="0 0 0"/>
    </collision>
    <inertial>
      <origin rpy="0 0 0" xyz="0 0 0"/>
      <mass value="0.75"/>
      <inertia ixx="0.0099" ixy="0" ixz="0" iyy="0.0119" iyz="0" izz="0.0122"/>
    </inertial>
  </link>
  <link name="torso">
    <visual>
      <geometry>
        <mesh filename="package://inmoov_description/meshes/torso.stl" scale="0.001 0.001 0.001"/>
      </geometry>
      <origin rpy="0 0 0" xyz="0 0 0"/>
      <material name="cframe">
        <color rgba="0.25 0.25 0.25 1"/>
      </material>
    </visual>
    <collision>
      <geometry>
        <mesh filename="package://inmoov_description/meshes/torso.stl" scale="0.001 0.001 0.001"/>
      </geometry>
      <origin rpy="0 0 0" xyz="0 0 0"/>
    </collision>
    <inertial>
      <origin rpy="0 0 0" xyz="0 0 0"/>
      <mass value="5.95"/>
      <inertia ixx="0.0682" ixy="0" ixz="0" iyy="0.0808" iyz="0" izz="0.0218"/>
    </inertial>
  </link>
  <link name="kinect">
    <visual>
      <geometry>
        <mesh filename="package://inmoov_description/meshes/kinectone.stl" scale="0.001 0.001 0.001"/>
      </geometry>
      <origin rpy="0 0 0" xyz="0 0 0"/>
      <material name="ckinect">
        <color rgba="0.1 0.1 0.1 1"/>
      </material>
    </visual>
    <collision>
      <geometry>
        <mesh filename="package://inmoov_description/meshes/kinectone.stl" scale="0.001 0.001 0.001"/>
      </geometry>
      <origin rpy="0 0 0" xyz="0 0 0"/>
    </collision>
    <inertial>
      <origin rpy="0 0 0" xyz="0 0 0"/>
      <mass value="1.3"/>
      <inertia ixx="0.0083" ixy="0" ixz="0" iyy="0.0634" iyz="0" izz="0.0644"/>
    </inertial>
  </link>
  <link name="chestplate">
    <visual>
      <geometry>
        <mesh filename="package://inmoov_description/meshes/chest.stl" scale="0.001 0.001 0.001"/>
      </geometry>
      <origin rpy="0 0 0" xyz="0 0 0"/>
      <material name="ccover">
        <color rgba="0.6 0.6 0.6 1"/>
      </material>
    </visual>
    <collision>
      <geometry>
        <mesh filename="package://inmoov_description/meshes/chest.stl" scale="0.001 0.001 0.001"/>
      </geometry>
      <origin rpy="0 0 0" xyz="0 0 0"/>
    </collision>
    <inertial>
      <origin rpy="0 0 0" xyz="0 0 0"/>
      <mass value="0.07"/>
      <inertia ixx="0.0024" ixy="0" ixz="0" iyy="0.0047" iyz="0" izz="0.0024"/>
    </inertial>
  </link>
  <joint name="waist_rotate" type="revolute">
    <axis xyz="0 0 1"/>
    <limit effort="1000.0" lower="-1.57" upper="1.57" velocity="0.5"/>
    <origin rpy="0 0 0" xyz="0 0 1.152"/>
    <parent link="mid_stomach"/>
    <child link="top_stomach"/>
    <dynamics damping="0.7"/>
  </joint>
  <joint name="disk" type="fixed">
    <origin rpy="0 0 0" xyz="0 0 0.09"/>
    <parent link="top_stomach"/>
    <child link="disk"/>
  </joint>
  <joint name="waist_lean" type="revolute">
    <axis xyz="0 1 0"/>
    <limit effort="1000.0" lower="-0.30" upper="0.30" velocity="0.5"/>
    <origin rpy="0 0 0" xyz="0 0 0.11"/>
    <parent link="top_stomach"/>
    <child link="torso"/>
    <dynamics damping="0.7"/>
  </joint>
  <joint name="chestplate" type="fixed">
    <origin rpy="0 0 0" xyz="0 0.039 0.025"/>
    <parent link="torso"/>
    <child link="chestplate"/>
  </joint>
  <joint name="kinect" type="fixed">
    <origin rpy="0 0 0" xyz="0 0 0.066"/>
    <parent link="torso"/>
    <child link="kinect"/>
  </joint>
  <joint name="head_tilt" type="revolute">
    <axis xyz="0 1 0"/>
    <limit effort="1000.0" lower="-0.30" upper="0.30" velocity="0.5"/>
    <origin rpy="0 0 0" xyz="-0.001 -0.0315 0.4551"/>
    <parent link="torso"/>
    <child link="head_tilt"/>
    <dynamics damping="0.7"/>
  </joint>
  <joint name="head_updown" type="revolute">
    <axis xyz="1 0 0"/>
    <limit effort="1000.0" lower="-0.30" upper="0.30" velocity="0.5"/>
    <origin rpy="0 0 0" xyz="0 0 0"/>
    <parent link="head_tilt"/>
    <child link="head_base"/>
    <dynamics damping="0.7"/>
  </joint>
  <link name="head_base">
    <visual>
      <geometry>
        <mesh filename="package://inmoov_description/meshes/head_base.stl" scale="0.001 0.001 0.001"/>
      </geometry>
      <origin rpy="0 0 0" xyz="0 0 0"/>
      <material name="cframe">
        <color rgba="0.25 0.25 0.25 1"/>
      </material>
    </visual>
    <collision>
      <geometry>
        <mesh filename="package://inmoov_description/meshes/head_base.stl" scale="0.001 0.001 0.001"/>
      </geometry>
      <origin rpy="0 0 0" xyz="0 0 0"/>
    </collision>
    <inertial>
      <origin rpy="0 0 0" xyz="0 0 0"/>
      <mass value="0.023"/>
      <inertia ixx="0.0001" ixy="0" ixz="0" iyy="0.0001" iyz="0" izz="0.0001"/>
    </inertial>
  </link>
  <link name="head">
    <visual>
      <geometry>
        <mesh filename="package://inmoov_description/meshes/head.stl" scale="0.001 0.001 0.001"/>
      </geometry>
      <origin rpy="0 0 0" xyz="0 0 0"/>
      <material name="cframe">
        <color rgba="0.25 0.25 0.25 1"/>
      </material>
    </visual>
    <collision>
      <geometry>
        <mesh filename="package://inmoov_description/meshes/head.stl" scale="0.001 0.001 0.001"/>
      </geometry>
      <origin rpy="0 0 0" xyz="0 0 0"/>
    </collision>
    <inertial>
      <origin rpy="0 0 0" xyz="0 0 0"/>
      <mass value="0.1"/>
      <inertia ixx="0.0001" ixy="0" ixz="0" iyy="0.0001" iyz="0" izz="0.0001"/>
    </inertial>
  </link>
  <link name="jaw">
    <visual>
      <geometry>
        <mesh filename="package://inmoov_description/meshes/jaw.stl" scale="0.001 0.001 0.001"/>
      </geometry>
      <origin rpy="0 0 3.1415" xyz="0 0 0"/>
      <material name="ccover">
        <color rgba="0.6 0.6 0.6 1"/>
      </material>
    </visual>
    <collision>
      <geometry>
        <mesh filename="package://inmoov_description/meshes/jaw.stl" scale="0.001 0.001 0.001"/>
      </geometry>
      <origin rpy="0 0 3.1415" xyz="0 0 0"/>
    </collision>
    <inertial>
      <origin rpy="0 0 3.1415" xyz="0 0 0"/>
      <mass value="0.031"/>
      <inertia ixx="0.0001" ixy="0" ixz="0" iyy="0.0001" iyz="0" izz="0.0001"/>
    </inertial>
  </link>
  <link name="skull">
    <visual>
      <geometry>
        <mesh filename="package://inmoov_description/meshes/skull.stl" scale="0.001 0.001 0.001"/>
      </geometry>
      <origin rpy="0 0 0" xyz="0.001 0 0"/>
      <material name="ccover">
        <color rgba="0.6 0.6 0.6 1"/>
      </material>
    </visual>
    <collision>
      <geometry>
        <mesh filename="package://inmoov_description/meshes/skull.stl" scale="0.001 0.001 0.001"/>
      </geometry>
      <origin rpy="0 0 0" xyz="0.001 0 0"/>
    </collision>
    <inertial>
      <origin rpy="0 0 0" xyz="0.001 0 0"/>
      <mass value="0.066"/>
      <inertia ixx="0.0034" ixy="0" ixz="0" iyy="0.0024" iyz="0" izz="0.0029"/>
    </inertial>
  </link>
  <link name="left_ear">
    <visual>
      <geometry>
        <mesh filename="package://inmoov_description/meshes/earleftv1.stl" scale="0.001 0.001 0.001"/>
      </geometry>
      <origin rpy="0 0 0" xyz="0 0 0"/>
      <material name="cframe">
        <color rgba="0.25 0.25 0.25 1"/>
      </material>
    </visual>
    <collision>
      <geometry>
        <mesh filename="package://inmoov_description/meshes/earleftv1.stl" scale="0.001 0.001 0.001"/>
      </geometry>
      <origin rpy="0 0 0" xyz="0 0 0"/>
    </collision>
    <inertial>
      <origin rpy="0 0 0" xyz="0 0 0"/>
      <mass value="0.045"/>
      <inertia ixx="0.0001" ixy="0" ixz="0" iyy="0.0001" iyz="0" izz="0.0001"/>
    </inertial>
  </link>
  <link name="right_ear">
    <visual>
      <geometry>
        <mesh filename="package://inmoov_description/meshes/earrightv1.stl" scale="0.001 0.001 0.001"/>
      </geometry>
      <origin rpy="0 0 0" xyz="0 0 0"/>
      <material name="cframe">
        <color rgba="0.25 0.25 0.25 1"/>
      </material>
    </visual>
    <collision>
      <geometry>
        <mesh filename="package://inmoov_description/meshes/earrightv1.stl" scale="0.001 0.001 0.001"/>
      </geometry>
      <origin rpy="0 0 0" xyz="0 0 0"/>
    </collision>
    <inertial>
      <origin rpy="0 0 0" xyz="0 0 0"/>
      <mass value="0.045"/>
      <inertia ixx="0.0001" ixy="0" ixz="0" iyy="0.0001" iyz="0" izz="0.0001"/>
    </inertial>
  </link>
  <joint name="head_leftright" type="revolute">
    <axis xyz="0 0 1"/>
    <limit effort="1000.0" lower="-1.57" upper="1.57" velocity="0.5"/>
    <origin rpy="0 0 0" xyz="0 0 0.0245"/>
    <parent link="head_base"/>
    <child link="head"/>
    <dynamics damping="0.7"/>
  </joint>
  <joint name="jaw" type="revolute">
    <axis xyz="1 0 0"/>
    <limit effort="1000.0" lower="0" upper="0.15" velocity="0.5"/>
    <origin rpy="0.085 0 3.1415" xyz="-0.001 0.0375 0.0437"/>
    <parent link="head"/>
    <child link="jaw"/>
    <dynamics damping="0.7"/>
  </joint>
  <joint name="skull" type="fixed">
    <origin rpy="0 0 0" xyz="-0.001 0.044 -0.0245"/>
    <parent link="head"/>
    <child link="skull"/>
  </joint>
  <joint name="left_ear" type="fixed">
    <origin rpy="0 0 0" xyz="-0.056 0.035 0.0437"/>
    <parent link="head"/>
    <child link="left_ear"/>
  </joint>
  <joint name="right_ear" type="fixed">
    <origin rpy="0 0 0" xyz="0.056 0.035 0.0437"/>
    <parent link="head"/>
    <child link="right_ear"/>
  </joint>
  <link name="face">
    <visual>
      <geometry>
        <mesh filename="package://inmoov_description/meshes/face.stl" scale="0.001 0.001 0.001"/>
      </geometry>
      <origin rpy="0 0 0" xyz="0 0 0"/>
      <material name="ccover">
        <color rgba="0.6 0.6 0.6 1"/>
      </material>
    </visual>
    <collision>
      <geometry>
        <mesh filename="package://inmoov_description/meshes/face.stl" scale="0.001 0.001 0.001"/>
      </geometry>
      <origin rpy="0 0 0" xyz="0 0 0"/>
    </collision>
    <inertial>
      <origin rpy="0 0 0" xyz="0 0 0"/>
      <mass value="0.01437"/>
      <inertia ixx="0.0003" ixy="0" ixz="0" iyy="0.0015" iyz="0" izz="0.0013"/>
    </inertial>
  </link>
  <joint name="eyes_updown" type="revolute">
    <axis xyz="1 0 0"/>
    <limit effort="1000.0" lower="-0.45" upper="0.45" velocity="0.5"/>
    <origin rpy="0 0 0" xyz="0 0 0"/>
    <parent link="face"/>
    <child link="eyesupport"/>
    <dynamics damping="0.7"/>
  </joint>
  <link name="eyesupport">
    <visual>
      <geometry>
        <mesh filename="package://inmoov_description/meshes/eyesupport.stl" scale="0.001 0.001 0.001"/>
      </geometry>
      <origin rpy="0 0 0" xyz="0 0 0"/>
      <material name="cframe">
        <color rgba="0.25 0.25 0.25 1"/>
      </material>
    </visual>
    <collision>
      <geometry>
        <mesh filename="package://inmoov_description/meshes/eyesupport.stl" scale="0.001 0.001 0.001"/>
      </geometry>
      <origin rpy="0 0 0" xyz="0 0 0"/>
    </collision>
    <inertial>
      <origin rpy="0 0 0" xyz="0 0 0"/>
      <mass value="0.0147"/>
      <inertia ixx="0.0001" ixy="0" ixz="0" iyy="0.0001" iyz="0" izz="0.0001"/>
    </inertial>
  </link>
  <link name="right_eyesupport">
    <visual>
      <geometry>
        <mesh filename="package://inmoov_description/meshes/right_eyesupport.stl" scale="0.001 0.001 0.001"/>
      </geometry>
      <origin rpy="0 0 0" xyz="0 0 0"/>
      <material name="cframe">
        <color rgba="0.25 0.25 0.25 1"/>
      </material>
    </visual>
    <collision>
      <geometry>
        <mesh filename="package://inmoov_description/meshes/right_eyesupport.stl" scale="0.001 0.001 0.001"/>
      </geometry>
      <origin rpy="0 0 0" xyz="0 0 0"/>
    </collision>
    <inertial>
      <origin rpy="0 0 0" xyz="0 0 0"/>
      <mass value="0.01"/>
      <inertia ixx="0.0001" ixy="0" ixz="0" iyy="0.0001" iyz="0" izz="0.0001"/>
    </inertial>
  </link>
  <link name="right_camera">
    <visual>
      <geometry>
        <mesh filename="package://inmoov_description/meshes/camera.stl" scale="0.001 0.001 0.001"/>
      </geometry>
      <origin rpy="0 0 0" xyz="0 0 0"/>
      <material name="ccamera">
        <color rgba="0.1 0.1 0.1 1"/>
      </material>
    </visual>
    <collision>
      <geometry>
        <mesh filename="package://inmoov_description/meshes/camera.stl" scale="0.001 0.001 0.001"/>
      </geometry>
      <origin rpy="0 0 0" xyz="0 0 0"/>
    </collision>
    <inertial>
      <origin rpy="0 0 0" xyz="0 0 0"/>
      <mass value="0.026"/>
      <inertia ixx="0.0001" ixy="0" ixz="0" iyy="0.0001" iyz="0" izz="0.0001"/>
    </inertial>
  </link>
  <link name="right_eye">
    <visual>
      <geometry>
        <mesh filename="package://inmoov_description/meshes/eye.stl" scale="0.001 0.001 0.001"/>
      </geometry>
      <origin rpy="0 0 0" xyz="0 0 0"/>
      <material name="ceyeball">
        <color rgba="0.7 0.7 0.7 1"/>
      </material>
    </visual>
    <collision>
      <geometry>
        <mesh filename="package://inmoov_description/meshes/eye.stl" scale="0.001 0.001 0.001"/>
      </geometry>
      <origin rpy="0 0 0" xyz="0 0 0"/>
    </collision>
    <inertial>
      <origin rpy="0 0 0" xyz="0 0 0"/>
      <mass value="0.0026"/>
      <inertia ixx="0.0001" ixy="0" ixz="0" iyy="0.0001" iyz="0" izz="0.0001"/>
    </inertial>
  </link>
  <link name="right_iris">
    <visual>
      <geometry>
        <mesh filename="package://inmoov_description/meshes/iris.stl" scale="0.001 0.001 0.001"/>
      </geometry>
      <origin rpy="0 0 0" xyz="0 0 0"/>
      <material name="ciris">
        <color rgba="0.25 0.41 0.88 1"/>
      </material>
    </visual>
    <collision>
      <geometry>
        <mesh filename="package://inmoov_description/meshes/iris.stl" scale="0.001 0.001 0.001"/>
      </geometry>
      <origin rpy="0 0 0" xyz="0 0 0"/>
    </collision>
    <inertial>
      <origin rpy="0 0 0" xyz="0 0 0"/>
      <mass value="0.0005"/>
      <inertia ixx="0.0001" ixy="0" ixz="0" iyy="0.0001" iyz="0" izz="0.0001"/>
    </inertial>
  </link>
  <joint name="right_camera" type="fixed">
    <origin rpy="0 0 0" xyz="0 -0.001 0"/>
    <parent link="right_eyesupport"/>
    <child link="right_camera"/>
  </joint>
  <joint name="right_eye" type="fixed">
    <origin rpy="0 0 0" xyz="0 0.003 0"/>
    <parent link="right_eyesupport"/>
    <child link="right_eye"/>
  </joint>
  <joint name="right_iris" type="fixed">
    <origin rpy="0 0 0" xyz="0 0.0061 0"/>
    <parent link="right_eyesupport"/>
    <child link="right_iris"/>
  </joint>
  <joint name="eye_leftright" type="revolute">
    <axis xyz="0 0 1"/>
    <limit effort="1000.0" lower="-0.45" upper="0.45" velocity="0.5"/>
    <origin rpy="0 0 0" xyz="0.033 0 -0.0036"/>
    <parent link="eyesupport"/>
    <child link="right_eyesupport"/>
    <dynamics damping="0.7"/>
  </joint>
  <link name="left_eyesupport">
    <visual>
      <geometry>
        <mesh filename="package://inmoov_description/meshes/left_eyesupport.stl" scale="0.001 0.001 0.001"/>
      </geometry>
      <origin rpy="0 0 0" xyz="0 0 0"/>
      <material name="cframe">
        <color rgba="0.25 0.25 0.25 1"/>
      </material>
    </visual>
    <collision>
      <geometry>
        <mesh filename="package://inmoov_description/meshes/left_eyesupport.stl" scale="0.001 0.001 0.001"/>
      </geometry>
      <origin rpy="0 0 0" xyz="0 0 0"/>
    </collision>
    <inertial>
      <origin rpy="0 0 0" xyz="0 0 0"/>
      <mass value="0.01"/>
      <inertia ixx="0.0001" ixy="0" ixz="0" iyy="0.0001" iyz="0" izz="0.0001"/>
    </inertial>
  </link>
  <link name="left_camera">
    <visual>
      <geometry>
        <mesh filename="package://inmoov_description/meshes/camera.stl" scale="0.001 0.001 0.001"/>
      </geometry>
      <origin rpy="0 0 0" xyz="0 0 0"/>
      <material name="ccamera">
        <color rgba="0.1 0.1 0.1 1"/>
      </material>
    </visual>
    <collision>
      <geometry>
        <mesh filename="package://inmoov_description/meshes/camera.stl" scale="0.001 0.001 0.001"/>
      </geometry>
      <origin rpy="0 0 0" xyz="0 0 0"/>
    </collision>
    <inertial>
      <origin rpy="0 0 0" xyz="0 0 0"/>
      <mass value="0.026"/>
      <inertia ixx="0.0001" ixy="0" ixz="0" iyy="0.0001" iyz="0" izz="0.0001"/>
    </inertial>
  </link>
  <link name="left_eye">
    <visual>
      <geometry>
        <mesh filename="package://inmoov_description/meshes/eye.stl" scale="0.001 0.001 0.001"/>
      </geometry>
      <origin rpy="0 0 0" xyz="0 0 0"/>
      <material name="ceyeball">
        <color rgba="0.7 0.7 0.7 1"/>
      </material>
    </visual>
    <collision>
      <geometry>
        <mesh filename="package://inmoov_description/meshes/eye.stl" scale="0.001 0.001 0.001"/>
      </geometry>
      <origin rpy="0 0 0" xyz="0 0 0"/>
    </collision>
    <inertial>
      <origin rpy="0 0 0" xyz="0 0 0"/>
      <mass value="0.0026"/>
      <inertia ixx="0.0001" ixy="0" ixz="0" iyy="0.0001" iyz="0" izz="0.0001"/>
    </inertial>
  </link>
  <link name="left_iris">
    <visual>
      <geometry>
        <mesh filename="package://inmoov_description/meshes/iris.stl" scale="0.001 0.001 0.001"/>
      </geometry>
      <origin rpy="0 0 0" xyz="0 0 0"/>
      <material name="ciris">
        <color rgba="0.25 0.41 0.88 1"/>
      </material>
    </visual>
    <collision>
      <geometry>
        <mesh filename="package://inmoov_description/meshes/iris.stl" scale="0.001 0.001 0.001"/>
      </geometry>
      <origin rpy="0 0 0" xyz="0 0 0"/>
    </collision>
    <inertial>
      <origin rpy="0 0 0" xyz="0 0 0"/>
      <mass value="0.0005"/>
      <inertia ixx="0.0001" ixy="0" ixz="0" iyy="0.0001" iyz="0" izz="0.0001"/>
    </inertial>
  </link>
  <joint name="left_camera" type="fixed">
    <origin rpy="0 0 0" xyz="0 -0.001 0"/>
    <parent link="left_eyesupport"/>
    <child link="left_camera"/>
  </joint>
  <joint name="left_eye" type="fixed">
    <origin rpy="0 0 0" xyz="0 0.003 0"/>
    <parent link="left_eyesupport"/>
    <child link="left_eye"/>
  </joint>
  <joint name="left_iris" type="fixed">
    <origin rpy="0 0 0" xyz="0 0.0061 0"/>
    <parent link="left_eyesupport"/>
    <child link="left_iris"/>
  </joint>
  <joint name="left_eye_leftright" type="revolute">
    <axis xyz="0 0 1"/>
    <limit effort="1000.0" lower="-0.45" upper="0.45" velocity="0.5"/>
    <mimic joint="eye_leftright" multiplier="1" offset="0"/>
    <origin rpy="0 0 0" xyz="-0.033 0 -0.0036"/>
    <parent link="eyesupport"/>
    <child link="left_eyesupport"/>
    <dynamics damping="0.7"/>
  </joint>
  <joint name="face" type="fixed">
    <origin rpy="0 0 0" xyz="0 0.0637 0.079"/>
    <parent link="skull"/>
    <child link="face"/>
  </joint>
  <link name="right_shoulder_base">
    <visual>
      <geometry>
        <mesh filename="package://inmoov_description/meshes/right_shoulder_base.stl" scale="0.001 0.001 0.001"/>
      </geometry>
      <origin rpy="0 0 0" xyz="0 0 0"/>
      <material name="cframe">
        <color rgba="0.25 0.25 0.25 1"/>
      </material>
    </visual>
    <collision>
      <geometry>
        <mesh filename="package://inmoov_description/meshes/right_shoulder_base.stl" scale="0.001 0.001 0.001"/>
      </geometry>
      <origin rpy="0 0 0" xyz="0 0 0"/>
    </collision>
    <inertial>
      <origin rpy="0 0 0" xyz="0 0 0"/>
      <mass value="0.25"/>
      <inertia ixx="0.0019" ixy="0" ixz="0" iyy="0.0018" iyz="0" izz="0.0012"/>
    </inertial>
  </link>
  <link name="right_shoulder">
    <visual>
      <geometry>
        <mesh filename="package://inmoov_description/meshes/right_shoulder.stl" scale="0.001 0.001 0.001"/>
      </geometry>
      <origin rpy="0 0 0" xyz="0 0 0"/>
      <material name="cframe">
        <color rgba="0.25 0.25 0.25 1"/>
      </material>
    </visual>
    <collision>
      <geometry>
        <mesh filename="package://inmoov_description/meshes/right_shoulder.stl" scale="0.001 0.001 0.001"/>
      </geometry>
      <origin rpy="0 0 0" xyz="0 0 0"/>
    </collision>
    <inertial>
      <origin rpy="0 0 0" xyz="0 0 0"/>
      <mass value="0.15"/>
      <inertia ixx="0.0014" ixy="0" ixz="0" iyy="0.0001" iyz="0" izz="0.0014"/>
    </inertial>
  </link>
  <link name="right_bicep">
    <visual>
      <geometry>
        <mesh filename="package://inmoov_description/meshes/bicep.stl" scale="0.001 0.001 0.001"/>
      </geometry>
      <origin rpy="0 0 0" xyz="0 0 0"/>
      <material name="cframe">
        <color rgba="0.25 0.25 0.25 1"/>
      </material>
    </visual>
    <collision>
      <geometry>
        <mesh filename="package://inmoov_description/meshes/bicep.stl" scale="0.001 0.001 0.001"/>
      </geometry>
      <origin rpy="0 0 0" xyz="0 0 0"/>
    </collision>
    <inertial>
      <origin rpy="0 0 0" xyz="0 0 0"/>
      <mass value="0.148"/>
      <inertia ixx="0.0007" ixy="0" ixz="0" iyy="0.0007" iyz="0" izz="0.0002"/>
    </inertial>
  </link>
  <link name="right_bicepcover">
    <visual>
      <geometry>
        <mesh filename="package://inmoov_description/meshes/bicepcover.stl" scale="0.001 0.001 0.001"/>
      </geometry>
      <origin rpy="0 0 0" xyz="0 0 0"/>
      <material name="ccover">
        <color rgba="0.6 0.6 0.6 1"/>
      </material>
    </visual>
    <collision>
      <geometry>
        <mesh filename="package://inmoov_description/meshes/bicepcover.stl" scale="0.001 0.001 0.001"/>
      </geometry>
      <origin rpy="0 0 0" xyz="0 0 0"/>
    </collision>
    <inertial>
      <origin rpy="0 0 0" xyz="0 0 0"/>
      <mass value="0.15"/>
      <inertia ixx="0.0040" ixy="0" ixz="0" iyy="0.0035" iyz="0" izz="0.0025"/>
    </inertial>
  </link>
  <link name="right_forearm">
    <visual>
      <geometry>
        <mesh filename="package://inmoov_description/meshes/right_forearm.stl" scale="0.001 0.001 0.001"/>
      </geometry>
      <origin rpy="0 0 0" xyz="0.001 0 0"/>
      <material name="ccover">
        <color rgba="0.6 0.6 0.6 1"/>
      </material>
    </visual>
    <collision>
      <geometry>
        <mesh filename="package://inmoov_description/meshes/right_forearm.stl" scale="0.001 0.001 0.001"/>
      </geometry>
      <origin rpy="0 0 0" xyz="0.001 0 0"/>
    </collision>
    <inertial>
      <origin rpy="0 0 0" xyz="0.001 0 0"/>
      <mass value="0.06"/>
      <inertia ixx="0.0033" ixy="0" ixz="0" iyy="0.0033" iyz="0" izz="0.0007"/>
    </inertial>
  </link>
  <joint name="right_shoulder_up" type="revolute">
    <axis xyz="1 0 0"/>
    <limit effort="1000.0" lower="0" upper="3.14" velocity="0.5"/>
    <origin rpy="0 0 0" xyz="0.012 0 -0.04"/>
    <parent link="right_shoulder_base"/>
    <child link="right_shoulder"/>
    <dynamics damping="0.7"/>
  </joint>
  <joint name="right_bicep_rotate" type="revolute">
    <axis xyz="0 0 1"/>
    <limit effort="1000.0" lower="-1.57" upper="1.57" velocity="0.5"/>
    <origin rpy="0 0 0" xyz="0.066 0 -0.060"/>
    <parent link="right_shoulder"/>
    <child link="right_bicep"/>
    <dynamics damping="0.7"/>
  </joint>
  <joint name="right_bicep" type="revolute">
    <axis xyz="1 0 0"/>
    <limit effort="1000.0" lower="0.4" upper="1.57" velocity="0.5"/>
    <origin rpy="0 0 0" xyz="0 -0.0278 -0.2235"/>
    <parent link="right_bicep"/>
    <child link="right_forearm"/>
    <dynamics damping="0.7"/>
  </joint>
  <joint name="right_bicepcover" type="fixed">
    <origin rpy="0 0 0" xyz="0 0 0"/>
    <parent link="right_bicep"/>
    <child link="right_bicepcover"/>
  </joint>
  <joint name="right_shoulder_side" type="revolute">
    <axis xyz="0 1 0"/>
    <limit effort="1000.0" lower="-0.75" upper="0" velocity="0.5"/>
    <origin rpy="0 0 0" xyz="0.143 0 0.298"/>
    <parent link="torso"/>
    <child link="right_shoulder_base"/>
    <dynamics damping="0.7"/>
  </joint>
  <link name="right_hand">
    <visual>
      <geometry>
        <mesh filename="package://inmoov_description/meshes/right_hand.stl" scale="0.001 0.001 0.001"/>
      </geometry>
      <origin rpy="0 0 0" xyz="0 0 0"/>
      <material name="cframe">
        <color rgba="0.25 0.25 0.25 1"/>
      </material>
    </visual>
    <collision>
      <geometry>
        <mesh filename="package://inmoov_description/meshes/right_hand.stl" scale="0.001 0.001 0.001"/>
      </geometry>
      <origin rpy="0 0 0" xyz="0 0 0"/>
    </collision>
    <inertial>
      <origin rpy="0 0 0" xyz="0 0 0"/>
      <mass value="0.044"/>
      <inertia ixx="0.0001" ixy="0" ixz="0" iyy="0.0007" iyz="0" izz="0.0001"/>
    </inertial>
  </link>
  <link name="right_thumb1">
    <visual>
      <geometry>
        <mesh filename="package://inmoov_description/meshes/right_thumb5_1.stl" scale="0.001 0.001 0.001"/>
      </geometry>
      <origin rpy="3.1415 0 0" xyz="0 0 0"/>
      <material name="cframe">
        <color rgba="0.25 0.25 0.25 1"/>
      </material>
    </visual>
    <collision>
      <geometry>
        <mesh filename="package://inmoov_description/meshes/right_thumb5_1.stl" scale="0.001 0.001 0.001"/>
      </geometry>
      <origin rpy="3.1415 0 0" xyz="0 0 0"/>
    </collision>
    <inertial>
      <origin rpy="3.1415 0 0" xyz="0 0 0"/>
      <mass value="0.005"/>
      <inertia ixx="0.0001" ixy="0" ixz="0" iyy="0.0001" iyz="0" izz="0.0001"/>
    </inertial>
  </link>
  <link name="right_thumb2">
    <visual>
      <geometry>
        <mesh filename="package://inmoov_description/meshes/thumb5_2.stl" scale="0.001 0.001 0.001"/>
      </geometry>
      <origin rpy="0 0 3.1415" xyz="0 0 0"/>
      <material name="cframe">
        <color rgba="0.25 0.25 0.25 1"/>
      </material>
    </visual>
    <collision>
      <geometry>
        <mesh filename="package://inmoov_description/meshes/thumb5_2.stl" scale="0.001 0.001 0.001"/>
      </geometry>
      <origin rpy="0 0 3.1415" xyz="0 0 0"/>
    </collision>
    <inertial>
      <origin rpy="0 0 3.1415" xyz="0 0 0"/>
      <mass value="0.004"/>
      <inertia ixx="0.0001" ixy="0" ixz="0" iyy="0.0001" iyz="0" izz="0.0001"/>
    </inertial>
  </link>
  <link name="right_thumb3">
    <visual>
      <geometry>
        <mesh filename="package://inmoov_description/meshes/thumb5_3.stl" scale="0.001 0.001 0.001"/>
      </geometry>
      <origin rpy="0 0 3.1415" xyz="0 0 0"/>
      <material name="cframe">
        <color rgba="0.25 0.25 0.25 1"/>
      </material>
    </visual>
    <collision>
      <geometry>
        <mesh filename="package://inmoov_description/meshes/thumb5_3.stl" scale="0.001 0.001 0.001"/>
      </geometry>
      <origin rpy="0 0 3.1415" xyz="0 0 0"/>
    </collision>
    <inertial>
      <origin rpy="0 0 3.1415" xyz="0 0 0"/>
      <mass value="0.003"/>
      <inertia ixx="0.0001" ixy="0" ixz="0" iyy="0.0001" iyz="0" izz="0.0001"/>
    </inertial>
  </link>
  <link name="right_index1">
    <visual>
      <geometry>
        <mesh filename="package://inmoov_description/meshes/index3_1.stl" scale="0.001 0.001 0.001"/>
      </geometry>
      <origin rpy="0 0 3.1415" xyz="0 0 0"/>
      <material name="cframe">
        <color rgba="0.25 0.25 0.25 1"/>
      </material>
    </visual>
    <collision>
      <geometry>
        <mesh filename="package://inmoov_description/meshes/index3_1.stl" scale="0.001 0.001 0.001"/>
      </geometry>
      <origin rpy="0 0 3.1415" xyz="0 0 0"/>
    </collision>
    <inertial>
      <origin rpy="0 0 3.1415" xyz="0 0 0"/>
      <mass value="0.003"/>
      <inertia ixx="0.0001" ixy="0" ixz="0" iyy="0.0001" iyz="0" izz="0.0001"/>
    </inertial>
  </link>
  <link name="right_index2">
    <visual>
      <geometry>
        <mesh filename="package://inmoov_description/meshes/index3_2.stl" scale="0.001 0.001 0.001"/>
      </geometry>
      <origin rpy="0 0 3.1415" xyz="0 0 0"/>
      <material name="cframe">
        <color rgba="0.25 0.25 0.25 1"/>
      </material>
    </visual>
    <collision>
      <geometry>
        <mesh filename="package://inmoov_description/meshes/index3_2.stl" scale="0.001 0.001 0.001"/>
      </geometry>
      <origin rpy="0 0 3.1415" xyz="0 0 0"/>
    </collision>
    <inertial>
      <origin rpy="0 0 3.1415" xyz="0 0 0"/>
      <mass value="0.003"/>
      <inertia ixx="0.0001" ixy="0" ixz="0" iyy="0.0001" iyz="0" izz="0.0001"/>
    </inertial>
  </link>
  <link name="right_index3">
    <visual>
      <geometry>
        <mesh filename="package://inmoov_description/meshes/index3_3.stl" scale="0.001 0.001 0.001"/>
      </geometry>
      <origin rpy="0 0 3.1415" xyz="0 0 0"/>
      <material name="cframe">
        <color rgba="0.25 0.25 0.25 1"/>
      </material>
    </visual>
    <collision>
      <geometry>
        <mesh filename="package://inmoov_description/meshes/index3_3.stl" scale="0.001 0.001 0.001"/>
      </geometry>
      <origin rpy="0 0 3.1415" xyz="0 0 0"/>
    </collision>
    <inertial>
      <origin rpy="0 0 3.1415" xyz="0 0 0"/>
      <mass value="0.003"/>
      <inertia ixx="0.0001" ixy="0" ixz="0" iyy="0.0001" iyz="0" izz="0.0001"/>
    </inertial>
  </link>
  <link name="right_middle1">
    <visual>
      <geometry>
        <mesh filename="package://inmoov_description/meshes/middle3_1.stl" scale="0.001 0.001 0.001"/>
      </geometry>
      <origin rpy="0 0 3.1415" xyz="0 0 0"/>
      <material name="cframe">
        <color rgba="0.25 0.25 0.25 1"/>
      </material>
    </visual>
    <collision>
      <geometry>
        <mesh filename="package://inmoov_description/meshes/middle3_1.stl" scale="0.001 0.001 0.001"/>
      </geometry>
      <origin rpy="0 0 3.1415" xyz="0 0 0"/>
    </collision>
    <inertial>
      <origin rpy="0 0 3.1415" xyz="0 0 0"/>
      <mass value="0.003"/>
      <inertia ixx="0.0001" ixy="0" ixz="0" iyy="0.0001" iyz="0" izz="0.0001"/>
    </inertial>
  </link>
  <link name="right_middle2">
    <visual>
      <geometry>
        <mesh filename="package://inmoov_description/meshes/middle3_2.stl" scale="0.001 0.001 0.001"/>
      </geometry>
      <origin rpy="0 0 3.1415" xyz="0 0 0"/>
      <material name="cframe">
        <color rgba="0.25 0.25 0.25 1"/>
      </material>
    </visual>
    <collision>
      <geometry>
        <mesh filename="package://inmoov_description/meshes/middle3_2.stl" scale="0.001 0.001 0.001"/>
      </geometry>
      <origin rpy="0 0 3.1415" xyz="0 0 0"/>
    </collision>
    <inertial>
      <origin rpy="0 0 3.1415" xyz="0 0 0"/>
      <mass value="0.003"/>
      <inertia ixx="0.0001" ixy="0" ixz="0" iyy="0.0001" iyz="0" izz="0.0001"/>
    </inertial>
  </link>
  <link name="right_middle3">
    <visual>
      <geometry>
        <mesh filename="package://inmoov_description/meshes/middle3_3.stl" scale="0.001 0.001 0.001"/>
      </geometry>
      <origin rpy="0 0 3.1415" xyz="0 0 0"/>
      <material name="cframe">
        <color rgba="0.25 0.25 0.25 1"/>
      </material>
    </visual>
    <collision>
      <geometry>
        <mesh filename="package://inmoov_description/meshes/middle3_3.stl" scale="0.001 0.001 0.001"/>
      </geometry>
      <origin rpy="0 0 3.1415" xyz="0 0 0"/>
    </collision>
    <inertial>
      <origin rpy="0 0 3.1415" xyz="0 0 0"/>
      <mass value="0.003"/>
      <inertia ixx="0.0001" ixy="0" ixz="0" iyy="0.0001" iyz="0" izz="0.0001"/>
    </inertial>
  </link>
  <link name="right_ring1">
    <visual>
      <geometry>
        <mesh filename="package://inmoov_description/meshes/right_ring3_1.stl" scale="0.001 0.001 0.001"/>
      </geometry>
      <origin rpy="0 0 3.1415" xyz="0 0 0"/>
      <material name="cframe">
        <color rgba="0.25 0.25 0.25 1"/>
      </material>
    </visual>
    <collision>
      <geometry>
        <mesh filename="package://inmoov_description/meshes/right_ring3_1.stl" scale="0.001 0.001 0.001"/>
      </geometry>
      <origin rpy="0 0 3.1415" xyz="0 0 0"/>
    </collision>
    <inertial>
      <origin rpy="0 0 3.1415" xyz="0 0 0"/>
      <mass value="0.003"/>
      <inertia ixx="0.0001" ixy="0" ixz="0" iyy="0.0001" iyz="0" izz="0.0001"/>
    </inertial>
  </link>
  <link name="right_ring2">
    <visual>
      <geometry>
        <mesh filename="package://inmoov_description/meshes/ring3_2.stl" scale="0.001 0.001 0.001"/>
      </geometry>
      <origin rpy="0 0 3.1415" xyz="0 0 0"/>
      <material name="cframe">
        <color rgba="0.25 0.25 0.25 1"/>
      </material>
    </visual>
    <collision>
      <geometry>
        <mesh filename="package://inmoov_description/meshes/ring3_2.stl" scale="0.001 0.001 0.001"/>
      </geometry>
      <origin rpy="0 0 3.1415" xyz="0 0 0"/>
    </collision>
    <inertial>
      <origin rpy="0 0 3.1415" xyz="0 0 0"/>
      <mass value="0.003"/>
      <inertia ixx="0.0001" ixy="0" ixz="0" iyy="0.0001" iyz="0" izz="0.0001"/>
    </inertial>
  </link>
  <link name="right_ring3">
    <visual>
      <geometry>
        <mesh filename="package://inmoov_description/meshes/ring3_3.stl" scale="0.001 0.001 0.001"/>
      </geometry>
      <origin rpy="0 0 3.1415" xyz="0 0 0"/>
      <material name="cframe">
        <color rgba="0.25 0.25 0.25 1"/>
      </material>
    </visual>
    <collision>
      <geometry>
        <mesh filename="package://inmoov_description/meshes/ring3_3.stl" scale="0.001 0.001 0.001"/>
      </geometry>
      <origin rpy="0 0 3.1415" xyz="0 0 0"/>
    </collision>
    <inertial>
      <origin rpy="0 0 3.1415" xyz="0 0 0"/>
      <mass value="0.003"/>
      <inertia ixx="0.0001" ixy="0" ixz="0" iyy="0.0001" iyz="0" izz="0.0001"/>
    </inertial>
  </link>
  <link name="right_ring4">
    <visual>
      <geometry>
        <mesh filename="package://inmoov_description/meshes/ring3_4.stl" scale="0.001 0.001 0.001"/>
      </geometry>
      <origin rpy="0 0 3.1415" xyz="0 0 0"/>
      <material name="cframe">
        <color rgba="0.25 0.25 0.25 1"/>
      </material>
    </visual>
    <collision>
      <geometry>
        <mesh filename="package://inmoov_description/meshes/ring3_4.stl" scale="0.001 0.001 0.001"/>
      </geometry>
      <origin rpy="0 0 3.1415" xyz="0 0 0"/>
    </collision>
    <inertial>
      <origin rpy="0 0 3.1415" xyz="0 0 0"/>
      <mass value="0.003"/>
      <inertia ixx="0.0001" ixy="0" ixz="0" iyy="0.0001" iyz="0" izz="0.0001"/>
    </inertial>
  </link>
  <link name="right_pinky1">
    <visual>
      <geometry>
        <mesh filename="package://inmoov_description/meshes/right_pinky3_1.stl" scale="0.001 0.001 0.001"/>
      </geometry>
      <origin rpy="0 0 3.1415" xyz="0 0 0"/>
      <material name="cframe">
        <color rgba="0.25 0.25 0.25 1"/>
      </material>
    </visual>
    <collision>
      <geometry>
        <mesh filename="package://inmoov_description/meshes/right_pinky3_1.stl" scale="0.001 0.001 0.001"/>
      </geometry>
      <origin rpy="0 0 3.1415" xyz="0 0 0"/>
    </collision>
    <inertial>
      <origin rpy="0 0 3.1415" xyz="0 0 0"/>
      <mass value="0.003"/>
      <inertia ixx="0.0001" ixy="0" ixz="0" iyy="0.0001" iyz="0" izz="0.0001"/>
    </inertial>
  </link>
  <link name="right_pinky2">
    <visual>
      <geometry>
        <mesh filename="package://inmoov_description/meshes/pinky3_2.stl" scale="0.001 0.001 0.001"/>
      </geometry>
      <origin rpy="0 0 3.1415" xyz="0 0 0"/>
      <material name="cframe">
        <color rgba="0.25 0.25 0.25 1"/>
      </material>
    </visual>
    <collision>
      <geometry>
        <mesh filename="package://inmoov_description/meshes/pinky3_2.stl" scale="0.001 0.001 0.001"/>
      </geometry>
      <origin rpy="0 0 3.1415" xyz="0 0 0"/>
    </collision>
    <inertial>
      <origin rpy="0 0 3.1415" xyz="0 0 0"/>
      <mass value="0.003"/>
      <inertia ixx="0.0001" ixy="0" ixz="0" iyy="0.0001" iyz="0" izz="0.0001"/>
    </inertial>
  </link>
  <link name="right_pinky3">
    <visual>
      <geometry>
        <mesh filename="package://inmoov_description/meshes/pinky3_3.stl" scale="0.001 0.001 0.001"/>
      </geometry>
      <origin rpy="0 0 3.1415" xyz="0 0 0"/>
      <material name="cframe">
        <color rgba="0.25 0.25 0.25 1"/>
      </material>
    </visual>
    <collision>
      <geometry>
        <mesh filename="package://inmoov_description/meshes/pinky3_3.stl" scale="0.001 0.001 0.001"/>
      </geometry>
      <origin rpy="0 0 3.1415" xyz="0 0 0"/>
    </collision>
    <inertial>
      <origin rpy="0 0 3.1415" xyz="0 0 0"/>
      <mass value="0.003"/>
      <inertia ixx="0.0001" ixy="0" ixz="0" iyy="0.0001" iyz="0" izz="0.0001"/>
    </inertial>
  </link>
  <link name="right_pinky4">
    <visual>
      <geometry>
        <mesh filename="package://inmoov_description/meshes/pinky3_4.stl" scale="0.001 0.001 0.001"/>
      </geometry>
      <origin rpy="0 0 3.1415" xyz="0 0 0"/>
      <material name="cframe">
        <color rgba="0.25 0.25 0.25 1"/>
      </material>
    </visual>
    <collision>
      <geometry>
        <mesh filename="package://inmoov_description/meshes/pinky3_4.stl" scale="0.001 0.001 0.001"/>
      </geometry>
      <origin rpy="0 0 3.1415" xyz="0 0 0"/>
    </collision>
    <inertial>
      <origin rpy="0 0 3.1415" xyz="0 0 0"/>
      <mass value="0.003"/>
      <inertia ixx="0.0001" ixy="0" ixz="0" iyy="0.0001" iyz="0" izz="0.0001"/>
    </inertial>
  </link>
  <joint name="right_thumb1" type="revolute">
    <axis xyz="0 0 1"/>
    <limit effort="1000.0" lower="0" upper="1.57" velocity="0.5"/>
    <origin rpy="3.1415 0.1 0" xyz="-0.029 0 -0.0577"/>
    <mimic joint="right_thumb" multiplier="-0.75" offset="0"/>
    <parent link="right_hand"/>
    <child link="right_thumb1"/>
  </joint>
  <joint name="right_thumb" type="revolute">
    <axis xyz="1 0 0"/>
    <limit effort="1000.0" lower="0" upper="1.5" velocity="0.5"/>
    <origin rpy="0 2.3 -0.3" xyz="-0.02725 -0.0006 0.014"/>
    <parent link="right_thumb1"/>
    <child link="right_thumb2"/>
    <dynamics damping="0.7"/>
  </joint>
  <joint name="right_thumb3" type="revolute">
    <axis xyz="1 0 0"/>
    <limit effort="1000.0" lower="-1.57" upper="0" velocity="0.5"/>
    <origin rpy="0 0 0" xyz="0 0 -0.035"/>
    <mimic joint="right_thumb" multiplier="1" offset="0"/>
    <parent link="right_thumb2"/>
    <child link="right_thumb3"/>
  </joint>
  <joint name="right_index1" type="revolute">
    <axis xyz="1 0 0"/>
    <limit effort="1000.0" lower="0" upper="1.5" velocity="0.5"/>
    <origin rpy="0 -0.1 3.1415" xyz="-0.0342 -0.0015 -0.119"/>
    <mimic joint="right_index" multiplier="1" offset="0"/>
    <parent link="right_hand"/>
    <child link="right_index1"/>
  </joint>
  <joint name="right_index" type="revolute">
    <axis xyz="1 0 0"/>
    <limit effort="1000.0" lower="0" upper="1.5" velocity="0.5"/>
    <origin rpy="0 0 0" xyz="0 0.001 -0.03595"/>
    <parent link="right_index1"/>
    <child link="right_index2"/>
    <dynamics damping="0.7"/>
  </joint>
  <joint name="right_index3" type="revolute">
    <axis xyz="1 0 0"/>
    <limit effort="1000.0" lower="0" upper="1.5" velocity="0.5"/>
    <origin rpy="0 0 0" xyz="0 0 -0.024"/>
    <mimic joint="right_index" multiplier="1" offset="0"/>
    <parent link="right_index2"/>
    <child link="right_index3"/>
  </joint>
  <joint name="right_middle1" type="revolute">
    <axis xyz="1 0 0"/>
    <limit effort="1000.0" lower="0" upper="1.5" velocity="0.5"/>
    <origin rpy="0 0 3.1415" xyz="-0.007 -0.00175 -0.12325"/>
    <mimic joint="right_middle" multiplier="1" offset="0"/>
    <parent link="right_hand"/>
    <child link="right_middle1"/>
  </joint>
  <joint name="right_middle" type="revolute">
    <axis xyz="1 0 0"/>
    <limit effort="1000.0" lower="0" upper="1.5" velocity="0.5"/>
    <origin rpy="0 0 0" xyz="0 0.000 -0.0389"/>
    <parent link="right_middle1"/>
    <child link="right_middle2"/>
    <dynamics damping="0.7"/>
  </joint>
  <joint name="right_middle3" type="revolute">
    <axis xyz="1 0 0"/>
    <limit effort="1000.0" lower="-1.57" upper="0" velocity="0.5"/>
    <origin rpy="0 0 0" xyz="0 0.0005 -0.0259"/>
    <mimic joint="right_middle" multiplier="1" offset="0"/>
    <parent link="right_middle2"/>
    <child link="right_middle3"/>
  </joint>
  <joint name="right_ring1" type="revolute">
    <axis xyz="0 0 1"/>
    <limit effort="1000.0" lower="-1.57" upper="0" velocity="0.5"/>
    <origin rpy="0 -0.7 3.1415" xyz="0.00705 0 -0.0794"/>
    <mimic joint="right_ring" multiplier="-0.1" offset="0"/>
    <parent link="right_hand"/>
    <child link="right_ring1"/>
  </joint>
  <joint name="right_ring" type="revolute">
    <axis xyz="1 0 0"/>
    <limit effort="1000.0" lower="0" upper="1.5" velocity="0.5"/>
    <origin rpy="0 0.7775 0" xyz="-0.0351 0.00126 -0.0166"/>
    <parent link="right_ring1"/>
    <child link="right_ring2"/>
    <dynamics damping="0.7"/>
  </joint>
  <joint name="right_ring3" type="revolute">
    <axis xyz="1 0 0"/>
    <limit effort="1000.0" lower="-1.57" upper="0" velocity="0.5"/>
    <origin rpy="0 0 0" xyz="0 0.0005 -0.0345"/>
    <mimic joint="right_ring" multiplier="1" offset="0"/>
    <parent link="right_ring2"/>
    <child link="right_ring3"/>
  </joint>
  <joint name="right_ring4" type="revolute">
    <axis xyz="1 0 0"/>
    <limit effort="1000.0" lower="-1.57" upper="0" velocity="0.5"/>
    <origin rpy="0 0 0" xyz="0 0.0004 -0.0229"/>
    <mimic joint="right_ring" multiplier="1" offset="0"/>
    <parent link="right_ring3"/>
    <child link="right_ring4"/>
  </joint>
  <joint name="right_pinky1" type="revolute">
    <axis xyz="0 0 1"/>
    <limit effort="1000.0" lower="-1.57" upper="0" velocity="0.5"/>
    <origin rpy="0 -0.7 3.1415" xyz="0.027 0 -0.0555"/>
    <mimic joint="right_pinky" multiplier="-0.1" offset="0"/>
    <parent link="right_hand"/>
    <child link="right_pinky1"/>
  </joint>
  <joint name="right_pinky" type="revolute">
    <axis xyz="1 0 0"/>
    <limit effort="1000.0" lower="0" upper="1.5" velocity="0.5"/>
    <origin rpy="0 0.93 0" xyz="-0.046 -0 -0.0228"/>
    <parent link="right_pinky1"/>
    <child link="right_pinky2"/>
    <dynamics damping="0.7"/>
  </joint>
  <joint name="right_pinky3" type="revolute">
    <axis xyz="1 0 0"/>
    <limit effort="1000.0" lower="-1.57" upper="0" velocity="0.5"/>
    <origin rpy="0 0 0" xyz="0 0.0005 -0.031"/>
    <mimic joint="right_pinky" multiplier="1" offset="0"/>
    <parent link="right_pinky2"/>
    <child link="right_pinky3"/>
  </joint>
  <joint name="right_pinky4" type="revolute">
    <axis xyz="1 0 0"/>
    <limit effort="1000.0" lower="-1.57" upper="0" velocity="0.5"/>
    <origin rpy="0 0 0" xyz="0 0.0004 -0.0208"/>
    <mimic joint="right_pinky" multiplier="1" offset="0"/>
    <parent link="right_pinky3"/>
    <child link="right_pinky4"/>
  </joint>
  <link name="right_handcover">
    <visual>
      <geometry>
        <mesh filename="package://inmoov_description/meshes/right_cover_hand.stl" scale="0.001 0.001 0.001"/>
      </geometry>
      <origin rpy="0 0 0" xyz="0 0 0"/>
      <material name="ccover">
        <color rgba="0.6 0.6 0.6 1"/>
      </material>
    </visual>
    <collision>
      <geometry>
        <mesh filename="package://inmoov_description/meshes/right_cover_hand.stl" scale="0.001 0.001 0.001"/>
      </geometry>
      <origin rpy="0 0 0" xyz="0 0 0"/>
    </collision>
    <inertial>
      <origin rpy="0 0 0" xyz="0 0 0"/>
      <mass value="0.023"/>
      <inertia ixx="0.0001" ixy="0" ixz="0" iyy="0.0003" iyz="0" izz="0.0001"/>
    </inertial>
  </link>
  <link name="right_cover_handring">
    <visual>
      <geometry>
        <mesh filename="package://inmoov_description/meshes/right_cover_handring.stl" scale="0.001 0.001 0.001"/>
      </geometry>
      <origin rpy="0 0 3.1415" xyz="0 0 0"/>
      <material name="ccover">
        <color rgba="0.6 0.6 0.6 1"/>
      </material>
    </visual>
    <collision>
      <geometry>
        <mesh filename="package://inmoov_description/meshes/right_cover_handring.stl" scale="0.001 0.001 0.001"/>
      </geometry>
      <origin rpy="0 0 3.1415" xyz="0 0 0"/>
    </collision>
    <inertial>
      <origin rpy="0 0 3.1415" xyz="0 0 0"/>
      <mass value="0.002"/>
      <inertia ixx="0.0001" ixy="0" ixz="0" iyy="0.0001" iyz="0" izz="0.0001"/>
    </inertial>
  </link>
  <link name="right_cover_handpinky">
    <visual>
      <geometry>
        <mesh filename="package://inmoov_description/meshes/right_cover_handpinky.stl" scale="0.001 0.001 0.001"/>
      </geometry>
      <origin rpy="0 0 3.1415" xyz="0 0 0"/>
      <material name="ccover">
        <color rgba="0.6 0.6 0.6 1"/>
      </material>
    </visual>
    <collision>
      <geometry>
        <mesh filename="package://inmoov_description/meshes/right_cover_handpinky.stl" scale="0.001 0.001 0.001"/>
      </geometry>
      <origin rpy="0 0 3.1415" xyz="0 0 0"/>
    </collision>
    <inertial>
      <origin rpy="0 0 3.1415" xyz="0 0 0"/>
      <mass value="0.002"/>
      <inertia ixx="0.0001" ixy="0" ixz="0" iyy="0.0001" iyz="0" izz="0.0001"/>
    </inertial>
  </link>
  <link name="right_cover_thumb">
    <visual>
      <geometry>
        <mesh filename="package://inmoov_description/meshes/right_cover_thumb.stl" scale="0.001 0.001 0.001"/>
      </geometry>
      <origin rpy="3.1415 0 0" xyz="0 0 0"/>
      <material name="ccover">
        <color rgba="0.6 0.6 0.6 1"/>
      </material>
    </visual>
    <collision>
      <geometry>
        <mesh filename="package://inmoov_description/meshes/right_cover_thumb.stl" scale="0.001 0.001 0.001"/>
      </geometry>
      <origin rpy="0 0 3.1415" xyz="0 0 0"/>
    </collision>
    <inertial>
      <origin rpy="0 0 3.1415" xyz="0 0 0"/>
      <mass value="0.002"/>
      <inertia ixx="0.0001" ixy="0" ixz="0" iyy="0.0001" iyz="0" izz="0.0001"/>
    </inertial>
  </link>
  <link name="right_cover_index">
    <visual>
      <geometry>
        <mesh filename="package://inmoov_description/meshes/right_cover_index.stl" scale="0.001 0.001 0.001"/>
      </geometry>
      <origin rpy="0 0 3.1415" xyz="0 0 0"/>
      <material name="ccover">
        <color rgba="0.6 0.6 0.6 1"/>
      </material>
    </visual>
    <collision>
      <geometry>
        <mesh filename="package://inmoov_description/meshes/right_cover_index.stl" scale="0.001 0.001 0.001"/>
      </geometry>
      <origin rpy="0 0 3.1415" xyz="0 0 0"/>
    </collision>
    <inertial>
      <origin rpy="0 0 3.1415" xyz="0 0 0"/>
      <mass value="0.002"/>
      <inertia ixx="0.0001" ixy="0" ixz="0" iyy="0.0001" iyz="0" izz="0.0001"/>
    </inertial>
  </link>
  <link name="right_cover_middle">
    <visual>
      <geometry>
        <mesh filename="package://inmoov_description/meshes/right_cover_middle.stl" scale="0.001 0.001 0.001"/>
      </geometry>
      <origin rpy="0 0 3.1415" xyz="0 0 0"/>
      <material name="ccover">
        <color rgba="0.6 0.6 0.6 1"/>
      </material>
    </visual>
    <collision>
      <geometry>
        <mesh filename="package://inmoov_description/meshes/right_cover_middle.stl" scale="0.001 0.001 0.001"/>
      </geometry>
      <origin rpy="0 0 3.1415" xyz="0 0 0"/>
    </collision>
    <inertial>
      <origin rpy="0 0 3.1415" xyz="0 0 0"/>
      <mass value="0.002"/>
      <inertia ixx="0.0001" ixy="0" ixz="0" iyy="0.0001" iyz="0" izz="0.0001"/>
    </inertial>
  </link>
  <link name="right_cover_ring">
    <visual>
      <geometry>
        <mesh filename="package://inmoov_description/meshes/right_cover_ring.stl" scale="0.001 0.001 0.001"/>
      </geometry>
      <origin rpy="0 0 3.1415" xyz="0 0 0"/>
      <material name="ccover">
        <color rgba="0.6 0.6 0.6 1"/>
      </material>
    </visual>
    <collision>
      <geometry>
        <mesh filename="package://inmoov_description/meshes/right_cover_ring.stl" scale="0.001 0.001 0.001"/>
      </geometry>
      <origin rpy="0 0 3.1415" xyz="0 0 0"/>
    </collision>
    <inertial>
      <origin rpy="0 0 3.1415" xyz="0 0 0"/>
      <mass value="0.002"/>
      <inertia ixx="0.0001" ixy="0" ixz="0" iyy="0.0001" iyz="0" izz="0.0001"/>
    </inertial>
  </link>
  <link name="right_cover_pinky">
    <visual>
      <geometry>
        <mesh filename="package://inmoov_description/meshes/right_cover_pinky.stl" scale="0.001 0.001 0.001"/>
      </geometry>
      <origin rpy="0 0 3.1415" xyz="0 0 0"/>
      <material name="ccover">
        <color rgba="0.6 0.6 0.6 1"/>
      </material>
    </visual>
    <collision>
      <geometry>
        <mesh filename="package://inmoov_description/meshes/right_cover_pinky.stl" scale="0.001 0.001 0.001"/>
      </geometry>
      <origin rpy="0 0 3.1415" xyz="0 0 0"/>
    </collision>
    <inertial>
      <origin rpy="0 0 3.1415" xyz="0 0 0"/>
      <mass value="0.002"/>
      <inertia ixx="0.0001" ixy="0" ixz="0" iyy="0.0001" iyz="0" izz="0.0001"/>
    </inertial>
  </link>
  <joint name="right_handcover" type="fixed">
    <origin rpy="0 0 0" xyz="-0.0192 0.009 -0.0977"/>
    <parent link="right_hand"/>
    <child link="right_handcover"/>
  </joint>
  <joint name="right_cover_handring" type="fixed">
    <origin rpy="0 0.7 0" xyz="-0.015 -0.009 -0.0008"/>
    <parent link="right_ring1"/>
    <child link="right_cover_handring"/>
  </joint>
  <joint name="right_cover_handpinky" type="fixed">
    <origin rpy="0 0.7 0" xyz="-0.0205 -0.01 -0.0069"/>
    <parent link="right_pinky1"/>
    <child link="right_cover_handpinky"/>
  </joint>
  <joint name="right_cover_thumb" type="fixed">
    <origin rpy="0 3.1 0" xyz="-0.02125 -0.01 -0.0047"/>
    <parent link="right_thumb1"/>
    <child link="right_cover_thumb"/>
  </joint>
  <joint name="right_cover_index" type="fixed">
    <origin rpy="0.05 0 0" xyz="0 -0.0071 -0.012"/>
    <parent link="right_index1"/>
    <child link="right_cover_index"/>
  </joint>
  <joint name="right_cover_middle" type="fixed">
    <origin rpy="-0.05 0 0" xyz="0 -0.0071 -0.012"/>
    <parent link="right_middle1"/>
    <child link="right_cover_middle"/>
  </joint>
  <joint name="right_cover_ring" type="fixed">
    <origin rpy="-0.05 -0.1 0" xyz="0 -0.005 -0.011"/>
    <parent link="right_ring2"/>
    <child link="right_cover_ring"/>
  </joint>
  <joint name="right_cover_pinky" type="fixed">
    <origin rpy="-0.05 -0.1 0" xyz="0 -0.005 -0.0105"/>
    <parent link="right_pinky2"/>
    <child link="right_cover_pinky"/>
  </joint>
  <joint name="right_hand" type="revolute">
    <axis xyz="0 0 1"/>
    <limit effort="1000.0" lower="-3.14" upper="0" velocity="0.5"/>
    <origin rpy="0 0 0" xyz="-0.01 -0.0144 -0.2885"/>
    <parent link="right_forearm"/>
    <child link="right_hand"/>
    <dynamics damping="0.7"/>
  </joint>
  <link name="left_shoulder_base">
    <visual>
      <geometry>
        <mesh filename="package://inmoov_description/meshes/left_shoulder_base.stl" scale="0.001 0.001 0.001"/>
      </geometry>
      <origin rpy="0 0 0" xyz="0 0 0"/>
      <material name="cframe">
        <color rgba="0.25 0.25 0.25 1"/>
      </material>
    </visual>
    <collision>
      <geometry>
        <mesh filename="package://inmoov_description/meshes/left_shoulder_base.stl" scale="0.001 0.001 0.001"/>
      </geometry>
      <origin rpy="0 0 0" xyz="0 0 0"/>
    </collision>
    <inertial>
      <origin rpy="0 0 0" xyz="0 0 0"/>
      <mass value="0.25"/>
      <inertia ixx="0.0019" ixy="0" ixz="0" iyy="0.0018" iyz="0" izz="0.0012"/>
    </inertial>
  </link>
  <link name="left_shoulder">
    <visual>
      <geometry>
        <mesh filename="package://inmoov_description/meshes/left_shoulder.stl" scale="0.001 0.001 0.001"/>
      </geometry>
      <origin rpy="0 0 0" xyz="0 0 0"/>
      <material name="cframe">
        <color rgba="0.25 0.25 0.25 1"/>
      </material>
    </visual>
    <collision>
      <geometry>
        <mesh filename="package://inmoov_description/meshes/left_shoulder.stl" scale="0.001 0.001 0.001"/>
      </geometry>
      <origin rpy="0 0 0" xyz="0 0 0"/>
    </collision>
    <inertial>
      <origin rpy="0 0 0" xyz="0 0 0"/>
      <mass value="0.15"/>
      <inertia ixx="0.0014" ixy="0" ixz="0" iyy="0.0001" iyz="0" izz="0.0014"/>
    </inertial>
  </link>
  <link name="left_bicep">
    <visual>
      <geometry>
        <mesh filename="package://inmoov_description/meshes/bicep.stl" scale="0.001 0.001 0.001"/>
      </geometry>
      <origin rpy="0 0 0" xyz="0 0 0"/>
      <material name="cframe">
        <color rgba="0.25 0.25 0.25 1"/>
      </material>
    </visual>
    <collision>
      <geometry>
        <mesh filename="package://inmoov_description/meshes/bicep.stl" scale="0.001 0.001 0.001"/>
      </geometry>
      <origin rpy="0 0 0" xyz="0 0 0"/>
    </collision>
    <inertial>
      <origin rpy="0 0 0" xyz="0 0 0"/>
      <mass value="0.148"/>
      <inertia ixx="0.0007" ixy="0" ixz="0" iyy="0.0007" iyz="0" izz="0.0002"/>
    </inertial>
  </link>
  <link name="left_bicepcover">
    <visual>
      <geometry>
        <mesh filename="package://inmoov_description/meshes/bicepcover.stl" scale="0.001 0.001 0.001"/>
      </geometry>
      <origin rpy="0 0 0" xyz="0 0 0"/>
      <material name="ccover">
        <color rgba="0.6 0.6 0.6 1"/>
      </material>
    </visual>
    <collision>
      <geometry>
        <mesh filename="package://inmoov_description/meshes/bicepcover.stl" scale="0.001 0.001 0.001"/>
      </geometry>
      <origin rpy="0 0 0" xyz="0 0 0"/>
    </collision>
    <inertial>
      <origin rpy="0 0 0" xyz="0 0 0"/>
      <mass value="0.15"/>
      <inertia ixx="0.0040" ixy="0" ixz="0" iyy="0.0035" iyz="0" izz="0.0025"/>
    </inertial>
  </link>
  <link name="left_forearm">
    <visual>
      <geometry>
        <mesh filename="package://inmoov_description/meshes/left_forearm.stl" scale="0.001 0.001 0.001"/>
      </geometry>
      <origin rpy="0 0 0" xyz="-0.001 0 0"/>
      <material name="ccover">
        <color rgba="0.6 0.6 0.6 1"/>
      </material>
    </visual>
    <collision>
      <geometry>
        <mesh filename="package://inmoov_description/meshes/left_forearm.stl" scale="0.001 0.001 0.001"/>
      </geometry>
      <origin rpy="0 0 0" xyz="-0.001 0 0"/>
    </collision>
    <inertial>
      <origin rpy="0 0 0" xyz="-0.001 0 0"/>
      <mass value="0.06"/>
      <inertia ixx="0.0033" ixy="0" ixz="0" iyy="0.0033" iyz="0" izz="0.0007"/>
    </inertial>
  </link>
  <joint name="left_shoulder_up" type="revolute">
    <axis xyz="1 0 0"/>
    <limit effort="1000.0" lower="0" upper="3.14" velocity="0.5"/>
    <origin rpy="0 0 0" xyz="-0.012 0 -0.04"/>
    <parent link="left_shoulder_base"/>
    <child link="left_shoulder"/>
    <dynamics damping="0.7"/>
  </joint>
  <joint name="left_bicep_rotate" type="revolute">
    <axis xyz="0 0 1"/>
    <limit effort="1000.0" lower="-1.57" upper="1.57" velocity="0.5"/>
    <origin rpy="0 0 0" xyz="-0.066 0 -0.060"/>
    <parent link="left_shoulder"/>
    <child link="left_bicep"/>
    <dynamics damping="0.7"/>
  </joint>
  <joint name="left_bicep" type="revolute">
    <axis xyz="1 0 0"/>
    <limit effort="1000.0" lower="0.4" upper="1.57" velocity="0.5"/>
    <origin rpy="0 0 0" xyz="0 -0.0278 -0.2235"/>
    <parent link="left_bicep"/>
    <child link="left_forearm"/>
    <dynamics damping="0.7"/>
  </joint>
  <joint name="left_bicepcover" type="fixed">
    <origin rpy="0 0 0" xyz="0 0 0"/>
    <parent link="left_bicep"/>
    <child link="left_bicepcover"/>
  </joint>
  <joint name="left_shoulder_side" type="revolute">
    <axis xyz="0 1 0"/>
    <limit effort="1000.0" lower="0" upper="0.75" velocity="0.5"/>
    <origin rpy="0 0 0" xyz="-0.143 0 0.298"/>
    <parent link="torso"/>
    <child link="left_shoulder_base"/>
    <dynamics damping="0.7"/>
  </joint>
  <link name="left_hand">
    <visual>
      <geometry>
        <mesh filename="package://inmoov_description/meshes/left_hand.stl" scale="0.001 0.001 0.001"/>
      </geometry>
      <origin rpy="0 0 0" xyz="0 0 0"/>
      <material name="cframe">
        <color rgba="0.25 0.25 0.25 1"/>
      </material>
    </visual>
    <collision>
      <geometry>
        <mesh filename="package://inmoov_description/meshes/left_hand.stl" scale="0.001 0.001 0.001"/>
      </geometry>
      <origin rpy="0 0 0" xyz="0 0 0"/>
    </collision>
    <inertial>
      <origin rpy="0 0 0" xyz="0 0 0"/>
      <mass value="0.044"/>
      <inertia ixx="0.0001" ixy="0" ixz="0" iyy="0.0007" iyz="0" izz="0.0001"/>
    </inertial>
  </link>
  <link name="left_thumb1">
    <visual>
      <geometry>
        <mesh filename="package://inmoov_description/meshes/left_thumb5_1.stl" scale="0.001 0.001 0.001"/>
      </geometry>
      <origin rpy="3.1415 0 0" xyz="0 0 0"/>
      <material name="cframe">
        <color rgba="0.25 0.25 0.25 1"/>
      </material>
    </visual>
    <collision>
      <geometry>
        <mesh filename="package://inmoov_description/meshes/left_thumb5_1.stl" scale="0.001 0.001 0.001"/>
      </geometry>
      <origin rpy="3.1415 0 0" xyz="0 0 0"/>
    </collision>
    <inertial>
      <origin rpy="3.1415 0 0" xyz="0 0 0"/>
      <mass value="0.005"/>
      <inertia ixx="0.0001" ixy="0" ixz="0" iyy="0.0001" iyz="0" izz="0.0001"/>
    </inertial>
  </link>
  <link name="left_thumb2">
    <visual>
      <geometry>
        <mesh filename="package://inmoov_description/meshes/thumb5_2.stl" scale="0.001 0.001 0.001"/>
      </geometry>
      <origin rpy="0 0 3.1415" xyz="0 0 0"/>
      <material name="cframe">
        <color rgba="0.25 0.25 0.25 1"/>
      </material>
    </visual>
    <collision>
      <geometry>
        <mesh filename="package://inmoov_description/meshes/thumb5_2.stl" scale="0.001 0.001 0.001"/>
      </geometry>
      <origin rpy="0 0 3.1415" xyz="0 0 0"/>
    </collision>
    <inertial>
      <origin rpy="0 0 3.1415" xyz="0 0 0"/>
      <mass value="0.004"/>
      <inertia ixx="0.0001" ixy="0" ixz="0" iyy="0.0001" iyz="0" izz="0.0001"/>
    </inertial>
  </link>
  <link name="left_thumb3">
    <visual>
      <geometry>
        <mesh filename="package://inmoov_description/meshes/thumb5_3.stl" scale="0.001 0.001 0.001"/>
      </geometry>
      <origin rpy="0 0 3.1415" xyz="0 0 0"/>
      <material name="cframe">
        <color rgba="0.25 0.25 0.25 1"/>
      </material>
    </visual>
    <collision>
      <geometry>
        <mesh filename="package://inmoov_description/meshes/thumb5_3.stl" scale="0.001 0.001 0.001"/>
      </geometry>
      <origin rpy="0 0 3.1415" xyz="0 0 0"/>
    </collision>
    <inertial>
      <origin rpy="0 0 3.1415" xyz="0 0 0"/>
      <mass value="0.003"/>
      <inertia ixx="0.0001" ixy="0" ixz="0" iyy="0.0001" iyz="0" izz="0.0001"/>
    </inertial>
  </link>
  <link name="left_index1">
    <visual>
      <geometry>
        <mesh filename="package://inmoov_description/meshes/index3_1.stl" scale="0.001 0.001 0.001"/>
      </geometry>
      <origin rpy="0 0 3.1415" xyz="0 0 0"/>
      <material name="cframe">
        <color rgba="0.25 0.25 0.25 1"/>
      </material>
    </visual>
    <collision>
      <geometry>
        <mesh filename="package://inmoov_description/meshes/index3_1.stl" scale="0.001 0.001 0.001"/>
      </geometry>
      <origin rpy="0 0 3.1415" xyz="0 0 0"/>
    </collision>
    <inertial>
      <origin rpy="0 0 3.1415" xyz="0 0 0"/>
      <mass value="0.003"/>
      <inertia ixx="0.0001" ixy="0" ixz="0" iyy="0.0001" iyz="0" izz="0.0001"/>
    </inertial>
  </link>
  <link name="left_index2">
    <visual>
      <geometry>
        <mesh filename="package://inmoov_description/meshes/index3_2.stl" scale="0.001 0.001 0.001"/>
      </geometry>
      <origin rpy="0 0 3.1415" xyz="0 0 0"/>
      <material name="cframe">
        <color rgba="0.25 0.25 0.25 1"/>
      </material>
    </visual>
    <collision>
      <geometry>
        <mesh filename="package://inmoov_description/meshes/index3_2.stl" scale="0.001 0.001 0.001"/>
      </geometry>
      <origin rpy="0 0 3.1415" xyz="0 0 0"/>
    </collision>
    <inertial>
      <origin rpy="0 0 3.1415" xyz="0 0 0"/>
      <mass value="0.003"/>
      <inertia ixx="0.0001" ixy="0" ixz="0" iyy="0.0001" iyz="0" izz="0.0001"/>
    </inertial>
  </link>
  <link name="left_index3">
    <visual>
      <geometry>
        <mesh filename="package://inmoov_description/meshes/index3_3.stl" scale="0.001 0.001 0.001"/>
      </geometry>
      <origin rpy="0 0 3.1415" xyz="0 0 0"/>
      <material name="cframe">
        <color rgba="0.25 0.25 0.25 1"/>
      </material>
    </visual>
    <collision>
      <geometry>
        <mesh filename="package://inmoov_description/meshes/index3_3.stl" scale="0.001 0.001 0.001"/>
      </geometry>
      <origin rpy="0 0 3.1415" xyz="0 0 0"/>
    </collision>
    <inertial>
      <origin rpy="0 0 3.1415" xyz="0 0 0"/>
      <mass value="0.003"/>
      <inertia ixx="0.0001" ixy="0" ixz="0" iyy="0.0001" iyz="0" izz="0.0001"/>
    </inertial>
  </link>
  <link name="left_middle1">
    <visual>
      <geometry>
        <mesh filename="package://inmoov_description/meshes/middle3_1.stl" scale="0.001 0.001 0.001"/>
      </geometry>
      <origin rpy="0 0 3.1415" xyz="0 0 0"/>
      <material name="cframe">
        <color rgba="0.25 0.25 0.25 1"/>
      </material>
    </visual>
    <collision>
      <geometry>
        <mesh filename="package://inmoov_description/meshes/middle3_1.stl" scale="0.001 0.001 0.001"/>
      </geometry>
      <origin rpy="0 0 3.1415" xyz="0 0 0"/>
    </collision>
    <inertial>
      <origin rpy="0 0 3.1415" xyz="0 0 0"/>
      <mass value="0.003"/>
      <inertia ixx="0.0001" ixy="0" ixz="0" iyy="0.0001" iyz="0" izz="0.0001"/>
    </inertial>
  </link>
  <link name="left_middle2">
    <visual>
      <geometry>
        <mesh filename="package://inmoov_description/meshes/middle3_2.stl" scale="0.001 0.001 0.001"/>
      </geometry>
      <origin rpy="0 0 3.1415" xyz="0 0 0"/>
      <material name="cframe">
        <color rgba="0.25 0.25 0.25 1"/>
      </material>
    </visual>
    <collision>
      <geometry>
        <mesh filename="package://inmoov_description/meshes/middle3_2.stl" scale="0.001 0.001 0.001"/>
      </geometry>
      <origin rpy="0 0 3.1415" xyz="0 0 0"/>
    </collision>
    <inertial>
      <origin rpy="0 0 3.1415" xyz="0 0 0"/>
      <mass value="0.003"/>
      <inertia ixx="0.0001" ixy="0" ixz="0" iyy="0.0001" iyz="0" izz="0.0001"/>
    </inertial>
  </link>
  <link name="left_middle3">
    <visual>
      <geometry>
        <mesh filename="package://inmoov_description/meshes/middle3_3.stl" scale="0.001 0.001 0.001"/>
      </geometry>
      <origin rpy="0 0 3.1415" xyz="0 0 0"/>
      <material name="cframe">
        <color rgba="0.25 0.25 0.25 1"/>
      </material>
    </visual>
    <collision>
      <geometry>
        <mesh filename="package://inmoov_description/meshes/middle3_3.stl" scale="0.001 0.001 0.001"/>
      </geometry>
      <origin rpy="0 0 3.1415" xyz="0 0 0"/>
    </collision>
    <inertial>
      <origin rpy="0 0 3.1415" xyz="0 0 0"/>
      <mass value="0.003"/>
      <inertia ixx="0.0001" ixy="0" ixz="0" iyy="0.0001" iyz="0" izz="0.0001"/>
    </inertial>
  </link>
  <link name="left_ring1">
    <visual>
      <geometry>
        <mesh filename="package://inmoov_description/meshes/left_ring3_1.stl" scale="0.001 0.001 0.001"/>
      </geometry>
      <origin rpy="0 0 3.1415" xyz="0 0 0"/>
      <material name="cframe">
        <color rgba="0.25 0.25 0.25 1"/>
      </material>
    </visual>
    <collision>
      <geometry>
        <mesh filename="package://inmoov_description/meshes/left_ring3_1.stl" scale="0.001 0.001 0.001"/>
      </geometry>
      <origin rpy="0 0 3.1415" xyz="0 0 0"/>
    </collision>
    <inertial>
      <origin rpy="0 0 3.1415" xyz="0 0 0"/>
      <mass value="0.003"/>
      <inertia ixx="0.0001" ixy="0" ixz="0" iyy="0.0001" iyz="0" izz="0.0001"/>
    </inertial>
  </link>
  <link name="left_ring2">
    <visual>
      <geometry>
        <mesh filename="package://inmoov_description/meshes/ring3_2.stl" scale="0.001 0.001 0.001"/>
      </geometry>
      <origin rpy="0 0 3.1415" xyz="0 0 0"/>
      <material name="cframe">
        <color rgba="0.25 0.25 0.25 1"/>
      </material>
    </visual>
    <collision>
      <geometry>
        <mesh filename="package://inmoov_description/meshes/ring3_2.stl" scale="0.001 0.001 0.001"/>
      </geometry>
      <origin rpy="0 0 3.1415" xyz="0 0 0"/>
    </collision>
    <inertial>
      <origin rpy="0 0 3.1415" xyz="0 0 0"/>
      <mass value="0.003"/>
      <inertia ixx="0.0001" ixy="0" ixz="0" iyy="0.0001" iyz="0" izz="0.0001"/>
    </inertial>
  </link>
  <link name="left_ring3">
    <visual>
      <geometry>
        <mesh filename="package://inmoov_description/meshes/ring3_3.stl" scale="0.001 0.001 0.001"/>
      </geometry>
      <origin rpy="0 0 3.1415" xyz="0 0 0"/>
      <material name="cframe">
        <color rgba="0.25 0.25 0.25 1"/>
      </material>
    </visual>
    <collision>
      <geometry>
        <mesh filename="package://inmoov_description/meshes/ring3_3.stl" scale="0.001 0.001 0.001"/>
      </geometry>
      <origin rpy="0 0 3.1415" xyz="0 0 0"/>
    </collision>
    <inertial>
      <origin rpy="0 0 3.1415" xyz="0 0 0"/>
      <mass value="0.003"/>
      <inertia ixx="0.0001" ixy="0" ixz="0" iyy="0.0001" iyz="0" izz="0.0001"/>
    </inertial>
  </link>
  <link name="left_ring4">
    <visual>
      <geometry>
        <mesh filename="package://inmoov_description/meshes/ring3_4.stl" scale="0.001 0.001 0.001"/>
      </geometry>
      <origin rpy="0 0 3.1415" xyz="0 0 0"/>
      <material name="cframe">
        <color rgba="0.25 0.25 0.25 1"/>
      </material>
    </visual>
    <collision>
      <geometry>
        <mesh filename="package://inmoov_description/meshes/ring3_4.stl" scale="0.001 0.001 0.001"/>
      </geometry>
      <origin rpy="0 0 3.1415" xyz="0 0 0"/>
    </collision>
    <inertial>
      <origin rpy="0 0 3.1415" xyz="0 0 0"/>
      <mass value="0.003"/>
      <inertia ixx="0.0001" ixy="0" ixz="0" iyy="0.0001" iyz="0" izz="0.0001"/>
    </inertial>
  </link>
  <link name="left_pinky1">
    <visual>
      <geometry>
        <mesh filename="package://inmoov_description/meshes/left_pinky3_1.stl" scale="0.001 0.001 0.001"/>
      </geometry>
      <origin rpy="0 0 3.1415" xyz="0 0 0"/>
      <material name="cframe">
        <color rgba="0.25 0.25 0.25 1"/>
      </material>
    </visual>
    <collision>
      <geometry>
        <mesh filename="package://inmoov_description/meshes/left_pinky3_1.stl" scale="0.001 0.001 0.001"/>
      </geometry>
      <origin rpy="0 0 3.1415" xyz="0 0 0"/>
    </collision>
    <inertial>
      <origin rpy="0 0 3.1415" xyz="0 0 0"/>
      <mass value="0.003"/>
      <inertia ixx="0.0001" ixy="0" ixz="0" iyy="0.0001" iyz="0" izz="0.0001"/>
    </inertial>
  </link>
  <link name="left_pinky2">
    <visual>
      <geometry>
        <mesh filename="package://inmoov_description/meshes/pinky3_2.stl" scale="0.001 0.001 0.001"/>
      </geometry>
      <origin rpy="0 0 3.1415" xyz="0 0 0"/>
      <material name="cframe">
        <color rgba="0.25 0.25 0.25 1"/>
      </material>
    </visual>
    <collision>
      <geometry>
        <mesh filename="package://inmoov_description/meshes/pinky3_2.stl" scale="0.001 0.001 0.001"/>
      </geometry>
      <origin rpy="0 0 3.1415" xyz="0 0 0"/>
    </collision>
    <inertial>
      <origin rpy="0 0 3.1415" xyz="0 0 0"/>
      <mass value="0.003"/>
      <inertia ixx="0.0001" ixy="0" ixz="0" iyy="0.0001" iyz="0" izz="0.0001"/>
    </inertial>
  </link>
  <link name="left_pinky3">
    <visual>
      <geometry>
        <mesh filename="package://inmoov_description/meshes/pinky3_3.stl" scale="0.001 0.001 0.001"/>
      </geometry>
      <origin rpy="0 0 3.1415" xyz="0 0 0"/>
      <material name="cframe">
        <color rgba="0.25 0.25 0.25 1"/>
      </material>
    </visual>
    <collision>
      <geometry>
        <mesh filename="package://inmoov_description/meshes/pinky3_3.stl" scale="0.001 0.001 0.001"/>
      </geometry>
      <origin rpy="0 0 3.1415" xyz="0 0 0"/>
    </collision>
    <inertial>
      <origin rpy="0 0 3.1415" xyz="0 0 0"/>
      <mass value="0.003"/>
      <inertia ixx="0.0001" ixy="0" ixz="0" iyy="0.0001" iyz="0" izz="0.0001"/>
    </inertial>
  </link>
  <link name="left_pinky4">
    <visual>
      <geometry>
        <mesh filename="package://inmoov_description/meshes/pinky3_4.stl" scale="0.001 0.001 0.001"/>
      </geometry>
      <origin rpy="0 0 3.1415" xyz="0 0 0"/>
      <material name="cframe">
        <color rgba="0.25 0.25 0.25 1"/>
      </material>
    </visual>
    <collision>
      <geometry>
        <mesh filename="package://inmoov_description/meshes/pinky3_4.stl" scale="0.001 0.001 0.001"/>
      </geometry>
      <origin rpy="0 0 3.1415" xyz="0 0 0"/>
    </collision>
    <inertial>
      <origin rpy="0 0 3.1415" xyz="0 0 0"/>
      <mass value="0.003"/>
      <inertia ixx="0.0001" ixy="0" ixz="0" iyy="0.0001" iyz="0" izz="0.0001"/>
    </inertial>
  </link>
  <joint name="left_thumb1" type="revolute">
    <axis xyz="0 0 1"/>
    <limit effort="1000.0" lower="0" upper="-1.57" velocity="0.5"/>
    <origin rpy="3.1415 -0.1 0" xyz="0.029 0 -0.0577"/>
    <mimic joint="left_thumb" multiplier="0.75" offset="0"/>
    <parent link="left_hand"/>
    <child link="left_thumb1"/>
  </joint>
  <joint name="left_thumb" type="revolute">
    <axis xyz="1 0 0"/>
    <limit effort="1000.0" lower="0" upper="1.5" velocity="0.5"/>
    <origin rpy="0 -2.3 0.3" xyz="0.02725 -0.0006 0.014"/>
    <parent link="left_thumb1"/>
    <child link="left_thumb2"/>
    <dynamics damping="0.7"/>
  </joint>
  <joint name="left_thumb3" type="revolute">
    <axis xyz="1 0 0"/>
    <limit effort="1000.0" lower="-1.57" upper="0" velocity="0.5"/>
    <origin rpy="0 0 0" xyz="0 0 -0.035"/>
    <mimic joint="left_thumb" multiplier="1" offset="0"/>
    <parent link="left_thumb2"/>
    <child link="left_thumb3"/>
  </joint>
  <joint name="left_index1" type="revolute">
    <axis xyz="1 0 0"/>
    <limit effort="1000.0" lower="0" upper="1.5" velocity="0.5"/>
    <origin rpy="0 0.1 3.1415" xyz="0.0342 -0.0015 -0.119"/>
    <mimic joint="left_index" multiplier="1" offset="0"/>
    <parent link="left_hand"/>
    <child link="left_index1"/>
  </joint>
  <joint name="left_index" type="revolute">
    <axis xyz="1 0 0"/>
    <limit effort="1000.0" lower="0" upper="1.5" velocity="0.5"/>
    <origin rpy="0 0 0" xyz="0 0.001 -0.03595"/>
    <parent link="left_index1"/>
    <child link="left_index2"/>
    <dynamics damping="0.7"/>
  </joint>
  <joint name="left_index3" type="revolute">
    <axis xyz="1 0 0"/>
    <limit effort="1000.0" lower="0" upper="1.5" velocity="0.5"/>
    <origin rpy="0 0 0" xyz="0 0 -0.024"/>
    <mimic joint="left_index" multiplier="1" offset="0"/>
    <parent link="left_index2"/>
    <child link="left_index3"/>
  </joint>
  <joint name="left_middle1" type="revolute">
    <axis xyz="1 0 0"/>
    <limit effort="1000.0" lower="0" upper="1.5" velocity="0.5"/>
    <origin rpy="0 0 3.1415" xyz="0.007 -0.00175 -0.12325"/>
    <mimic joint="left_middle" multiplier="1" offset="0"/>
    <parent link="left_hand"/>
    <child link="left_middle1"/>
  </joint>
  <joint name="left_middle" type="revolute">
    <axis xyz="1 0 0"/>
    <limit effort="1000.0" lower="0" upper="1.5" velocity="0.5"/>
    <origin rpy="0 0 0" xyz="0 0.000 -0.0389"/>
    <parent link="left_middle1"/>
    <child link="left_middle2"/>
    <dynamics damping="0.7"/>
  </joint>
  <joint name="left_middle3" type="revolute">
    <axis xyz="1 0 0"/>
    <limit effort="1000.0" lower="-1.57" upper="0" velocity="0.5"/>
    <origin rpy="0 0 0" xyz="0 0.0005 -0.0259"/>
    <mimic joint="left_middle" multiplier="1" offset="0"/>
    <parent link="left_middle2"/>
    <child link="left_middle3"/>
  </joint>
  <joint name="left_ring1" type="revolute">
    <axis xyz="0 0 1"/>
    <limit effort="1000.0" lower="1.57" upper="0" velocity="0.5"/>
    <origin rpy="0 0.7 3.1415" xyz="-0.00705 0 -0.0794"/>
    <mimic joint="left_ring" multiplier="0.1" offset="0"/>
    <parent link="left_hand"/>
    <child link="left_ring1"/>
  </joint>
  <joint name="left_ring" type="revolute">
    <axis xyz="1 0 0"/>
    <limit effort="1000.0" lower="0" upper="1.5" velocity="0.5"/>
    <origin rpy="0 -0.7775 0" xyz="0.0351 0.00126 -0.0166"/>
    <parent link="left_ring1"/>
    <child link="left_ring2"/>
    <dynamics damping="0.7"/>
  </joint>
  <joint name="left_ring3" type="revolute">
    <axis xyz="1 0 0"/>
    <limit effort="1000.0" lower="-1.57" upper="0" velocity="0.5"/>
    <origin rpy="0 0 0" xyz="0 0.0005 -0.0345"/>
    <mimic joint="left_ring" multiplier="1" offset="0"/>
    <parent link="left_ring2"/>
    <child link="left_ring3"/>
  </joint>
  <joint name="left_ring4" type="revolute">
    <axis xyz="1 0 0"/>
    <limit effort="1000.0" lower="-1.57" upper="0" velocity="0.5"/>
    <origin rpy="0 0 0" xyz="0 0.0004 -0.0229"/>
    <mimic joint="left_ring" multiplier="1" offset="0"/>
    <parent link="left_ring3"/>
    <child link="left_ring4"/>
  </joint>
  <joint name="left_pinky1" type="revolute">
    <axis xyz="0 0 1"/>
    <limit effort="1000.0" lower="1.57" upper="0" velocity="0.5"/>
    <origin rpy="0 0.7 3.1415" xyz="-0.027 0 -0.0555"/>
    <mimic joint="left_pinky" multiplier="0.1" offset="0"/>
    <parent link="left_hand"/>
    <child link="left_pinky1"/>
  </joint>
  <joint name="left_pinky" type="revolute">
    <axis xyz="1 0 0"/>
    <limit effort="1000.0" lower="0" upper="1.5" velocity="0.5"/>
    <origin rpy="0 -0.93 0" xyz="0.046 -0 -0.0228"/>
    <parent link="left_pinky1"/>
    <child link="left_pinky2"/>
    <dynamics damping="0.7"/>
  </joint>
  <joint name="left_pinky3" type="revolute">
    <axis xyz="1 0 0"/>
    <limit effort="1000.0" lower="-1.57" upper="0" velocity="0.5"/>
    <origin rpy="0 0 0" xyz="0 0.0005 -0.031"/>
    <mimic joint="left_pinky" multiplier="1" offset="0"/>
    <parent link="left_pinky2"/>
    <child link="left_pinky3"/>
  </joint>
  <joint name="left_pinky4" type="revolute">
    <axis xyz="1 0 0"/>
    <limit effort="1000.0" lower="-1.57" upper="0" velocity="0.5"/>
    <origin rpy="0 0 0" xyz="0 0.0004 -0.0208"/>
    <mimic joint="left_pinky" multiplier="1" offset="0"/>
    <parent link="left_pinky3"/>
    <child link="left_pinky4"/>
  </joint>
  <link name="left_handcover">
    <visual>
      <geometry>
        <mesh filename="package://inmoov_description/meshes/left_cover_hand.stl" scale="0.001 0.001 0.001"/>
      </geometry>
      <origin rpy="0 0 0" xyz="0 0 0"/>
      <material name="ccover">
        <color rgba="0.6 0.6 0.6 1"/>
      </material>
    </visual>
    <collision>
      <geometry>
        <mesh filename="package://inmoov_description/meshes/left_cover_hand.stl" scale="0.001 0.001 0.001"/>
      </geometry>
      <origin rpy="0 0 0" xyz="0 0 0"/>
    </collision>
    <inertial>
      <origin rpy="0 0 0" xyz="0 0 0"/>
      <mass value="0.023"/>
      <inertia ixx="0.0001" ixy="0" ixz="0" iyy="0.0003" iyz="0" izz="0.0001"/>
    </inertial>
  </link>
  <link name="left_cover_handring">
    <visual>
      <geometry>
        <mesh filename="package://inmoov_description/meshes/left_cover_handring.stl" scale="0.001 0.001 0.001"/>
      </geometry>
      <origin rpy="0 0 3.1415" xyz="0 0 0"/>
      <material name="ccover">
        <color rgba="0.6 0.6 0.6 1"/>
      </material>
    </visual>
    <collision>
      <geometry>
        <mesh filename="package://inmoov_description/meshes/left_cover_handring.stl" scale="0.001 0.001 0.001"/>
      </geometry>
      <origin rpy="0 0 3.1415" xyz="0 0 0"/>
    </collision>
    <inertial>
      <origin rpy="0 0 3.1415" xyz="0 0 0"/>
      <mass value="0.002"/>
      <inertia ixx="0.0001" ixy="0" ixz="0" iyy="0.0001" iyz="0" izz="0.0001"/>
    </inertial>
  </link>
  <link name="left_cover_handpinky">
    <visual>
      <geometry>
        <mesh filename="package://inmoov_description/meshes/left_cover_handpinky.stl" scale="0.001 0.001 0.001"/>
      </geometry>
      <origin rpy="0 0 3.1415" xyz="0 0 0"/>
      <material name="ccover">
        <color rgba="0.6 0.6 0.6 1"/>
      </material>
    </visual>
    <collision>
      <geometry>
        <mesh filename="package://inmoov_description/meshes/left_cover_handpinky.stl" scale="0.001 0.001 0.001"/>
      </geometry>
      <origin rpy="0 0 3.1415" xyz="0 0 0"/>
    </collision>
    <inertial>
      <origin rpy="0 0 3.1415" xyz="0 0 0"/>
      <mass value="0.002"/>
      <inertia ixx="0.0001" ixy="0" ixz="0" iyy="0.0001" iyz="0" izz="0.0001"/>
    </inertial>
  </link>
  <link name="left_cover_thumb">
    <visual>
      <geometry>
        <mesh filename="package://inmoov_description/meshes/left_cover_thumb.stl" scale="0.001 0.001 0.001"/>
      </geometry>
      <origin rpy="3.1415 0 0" xyz="0 0 0"/>
      <material name="ccover">
        <color rgba="0.6 0.6 0.6 1"/>
      </material>
    </visual>
    <collision>
      <geometry>
        <mesh filename="package://inmoov_description/meshes/left_cover_thumb.stl" scale="0.001 0.001 0.001"/>
      </geometry>
      <origin rpy="0 0 3.1415" xyz="0 0 0"/>
    </collision>
    <inertial>
      <origin rpy="0 0 3.1415" xyz="0 0 0"/>
      <mass value="0.002"/>
      <inertia ixx="0.0001" ixy="0" ixz="0" iyy="0.0001" iyz="0" izz="0.0001"/>
    </inertial>
  </link>
  <link name="left_cover_index">
    <visual>
      <geometry>
        <mesh filename="package://inmoov_description/meshes/left_cover_index.stl" scale="0.001 0.001 0.001"/>
      </geometry>
      <origin rpy="0 0 3.1415" xyz="0 0 0"/>
      <material name="ccover">
        <color rgba="0.6 0.6 0.6 1"/>
      </material>
    </visual>
    <collision>
      <geometry>
        <mesh filename="package://inmoov_description/meshes/left_cover_index.stl" scale="0.001 0.001 0.001"/>
      </geometry>
      <origin rpy="0 0 3.1415" xyz="0 0 0"/>
    </collision>
    <inertial>
      <origin rpy="0 0 3.1415" xyz="0 0 0"/>
      <mass value="0.002"/>
      <inertia ixx="0.0001" ixy="0" ixz="0" iyy="0.0001" iyz="0" izz="0.0001"/>
    </inertial>
  </link>
  <link name="left_cover_middle">
    <visual>
      <geometry>
        <mesh filename="package://inmoov_description/meshes/left_cover_middle.stl" scale="0.001 0.001 0.001"/>
      </geometry>
      <origin rpy="0 0 3.1415" xyz="0 0 0"/>
      <material name="ccover">
        <color rgba="0.6 0.6 0.6 1"/>
      </material>
    </visual>
    <collision>
      <geometry>
        <mesh filename="package://inmoov_description/meshes/left_cover_middle.stl" scale="0.001 0.001 0.001"/>
      </geometry>
      <origin rpy="0 0 3.1415" xyz="0 0 0"/>
    </collision>
    <inertial>
      <origin rpy="0 0 3.1415" xyz="0 0 0"/>
      <mass value="0.002"/>
      <inertia ixx="0.0001" ixy="0" ixz="0" iyy="0.0001" iyz="0" izz="0.0001"/>
    </inertial>
  </link>
  <link name="left_cover_ring">
    <visual>
      <geometry>
        <mesh filename="package://inmoov_description/meshes/left_cover_ring.stl" scale="0.001 0.001 0.001"/>
      </geometry>
      <origin rpy="0 0 3.1415" xyz="0 0 0"/>
      <material name="ccover">
        <color rgba="0.6 0.6 0.6 1"/>
      </material>
    </visual>
    <collision>
      <geometry>
        <mesh filename="package://inmoov_description/meshes/left_cover_ring.stl" scale="0.001 0.001 0.001"/>
      </geometry>
      <origin rpy="0 0 3.1415" xyz="0 0 0"/>
    </collision>
    <inertial>
      <origin rpy="0 0 3.1415" xyz="0 0 0"/>
      <mass value="0.002"/>
      <inertia ixx="0.0001" ixy="0" ixz="0" iyy="0.0001" iyz="0" izz="0.0001"/>
    </inertial>
  </link>
  <link name="left_cover_pinky">
    <visual>
      <geometry>
        <mesh filename="package://inmoov_description/meshes/left_cover_pinky.stl" scale="0.001 0.001 0.001"/>
      </geometry>
      <origin rpy="0 0 3.1415" xyz="0 0 0"/>
      <material name="ccover">
        <color rgba="0.6 0.6 0.6 1"/>
      </material>
    </visual>
    <collision>
      <geometry>
        <mesh filename="package://inmoov_description/meshes/left_cover_pinky.stl" scale="0.001 0.001 0.001"/>
      </geometry>
      <origin rpy="0 0 3.1415" xyz="0 0 0"/>
    </collision>
    <inertial>
      <origin rpy="0 0 3.1415" xyz="0 0 0"/>
      <mass value="0.002"/>
      <inertia ixx="0.0001" ixy="0" ixz="0" iyy="0.0001" iyz="0" izz="0.0001"/>
    </inertial>
  </link>
  <joint name="left_handcover" type="fixed">
    <origin rpy="0 0 0" xyz="0.0192 0.009 -0.0977"/>
    <parent link="left_hand"/>
    <child link="left_handcover"/>
  </joint>
  <joint name="left_cover_handring" type="fixed">
    <origin rpy="0 -0.7 0" xyz="0.015 -0.009 -0.0008"/>
    <parent link="left_ring1"/>
    <child link="left_cover_handring"/>
  </joint>
  <joint name="left_cover_handpinky" type="fixed">
    <origin rpy="0 -0.7 0" xyz="0.0205 -0.01 -0.0069"/>
    <parent link="left_pinky1"/>
    <child link="left_cover_handpinky"/>
  </joint>
  <joint name="left_cover_thumb" type="fixed">
    <origin rpy="0 -3.1 0" xyz="0.02125 -0.01 -0.0047"/>
    <parent link="left_thumb1"/>
    <child link="left_cover_thumb"/>
  </joint>
  <joint name="left_cover_index" type="fixed">
    <origin rpy="-0.05 0 0" xyz="0 -0.0071 -0.012"/>
    <parent link="left_index1"/>
    <child link="left_cover_index"/>
  </joint>
  <joint name="left_cover_middle" type="fixed">
    <origin rpy="0.05 0 0" xyz="0 -0.0071 -0.012"/>
    <parent link="left_middle1"/>
    <child link="left_cover_middle"/>
  </joint>
  <joint name="left_cover_ring" type="fixed">
    <origin rpy="0.05 0.1 0" xyz="0 -0.005 -0.011"/>
    <parent link="left_ring2"/>
    <child link="left_cover_ring"/>
  </joint>
  <joint name="left_cover_pinky" type="fixed">
    <origin rpy="0.05 0.1 0" xyz="0 -0.005 -0.0105"/>
    <parent link="left_pinky2"/>
    <child link="left_cover_pinky"/>
  </joint>
  <joint name="left_hand" type="revolute">
    <axis xyz="0 0 1"/>
    <limit effort="1000.0" lower="0" upper="3.14" velocity="0.5"/>
    <origin rpy="0 0 0" xyz="0.01 -0.0144 -0.2885"/>
    <parent link="left_forearm"/>
    <child link="left_hand"/>
    <dynamics damping="0.7"/>
  </joint>
  <!--HEAD MOUNTED CAMERAS (STEREO)-->
  <gazebo reference="left_camera">
    <sensor name="stereo_camera" type="multicamera">
      <update_rate>30.0</update_rate>
      <camera name="left">
        <horizontal_fov>1.3962634</horizontal_fov>
        <image>
          <width>1280</width>
          <height>720</height>
          <format>R8G8B8</format>
        </image>
        <clip>
          <near>0.02</near>
          <far>300</far>
        </clip>
        <noise>
          <type>gaussian</type>
          <mean>0.0</mean>
          <stddev>0.007</stddev>
        </noise>
      </camera>
      <camera name="right">
        <pose>0 -0.07 0 0 0 0</pose>
        <horizontal_fov>1.3962634</horizontal_fov>
        <image>
          <width>1280</width>
          <height>720</height>
          <format>R8G8B8</format>
        </image>
        <clip>
          <near>0.02</near>
          <far>300</far>
        </clip>
        <noise>
          <type>gaussian</type>
          <mean>0.0</mean>
          <stddev>0.007</stddev>
        </noise>
      </camera>
      <plugin filename="libgazebo_ros_multicamera.so" name="stereo_camera_controller">
        <alwaysOn>true</alwaysOn>
        <updateRate>0.0</updateRate>
        <cameraName>inmoov/stereocamera</cameraName>
        <imageTopicName>image_raw</imageTopicName>
        <cameraInfoTopicName>camera_info</cameraInfoTopicName>
        <frameName>left_camera</frameName>
        <!--<rightFrameName>right_camera</rightFrameName>-->
        <hackBaseline>0.07</hackBaseline>
        <distortionK1>0.0</distortionK1>
        <distortionK2>0.0</distortionK2>
        <distortionK3>0.0</distortionK3>
        <distortionT1>0.0</distortionT1>
        <distortionT2>0.0</distortionT2>
      </plugin>
    </sensor>
  </gazebo>
  <!--KINECT-->
  <!--gazebo_ros_wge100 plugin is in kt2_gazebo_plugins package -->
  <!--gazebo reference="kinect">
  <sensor type="camera" name="camera">
    <camera name="kinetc_ir">
      <horizontal_fov>60</horizontal_fov>
      <image>
        <width>640</width>
        <height>480</height>
        <format>R8G8B8</format>
      </image>
      <clip>
        <near>0.05</near>
        <far>3</far>
      </clip>
    </camera>
    <plugin name="kinect_camera_controller" filename="libgazebo_ros_openni_kinect.so">
      <alwaysOn>true</alwaysOn>
      <updateRate>20</updateRate>
      <imageTopicName>/kinect_ir/image_raw</imageTopicName>
      <pointCloudTopicName>/kinect_ir/depth/points</pointCloudTopicName>
      <cameraInfoTopicName>/kinect_ir/camera_info</cameraInfoTopicName>
      <frameName>kinect_frame</frameName>
      <distortion_k1>0.0</distortion_k1>
      <distortion_k2>0.0</distortion_k2>
      <distortion_k3>0.0</distortion_k3>
      <distortion_t1>0.0</distortion_t1>
      <distortion_t2>0.0</distortion_t2>
    </plugin>
  </sensor>
</gazebo-->
  <!--TOUCH SENSORS-->
  <!--PIR SENSOR-->
  <!--GAZEBO_ROS_CONTROL PLUGIN-->
  <gazebo>
    <plugin filename="libgazebo_ros_control.so" name="gazebo_ros_control">
      <robotNamespace>/inmoov</robotNamespace>
    </plugin>
  </gazebo>
  <!--TRANSMISSION PLUGINS-->
  <!--Head & Face-->
  <transmission name="head_tran1">
    <type>transmission_interface/SimpleTransmission</type>
    <joint name="head_tilt">
      <hardwareInterface>EffortJointInterface</hardwareInterface>
    </joint>
    <actuator name="headmotor1">
      <hardwareInterface>EffortJointInterface</hardwareInterface>
      <mechanicalReduction>1</mechanicalReduction>
    </actuator>
  </transmission>
  <transmission name="head_tran2">
    <type>transmission_interface/SimpleTransmission</type>
    <joint name="head_updown">
      <hardwareInterface>EffortJointInterface</hardwareInterface>
    </joint>
    <actuator name="headmotor2">
      <hardwareInterface>EffortJointInterface</hardwareInterface>
      <mechanicalReduction>1</mechanicalReduction>
    </actuator>
  </transmission>
  <transmission name="head_tran3">
    <type>transmission_interface/SimpleTransmission</type>
    <joint name="head_leftright">
      <hardwareInterface>EffortJointInterface</hardwareInterface>
    </joint>
    <actuator name="headmotor3">
      <hardwareInterface>EffortJointInterface</hardwareInterface>
      <mechanicalReduction>1</mechanicalReduction>
    </actuator>
  </transmission>
  <transmission name="jaw_tran">
    <type>transmission_interface/SimpleTransmission</type>
    <joint name="jaw">
      <hardwareInterface>EffortJointInterface</hardwareInterface>
    </joint>
    <actuator name="jawmotor">
      <hardwareInterface>EffortJointInterface</hardwareInterface>
      <mechanicalReduction>1</mechanicalReduction>
    </actuator>
  </transmission>
  <transmission name="eye_tran1">
    <type>transmission_interface/SimpleTransmission</type>
    <joint name="eyes_updown">
      <hardwareInterface>EffortJointInterface</hardwareInterface>
    </joint>
    <actuator name="eyemotor1">
      <hardwareInterface>EffortJointInterface</hardwareInterface>
      <mechanicalReduction>1</mechanicalReduction>
    </actuator>
  </transmission>
  <transmission name="eye_tran2">
    <type>transmission_interface/SimpleTransmission</type>
    <joint name="eye_leftright">
      <hardwareInterface>EffortJointInterface</hardwareInterface>
    </joint>
    <actuator name="eyemotor2">
      <hardwareInterface>EffortJointInterface</hardwareInterface>
      <mechanicalReduction>1</mechanicalReduction>
    </actuator>
  </transmission>
  <!--Torso-->
  <transmission name="waist_tran1">
    <type>transmission_interface/SimpleTransmission</type>
    <joint name="waist_rotate">
      <hardwareInterface>EffortJointInterface</hardwareInterface>
    </joint>
    <actuator name="waistmotor1">
      <hardwareInterface>EffortJointInterface</hardwareInterface>
      <mechanicalReduction>1</mechanicalReduction>
    </actuator>
  </transmission>
  <transmission name="waist_tran2">
    <type>transmission_interface/SimpleTransmission</type>
    <joint name="waist_lean">
      <hardwareInterface>EffortJointInterface</hardwareInterface>
    </joint>
    <actuator name="waistmotor2">
      <hardwareInterface>EffortJointInterface</hardwareInterface>
      <mechanicalReduction>1</mechanicalReduction>
    </actuator>
  </transmission>
  <!--Right Arm-->
  <transmission name="rshoulder_tran1">
    <type>transmission_interface/SimpleTransmission</type>
    <joint name="right_shoulder_side">
      <hardwareInterface>EffortJointInterface</hardwareInterface>
    </joint>
    <actuator name="rshouldermotor1">
      <hardwareInterface>EffortJointInterface</hardwareInterface>
      <mechanicalReduction>1</mechanicalReduction>
    </actuator>
  </transmission>
  <transmission name="rshoulder_tran2">
    <type>transmission_interface/SimpleTransmission</type>
    <joint name="right_shoulder_up">
      <hardwareInterface>EffortJointInterface</hardwareInterface>
    </joint>
    <actuator name="rshouldermotor2">
      <hardwareInterface>EffortJointInterface</hardwareInterface>
      <mechanicalReduction>1</mechanicalReduction>
    </actuator>
  </transmission>
  <transmission name="rbicep_tran1">
    <type>transmission_interface/SimpleTransmission</type>
    <joint name="right_bicep_rotate">
      <hardwareInterface>EffortJointInterface</hardwareInterface>
    </joint>
    <actuator name="rbicepmotor1">
      <hardwareInterface>EffortJointInterface</hardwareInterface>
      <mechanicalReduction>1</mechanicalReduction>
    </actuator>
  </transmission>
  <transmission name="rbicep_tran2">
    <type>transmission_interface/SimpleTransmission</type>
    <joint name="right_bicep">
      <hardwareInterface>EffortJointInterface</hardwareInterface>
    </joint>
    <actuator name="rbicepmotor2">
      <hardwareInterface>EffortJointInterface</hardwareInterface>
      <mechanicalReduction>1</mechanicalReduction>
    </actuator>
  </transmission>
  <!--Left Arm-->
  <transmission name="lshoulder_tran1">
    <type>transmission_interface/SimpleTransmission</type>
    <joint name="left_shoulder_side">
      <hardwareInterface>EffortJointInterface</hardwareInterface>
    </joint>
    <actuator name="lshouldermotor1">
      <hardwareInterface>EffortJointInterface</hardwareInterface>
      <mechanicalReduction>1</mechanicalReduction>
    </actuator>
  </transmission>
  <transmission name="lshoulder_tran2">
    <type>transmission_interface/SimpleTransmission</type>
    <joint name="left_shoulder_up">
      <hardwareInterface>EffortJointInterface</hardwareInterface>
    </joint>
    <actuator name="lshouldermotor2">
      <hardwareInterface>EffortJointInterface</hardwareInterface>
      <mechanicalReduction>1</mechanicalReduction>
    </actuator>
  </transmission>
  <transmission name="lbicep_tran1">
    <type>transmission_interface/SimpleTransmission</type>
    <joint name="left_bicep_rotate">
      <hardwareInterface>EffortJointInterface</hardwareInterface>
    </joint>
    <actuator name="lbicepmotor1">
      <hardwareInterface>EffortJointInterface</hardwareInterface>
      <mechanicalReduction>1</mechanicalReduction>
    </actuator>
  </transmission>
  <transmission name="lbicep_tran2">
    <type>transmission_interface/SimpleTransmission</type>
    <joint name="left_bicep">
      <hardwareInterface>EffortJointInterface</hardwareInterface>
    </joint>
    <actuator name="lbicepmotor2">
      <hardwareInterface>EffortJointInterface</hardwareInterface>
      <mechanicalReduction>1</mechanicalReduction>
    </actuator>
  </transmission>
  <!--Right Hand-->
  <transmission name="rthumb_tran">
    <type>transmission_interface/SimpleTransmission</type>
    <joint name="right_thumb">
      <hardwareInterface>EffortJointInterface</hardwareInterface>
    </joint>
    <actuator name="rthumbmotor">
      <hardwareInterface>EffortJointInterface</hardwareInterface>
      <mechanicalReduction>1</mechanicalReduction>
    </actuator>
  </transmission>
  <transmission name="rindex_tran">
    <type>transmission_interface/SimpleTransmission</type>
    <joint name="right_index">
      <hardwareInterface>EffortJointInterface</hardwareInterface>
    </joint>
    <actuator name="rindexmotor">
      <hardwareInterface>EffortJointInterface</hardwareInterface>
      <mechanicalReduction>1</mechanicalReduction>
    </actuator>
  </transmission>
  <transmission name="rmiddle_tran">
    <type>transmission_interface/SimpleTransmission</type>
    <joint name="right_middle">
      <hardwareInterface>EffortJointInterface</hardwareInterface>
    </joint>
    <actuator name="rmiddlemotor">
      <hardwareInterface>EffortJointInterface</hardwareInterface>
      <mechanicalReduction>1</mechanicalReduction>
    </actuator>
  </transmission>
  <transmission name="rring_tran">
    <type>transmission_interface/SimpleTransmission</type>
    <joint name="right_ring">
      <hardwareInterface>EffortJointInterface</hardwareInterface>
    </joint>
    <actuator name="rringmotor">
      <hardwareInterface>EffortJointInterface</hardwareInterface>
      <mechanicalReduction>1</mechanicalReduction>
    </actuator>
  </transmission>
  <transmission name="rpinky_tran">
    <type>transmission_interface/SimpleTransmission</type>
    <joint name="right_pinky">
      <hardwareInterface>EffortJointInterface</hardwareInterface>
    </joint>
    <actuator name="rpinkymotor">
      <hardwareInterface>EffortJointInterface</hardwareInterface>
      <mechanicalReduction>1</mechanicalReduction>
    </actuator>
  </transmission>
  <transmission name="rwrist_tran">
    <type>transmission_interface/SimpleTransmission</type>
    <joint name="right_hand">
      <hardwareInterface>EffortJointInterface</hardwareInterface>
    </joint>
    <actuator name="rwristmotor">
      <hardwareInterface>EffortJointInterface</hardwareInterface>
      <mechanicalReduction>1</mechanicalReduction>
    </actuator>
  </transmission>
  <!--Left Hand-->
  <transmission name="lthumb_tran">
    <type>transmission_interface/SimpleTransmission</type>
    <joint name="left_thumb">
      <hardwareInterface>EffortJointInterface</hardwareInterface>
    </joint>
    <actuator name="lthumbmotor">
      <hardwareInterface>EffortJointInterface</hardwareInterface>
      <mechanicalReduction>1</mechanicalReduction>
    </actuator>
  </transmission>
  <transmission name="lindex_tran">
    <type>transmission_interface/SimpleTransmission</type>
    <joint name="left_index">
      <hardwareInterface>EffortJointInterface</hardwareInterface>
    </joint>
    <actuator name="lindexmotor">
      <hardwareInterface>EffortJointInterface</hardwareInterface>
      <mechanicalReduction>1</mechanicalReduction>
    </actuator>
  </transmission>
  <transmission name="lmiddle_tran">
    <type>transmission_interface/SimpleTransmission</type>
    <joint name="left_middle">
      <hardwareInterface>EffortJointInterface</hardwareInterface>
    </joint>
    <actuator name="lmiddlemotor">
      <hardwareInterface>EffortJointInterface</hardwareInterface>
      <mechanicalReduction>1</mechanicalReduction>
    </actuator>
  </transmission>
  <transmission name="lring_tran">
    <type>transmission_interface/SimpleTransmission</type>
    <joint name="left_ring">
      <hardwareInterface>EffortJointInterface</hardwareInterface>
    </joint>
    <actuator name="lringmotor">
      <hardwareInterface>EffortJointInterface</hardwareInterface>
      <mechanicalReduction>1</mechanicalReduction>
    </actuator>
  </transmission>
  <transmission name="lpinky_tran">
    <type>transmission_interface/SimpleTransmission</type>
    <joint name="left_pinky">
      <hardwareInterface>EffortJointInterface</hardwareInterface>
    </joint>
    <actuator name="lpinkymotor">
      <hardwareInterface>EffortJointInterface</hardwareInterface>
      <mechanicalReduction>1</mechanicalReduction>
    </actuator>
  </transmission>
  <transmission name="lwrist_tran">
    <type>transmission_interface/SimpleTransmission</type>
    <joint name="left_hand">
      <hardwareInterface>EffortJointInterface</hardwareInterface>
    </joint>
    <actuator name="lwristmotor">
      <hardwareInterface>EffortJointInterface</hardwareInterface>
      <mechanicalReduction>1</mechanicalReduction>
    </actuator>
  </transmission>
  <!--GENERAL-->
  <gazebo reference="base_link">
    <mu1>0.3</mu1>
    <mu2>0.3</mu2>
    <material>Gazebo/Black</material>
  </gazebo>
  <gazebo reference="pedestal">
    <mu1>0.3</mu1>
    <mu2>0.3</mu2>
    <material>Gazebo/Black</material>
  </gazebo>
  <gazebo reference="head_tilt">
    <mu1>0.3</mu1>
    <mu2>0.3</mu2>
    <material>Gazebo/DarkGrey</material>
  </gazebo>
  <!--TORSO-->
  <gazebo reference="mid_stomach">
    <mu1>0.3</mu1>
    <mu2>0.3</mu2>
    <material>Gazebo/DarkGrey</material>
  </gazebo>
  <gazebo reference="disk">
    <mu1>0.3</mu1>
    <mu2>0.3</mu2>
    <material>Gazebo/Grey</material>
  </gazebo>
  <gazebo reference="top_stomach">
    <mu1>0.3</mu1>
    <mu2>0.3</mu2>
    <material>Gazebo/DarkGrey</material>
  </gazebo>
  <gazebo reference="torso">
    <mu1>0.3</mu1>
    <mu2>0.3</mu2>
    <material>Gazebo/DarkGrey</material>
  </gazebo>
  <gazebo reference="kinect">
    <mu1>0.3</mu1>
    <mu2>0.3</mu2>
    <material>Gazebo/Black</material>
  </gazebo>
  <gazebo reference="chestplate">
    <mu1>0.3</mu1>
    <mu2>0.3</mu2>
    <material>Gazebo/Grey</material>
  </gazebo>
  <!--HEAD-->
  <gazebo reference="head_base">
    <mu1>0.3</mu1>
    <mu2>0.3</mu2>
    <material>Gazebo/DarkGrey</material>
  </gazebo>
  <gazebo reference="head">
    <mu1>0.3</mu1>
    <mu2>0.3</mu2>
    <material>Gazebo/DarkGrey</material>
  </gazebo>
  <gazebo reference="jaw">
    <mu1>0.3</mu1>
    <mu2>0.3</mu2>
    <material>Gazebo/Grey</material>
  </gazebo>
  <gazebo reference="skull">
    <mu1>0.3</mu1>
    <mu2>0.3</mu2>
    <material>Gazebo/Grey</material>
  </gazebo>
  <gazebo reference="left_ear">
    <mu1>0.3</mu1>
    <mu2>0.3</mu2>
    <material>Gazebo/DarkGrey</material>
  </gazebo>
  <gazebo reference="right_ear">
    <mu1>0.3</mu1>
    <mu2>0.3</mu2>
    <material>Gazebo/DarkGrey</material>
  </gazebo>
  <!--FACE-->
  <gazebo reference="face">
    <mu1>0.3</mu1>
    <mu2>0.3</mu2>
    <material>Gazebo/Grey</material>
  </gazebo>
  <gazebo reference="eyesupport">
    <mu1>0.3</mu1>
    <mu2>0.3</mu2>
    <material>Gazebo/DarkGrey</material>
  </gazebo>
  <gazebo reference="right_eyesupport">
    <mu1>0.3</mu1>
    <mu2>0.3</mu2>
    <material>Gazebo/DarkGrey</material>
  </gazebo>
  <gazebo reference="right_camera">
    <mu1>0.3</mu1>
    <mu2>0.3</mu2>
    <material>Gazebo/Black</material>
  </gazebo>
  <gazebo reference="right_eye">
    <mu1>0.3</mu1>
    <mu2>0.3</mu2>
    <material>Gazebo/White</material>
  </gazebo>
  <gazebo reference="right_iris">
    <mu1>0.3</mu1>
    <mu2>0.3</mu2>
    <material>Gazebo/Blue</material>
  </gazebo>
  <gazebo reference="left_eyesupport">
    <mu1>0.3</mu1>
    <mu2>0.3</mu2>
    <material>Gazebo/DarkGrey</material>
  </gazebo>
  <gazebo reference="left_camera">
    <mu1>0.3</mu1>
    <mu2>0.3</mu2>
    <material>Gazebo/Black</material>
  </gazebo>
  <gazebo reference="left_eye">
    <mu1>0.3</mu1>
    <mu2>0.3</mu2>
    <material>Gazebo/White</material>
  </gazebo>
  <gazebo reference="left_iris">
    <mu1>0.3</mu1>
    <mu2>0.3</mu2>
    <material>Gazebo/Blue</material>
  </gazebo>
  <!--RIGHT ARM-->
  <gazebo reference="right_shoulder_base">
    <mu1>0.3</mu1>
    <mu2>0.3</mu2>
    <material>Gazebo/DarkGrey</material>
  </gazebo>
  <gazebo reference="right_shoulder">
    <mu1>0.3</mu1>
    <mu2>0.3</mu2>
    <material>Gazebo/DarkGrey</material>
  </gazebo>
  <gazebo reference="right_bicep">
    <mu1>0.3</mu1>
    <mu2>0.3</mu2>
    <material>Gazebo/DarkGrey</material>
  </gazebo>
  <gazebo reference="right_bicepcover">
    <mu1>0.3</mu1>
    <mu2>0.3</mu2>
    <material>Gazebo/Grey</material>
  </gazebo>
  <gazebo reference="right_forarm">
    <mu1>0.3</mu1>
    <mu2>0.3</mu2>
    <material>Gazebo/Grey</material>
  </gazebo>
  <!--LEFT ARM-->
  <gazebo reference="left_shoulder_base">
    <mu1>0.3</mu1>
    <mu2>0.3</mu2>
    <material>Gazebo/DarkGrey</material>
  </gazebo>
  <gazebo reference="left_shoulder">
    <mu1>0.3</mu1>
    <mu2>0.3</mu2>
    <material>Gazebo/DarkGrey</material>
  </gazebo>
  <gazebo reference="left_bicep">
    <mu1>0.3</mu1>
    <mu2>0.3</mu2>
    <material>Gazebo/DarkGrey</material>
  </gazebo>
  <gazebo reference="left_bicepcover">
    <mu1>0.3</mu1>
    <mu2>0.3</mu2>
    <material>Gazebo/Grey</material>
  </gazebo>
  <gazebo reference="left_forarm">
    <mu1>0.3</mu1>
    <mu2>0.3</mu2>
    <material>Gazebo/Grey</material>
  </gazebo>
  <!--RIGHT HAND-->
  <gazebo reference="right_hand">
    <mu1>0.3</mu1>
    <mu2>0.3</mu2>
    <material>Gazebo/DarkGrey</material>
  </gazebo>
  <gazebo reference="right_thumb1">
    <mu1>0.3</mu1>
    <mu2>0.3</mu2>
    <material>Gazebo/DarkGrey</material>
  </gazebo>
  <gazebo reference="right_thumb2">
    <mu1>0.3</mu1>
    <mu2>0.3</mu2>
    <material>Gazebo/DarkGrey</material>
  </gazebo>
  <gazebo reference="right_index1">
    <mu1>0.3</mu1>
    <mu2>0.3</mu2>
    <material>Gazebo/DarkGrey</material>
  </gazebo>
  <gazebo reference="right_index2">
    <mu1>0.3</mu1>
    <mu2>0.3</mu2>
    <material>Gazebo/DarkGrey</material>
  </gazebo>
  <gazebo reference="right_index3">
    <mu1>0.3</mu1>
    <mu2>0.3</mu2>
    <material>Gazebo/DarkGrey</material>
  </gazebo>
  <gazebo reference="right_middle1">
    <mu1>0.3</mu1>
    <mu2>0.3</mu2>
    <material>Gazebo/DarkGrey</material>
  </gazebo>
  <gazebo reference="right_middle2">
    <mu1>0.3</mu1>
    <mu2>0.3</mu2>
    <material>Gazebo/DarkGrey</material>
  </gazebo>
  <gazebo reference="right_middle3">
    <mu1>0.3</mu1>
    <mu2>0.3</mu2>
    <material>Gazebo/DarkGrey</material>
  </gazebo>
  <gazebo reference="right_ring1">
    <mu1>0.3</mu1>
    <mu2>0.3</mu2>
    <material>Gazebo/DarkGrey</material>
  </gazebo>
  <gazebo reference="right_ring2">
    <mu1>0.3</mu1>
    <mu2>0.3</mu2>
    <material>Gazebo/DarkGrey</material>
  </gazebo>
  <gazebo reference="right_ring3">
    <mu1>0.3</mu1>
    <mu2>0.3</mu2>
    <material>Gazebo/DarkGrey</material>
  </gazebo>
  <gazebo reference="right_ring4">
    <mu1>0.3</mu1>
    <mu2>0.3</mu2>
    <material>Gazebo/DarkGrey</material>
  </gazebo>
  <gazebo reference="right_pinky1">
    <mu1>0.3</mu1>
    <mu2>0.3</mu2>
    <material>Gazebo/DarkGrey</material>
  </gazebo>
  <gazebo reference="right_pinky2">
    <mu1>0.3</mu1>
    <mu2>0.3</mu2>
    <material>Gazebo/DarkGrey</material>
  </gazebo>
  <gazebo reference="right_pinky3">
    <mu1>0.3</mu1>
    <mu2>0.3</mu2>
    <material>Gazebo/DarkGrey</material>
  </gazebo>
  <gazebo reference="right_pinky4">
    <mu1>0.3</mu1>
    <mu2>0.3</mu2>
    <material>Gazebo/DarkGrey</material>
  </gazebo>
  <gazebo reference="right_cover_handring">
    <mu1>0.3</mu1>
    <mu2>0.3</mu2>
    <material>Gazebo/Grey</material>
  </gazebo>
  <gazebo reference="right_cover_handpinky">
    <mu1>0.3</mu1>
    <mu2>0.3</mu2>
    <material>Gazebo/Grey</material>
  </gazebo>
  <gazebo reference="right_cover_thumb">
    <mu1>0.3</mu1>
    <mu2>0.3</mu2>
    <material>Gazebo/Grey</material>
  </gazebo>
  <gazebo reference="right_cover_index">
    <mu1>0.3</mu1>
    <mu2>0.3</mu2>
    <material>Gazebo/Grey</material>
  </gazebo>
  <gazebo reference="right_cover_ring">
    <mu1>0.3</mu1>
    <mu2>0.3</mu2>
    <material>Gazebo/Grey</material>
  </gazebo>
  <gazebo reference="right_cover_pinky">
    <mu1>0.3</mu1>
    <mu2>0.3</mu2>
    <material>Gazebo/Grey</material>
  </gazebo>
  <!--LEFT HAND-->
  <gazebo reference="left_hand">
    <mu1>0.3</mu1>
    <mu2>0.3</mu2>
    <material>Gazebo/DarkGrey</material>
  </gazebo>
  <gazebo reference="left_thumb1">
    <mu1>0.3</mu1>
    <mu2>0.3</mu2>
    <material>Gazebo/DarkGrey</material>
  </gazebo>
  <gazebo reference="left_thumb2">
    <mu1>0.3</mu1>
    <mu2>0.3</mu2>
    <material>Gazebo/DarkGrey</material>
  </gazebo>
  <gazebo reference="left_index1">
    <mu1>0.3</mu1>
    <mu2>0.3</mu2>
    <material>Gazebo/DarkGrey</material>
  </gazebo>
  <gazebo reference="left_index2">
    <mu1>0.3</mu1>
    <mu2>0.3</mu2>
    <material>Gazebo/DarkGrey</material>
  </gazebo>
  <gazebo reference="left_index3">
    <mu1>0.3</mu1>
    <mu2>0.3</mu2>
    <material>Gazebo/DarkGrey</material>
  </gazebo>
  <gazebo reference="left_middle1">
    <mu1>0.3</mu1>
    <mu2>0.3</mu2>
    <material>Gazebo/DarkGrey</material>
  </gazebo>
  <gazebo reference="left_middle2">
    <mu1>0.3</mu1>
    <mu2>0.3</mu2>
    <material>Gazebo/DarkGrey</material>
  </gazebo>
  <gazebo reference="left_middle3">
    <mu1>0.3</mu1>
    <mu2>0.3</mu2>
    <material>Gazebo/DarkGrey</material>
  </gazebo>
  <gazebo reference="left_ring1">
    <mu1>0.3</mu1>
    <mu2>0.3</mu2>
    <material>Gazebo/DarkGrey</material>
  </gazebo>
  <gazebo reference="left_ring2">
    <mu1>0.3</mu1>
    <mu2>0.3</mu2>
    <material>Gazebo/DarkGrey</material>
  </gazebo>
  <gazebo reference="left_ring3">
    <mu1>0.3</mu1>
    <mu2>0.3</mu2>
    <material>Gazebo/DarkGrey</material>
  </gazebo>
  <gazebo reference="left_ring4">
    <mu1>0.3</mu1>
    <mu2>0.3</mu2>
    <material>Gazebo/DarkGrey</material>
  </gazebo>
  <gazebo reference="left_pinky1">
    <mu1>0.3</mu1>
    <mu2>0.3</mu2>
    <material>Gazebo/DarkGrey</material>
  </gazebo>
  <gazebo reference="left_pinky2">
    <mu1>0.3</mu1>
    <mu2>0.3</mu2>
    <material>Gazebo/DarkGrey</material>
  </gazebo>
  <gazebo reference="left_pinky3">
    <mu1>0.3</mu1>
    <mu2>0.3</mu2>
    <material>Gazebo/DarkGrey</material>
  </gazebo>
  <gazebo reference="left_pinky4">
    <mu1>0.3</mu1>
    <mu2>0.3</mu2>
    <material>Gazebo/DarkGrey</material>
  </gazebo>
  <gazebo reference="left_cover_handring">
    <mu1>0.3</mu1>
    <mu2>0.3</mu2>
    <material>Gazebo/Grey</material>
  </gazebo>
  <gazebo reference="left_cover_handpinky">
    <mu1>0.3</mu1>
    <mu2>0.3</mu2>
    <material>Gazebo/Grey</material>
  </gazebo>
  <gazebo reference="left_cover_thumb">
    <mu1>0.3</mu1>
    <mu2>0.3</mu2>
    <material>Gazebo/Grey</material>
  </gazebo>
  <gazebo reference="left_cover_index">
    <mu1>0.3</mu1>
    <mu2>0.3</mu2>
    <material>Gazebo/Grey</material>
  </gazebo>
  <gazebo reference="left_cover_ring">
    <mu1>0.3</mu1>
    <mu2>0.3</mu2>
    <material>Gazebo/Grey</material>
  </gazebo>
  <gazebo reference="left_cover_pinky">
    <mu1>0.3</mu1>
    <mu2>0.3</mu2>
    <material>Gazebo/Grey</material>
  </gazebo>
</robot>
