<?xml version="1.0"?>

<robot name="inmoov" xmlns:xacro="http://ros.org/wiki/xacro">

  <xacro:include filename="$(find inmoov_description)/urdf/materials.urdf.xacro" />
  <xacro:include filename="$(find inmoov_description)/urdf/default/asmBase.urdf.xacro" />
  <xacro:include filename="$(find inmoov_description)/urdf/default/asmTorso.urdf.xacro" />
  <xacro:include filename="$(find inmoov_description)/urdf/default/asmHead.urdf.xacro" />
  <xacro:include filename="$(find inmoov_description)/urdf/default/asmFace.urdf.xacro" />
  <xacro:include filename="$(find inmoov_description)/urdf/default/asmArm.urdf.xacro" />
  <xacro:include filename="$(find inmoov_description)/urdf/default/rightHand.urdf.xacro" />
  <xacro:include filename="$(find inmoov_description)/urdf/default/leftHand.urdf.xacro" />


  <link name="world"/>


  <joint name="fixed" type="fixed">
    <parent link="world"/>
    <child link="base_link"/>
  </joint>


  <link name="base_link">
    <visual>
      <geometry>
        <cylinder length="0.11" radius="0.26"/>
      </geometry> 
      <origin rpy="0 0 0" xyz="0 0 0.055"/>
      <xacro:base_color/>
    </visual>
    <collision>
      <geometry>
        <cylinder length="0.11" radius="0.26"/>
      </geometry> 
      <origin rpy="0 0 0" xyz="0 0 0.055"/>
    </collision>
  </link>


  <joint name="base_to_pedestal" type="fixed">
    <parent link="base_link"/>
    <child link="pedestal"/>
    <origin rpy="0 0 0"  xyz="0 0 0"/>
  </joint>


  <link name="pedestal">
    <visual>
      <geometry>
        <cylinder length="0.94" radius="0.0254"/>
      </geometry>
      <origin rpy="0 0 0" xyz="0 0 0.58"/>
      <xacro:base_color/>
    </visual>
    <collision>
      <geometry>
        <cylinder length="0.94" radius="0.0254"/>
      </geometry> 
      <origin rpy="0 0 0" xyz="0 0 0.58"/>
    </collision>
    <inertial>
      <origin rpy="0 0 0" xyz="0 0 0.58"/>
      <mass value="5"/>
      <inertia ixx="0.1"  ixy="0"  ixz="0" iyy="0.1" iyz="0" izz="0.1" />
    </inertial>
  </link>


  <link name="head_tilt">
    <visual>
      <geometry>
        <mesh filename="package://inmoov_meshes/meshes/virtual.stl" scale="0.001 0.001 0.001"/>
      </geometry>
      <origin rpy="0 0 0" xyz="0 0 0"/>
      <xacro:frame_color/>
    </visual>
    <inertial>
      <origin rpy="0 0 0" xyz="0 0.001 0.001"/>
      <mass value="5.25e-4"/>
      <inertia ixx="1e-3"  ixy="0"  ixz="0" iyy="1e-3" iyz="0" izz="1e-3" />
    </inertial>
  </link>


  <joint name="pedestal_to_mid_stomach" type="fixed">
    <parent link="pedestal"/>
    <child link="mid_stomach"/>
    <origin rpy="0 0 0"  xyz="0 0 0"/>
  </joint>


  <xacro:torso side="right" covers="yes" />


  <joint name="head_tilt" type="revolute">
   <axis xyz="0 1 0"/>
   <limit effort="1000.0" lower="-0.30" upper="0.30" velocity="0.5"/>
   <origin rpy="0 0 0" xyz="-0.001 -0.0315 0.4551"/>
   <parent link="torso"/>
   <child link="head_tilt"/>
   <dynamics damping="0.7"/>
  </joint>


  <joint name="head_updown" type="revolute">
   <axis xyz="1 0 0"/>
   <limit effort="2.422" lower="-1.22" upper="1.22" velocity="7.48"/>
   <origin rpy="0 0 0" xyz="0 0 0"/>
   <parent link="head_tilt"/>
   <child link="head_base"/>
   <dynamics damping="0.7"/>
  </joint>


  <xacro:head covers="yes" />


  <xacro:face covers="yes" />


  <joint name="face" type="fixed">
    <origin rpy="0 0 0" xyz="0 0.0637 0.079"/>
    <parent link="skull"/>
    <child link="face"/>
  </joint>


  <xacro:arm side="right" flip="1" covers="yes" />


  <joint name="right_shoulder_side" type="revolute">
   <axis xyz="0 1 0"/>
   <limit effort="2.422" lower="-1.22" upper="0" velocity="7.48"/>
   <origin rpy="0 0 0" xyz="0.143 0 0.298"/>
   <parent link="torso"/>
   <child link="right_shoulder_base"/>
   <dynamics damping="0.7"/>
  </joint>


  <xacro:rhand side="right" neg="1" covers="yes" />


  <link name="right_wrist_link">
    <visual>
      <geometry>
        <mesh filename="package://inmoov_meshes/meshes/virtual.stl" scale="0.001 0.001 0.001"/>
      </geometry>
      <origin rpy="0 0 0" xyz="0 0 0"/>
      <material name="cframe">
        <color rgba="0.25 0.25 0.25 1"/>
      </material>
    </visual>
    <inertial>
      <origin rpy="0 0 0" xyz="0 0.001 0.001"/>
      <mass value="5.25e-4"/>
      <inertia ixx="1e-3"  ixy="0"  ixz="0" iyy="1e-3" iyz="0" izz="1e-3" />
    </inertial>
  </link>


  <joint name="right_wrist" type="revolute">
   <axis xyz="0 0 1"/>
   <limit effort="0.9807" lower="-3.14" upper="0" velocity="5.236"/>
   <origin rpy="0 0 0" xyz="-0.01 -0.0144 -0.2885"/>
   <parent link="right_forearm"/>
   <child link="right_wrist_link"/>
   <dynamics damping="0.7"/>
  </joint>


  <joint name="right_wrist_fixed" type="fixed">
   <origin rpy="0 0 0" xyz="0 0 0"/>
   <parent link="right_wrist_link"/>
   <child link="right_hand"/>
  </joint>


  <xacro:arm side="left" flip="-1" covers="yes" />


  <joint name="left_shoulder_side" type="revolute">
   <axis xyz="0 1 0"/>
   <limit effort="2.422" lower="0" upper="1.22" velocity="7.48"/>
   <origin rpy="0 0 0" xyz="-0.143 0 0.298"/>
   <parent link="torso"/>
   <child link="left_shoulder_base"/>
   <dynamics damping="0.7"/>
  </joint>


  <xacro:lhand side="left" neg="-1" covers="yes" />


  <link name="left_wrist_link">
    <visual>
      <geometry>
        <mesh filename="package://inmoov_meshes/meshes/virtual.stl" scale="0.001 0.001 0.001"/>
      </geometry>
      <origin rpy="0 0 0" xyz="0 0 0"/>
      <material name="cframe">
        <color rgba="0.25 0.25 0.25 1"/>
      </material>
    </visual>
    <inertial>
      <origin rpy="0 0 0" xyz="0 0.001 0.001"/>
      <mass value="5.25e-4"/>
      <inertia ixx="1e-3"  ixy="0"  ixz="0" iyy="1e-3" iyz="0" izz="1e-3" />
    </inertial>
  </link>


  <joint name="left_wrist" type="revolute">
   <axis xyz="0 0 1"/>
   <limit effort="0.9807" lower="0" upper="3.14" velocity="5.236"/>
   <origin rpy="0 0 0" xyz="0.01 -0.0144 -0.2885"/>
   <parent link="left_forearm"/>
   <child link="left_wrist_link"/>
   <dynamics damping="0.7"/>
  </joint>


  <joint name="left_wrist_fixed" type="fixed">
   <origin rpy="0 0 0" xyz="0 0 0"/>
   <parent link="left_wrist_link"/>
   <child link="left_hand"/>
  </joint>

<<<<<<< HEAD
  <xacro:include filename="$(find inmoov_description)/urdf/sensors.gazebo"/>  
=======
  <xacro:include filename="$(find inmoov_description)/urdf/emr_sensors.gazebo"/>  
  <xacro:include filename="$(find inmoov_description)/urdf/contact_sensors.gazebo"/> 
>>>>>>> 634610668551a6d8b94040087a2017a49e50d6e6
  <xacro:include filename="$(find inmoov_description)/urdf/servos.urdf.xacro"/>
  <xacro:include filename="$(find inmoov_description)/urdf/materials.gazebo"/>

</robot>

